Workbook

Sheet Технологии
A1: ДЕРЕВО ТЕХНОЛОГИЙ — 15 ХОДОВ
A3: Вложения автоматически собираются с листов Ход 2026–2040. Незавершённые исследования накапливаются; prerequisites проверяются по накопленному прогрессу. Игровые эффекты технологий в состояние страны вносятся вручную.
A5: ВСЕГО ТЕХНОЛОГИЙ | E5: ОСНОВНЫХ ВЕТВЕЙ | I5: МЕЖВЕТВЕВЫХ | M5: СТАРТОВО ОТКРЫТО
A6: 40 | E6: 6 | I6: 4 | M6: 6
A10: ID | B10: Ветвь | C10: Уровень | D10: Технология | E10: Цена науки | F10: Требование 1 | G10: Требование 2 | H10: Требование 3 | I10: Суть | J10: Игровой эффект | K10: Вложено 2026 | L10: Вложено 2027 | M10: Вложено 2028 | N10: Вложено 2029 | O10: Вложено 2030 | P10: Вложено 2031 | Q10: Вложено 2032 | R10: Вложено 2033 | S10: Вложено 2034 | T10: Вложено 2035 | U10: Вложено 2036 | V10: Вложено 2037 | W10: Вложено 2038 | X10: Вложено 2039 | Y10: Вложено 2040 | Z10: Накоплено всего | AA10: Осталось | AB10: Текущий статус | AC10: Σ 2026 | AD10: Σ 2027 | AE10: Σ 2028 | AF10: Σ 2029 | AG10: Σ 2030 | AH10: Σ 2031 | AI10: Σ 2032 | AJ10: Σ 2033 | AK10: Σ 2034 | AL10: Σ 2035 | AM10: Σ 2036 | AN10: Σ 2037 | AO10: Σ 2038 | AP10: Σ 2039 | AQ10: Σ 2040 | AR10: Статус 2026 | AS10: Статус 2027 | AT10: Статус 2028 | AU10: Статус 2029 | AV10: Статус 2030 | AW10: Статус 2031 | AX10: Статус 2032 | AY10: Статус 2033 | AZ10: Статус 2034 | BA10: Статус 2035 | BB10: Статус 2036 | BC10: Статус 2037 | BD10: Статус 2038 | BE10: Статус 2039 | BF10: Статус 2040 | BG10: Год изучения | BH10: Эффект с года
A11: C1 | B11: Вычисления и аппаратная база | C11: I | D11: GPU-узлы с тензорными ядрами | E11: 20 | I11: Технология означает освоение серверных узлов на графических процессорах, выполняющих матричные операции при обучении и применении нейросетей. Государство получает доступ к относительно универсальной аппаратной базе, которую можно использовать для разных моделей без изготовления собственного процессора. Такой шаг повышает вычислительный потенциал и создаёт основу для специализированных ускорителей и крупных кластеров. На первом уровне инфраструктура достаточно ограничена, поэтому отдельный ресурсный штраф не вводится. | J11: + Вычислительные компоненты: +0,20 | K11: =SUMIF('Ход 2026'!$G$29:$G$38,$A11,'Ход 2026'!$I$29:$I$38)*(1+'Эффекты технологий'!J$7) -> 20 | L11: =SUMIF('Ход 2027'!$G$29:$G$38,$A11,'Ход 2027'!$I$29:$I$38)*(1+'Эффекты технологий'!K$7) -> 0 | M11: =SUMIF('Ход 2028'!$G$29:$G$38,$A11,'Ход 2028'!$I$29:$I$38)*(1+'Эффекты технологий'!L$7) -> 0 | N11: =SUMIF('Ход 2029'!$G$29:$G$38,$A11,'Ход 2029'!$I$29:$I$38)*(1+'Эффекты технологий'!M$7) -> 0 | O11: =SUMIF('Ход 2030'!$G$29:$G$38,$A11,'Ход 2030'!$I$29:$I$38)*(1+'Эффекты технологий'!N$7) -> 0 | P11: =SUMIF('Ход 2031'!$G$29:$G$38,$A11,'Ход 2031'!$I$29:$I$38)*(1+'Эффекты технологий'!O$7) -> 0 | Q11: =SUMIF('Ход 2032'!$G$29:$G$38,$A11,'Ход 2032'!$I$29:$I$38)*(1+'Эффекты технологий'!P$7) -> 0 | R11: =SUMIF('Ход 2033'!$G$29:$G$38,$A11,'Ход 2033'!$I$29:$I$38)*(1+'Эффекты технологий'!Q$7) -> 0 | S11: =SUMIF('Ход 2034'!$G$29:$G$38,$A11,'Ход 2034'!$I$29:$I$38)*(1+'Эффекты технологий'!R$7) -> 0 | T11: =SUMIF('Ход 2035'!$G$29:$G$38,$A11,'Ход 2035'!$I$29:$I$38)*(1+'Эффекты технологий'!S$7) -> 0 | U11: =SUMIF('Ход 2036'!$G$29:$G$38,$A11,'Ход 2036'!$I$29:$I$38)*(1+'Эффекты технологий'!T$7) -> 0 | V11: =SUMIF('Ход 2037'!$G$29:$G$38,$A11,'Ход 2037'!$I$29:$I$38)*(1+'Эффекты технологий'!U$7) -> 0 | W11: =SUMIF('Ход 2038'!$G$29:$G$38,$A11,'Ход 2038'!$I$29:$I$38)*(1+'Эффекты технологий'!V$7) -> 0 | X11: =SUMIF('Ход 2039'!$G$29:$G$38,$A11,'Ход 2039'!$I$29:$I$38)*(1+'Эффекты технологий'!W$7) -> 0 | Y11: =SUMIF('Ход 2040'!$G$29:$G$38,$A11,'Ход 2040'!$I$29:$I$38)*(1+'Эффекты технологий'!X$7) -> 0 | Z11: =SUM(K11:Y11) -> 20 | AA11: =MAX(0,E11-Z11) -> 0 | AB11: =BF11 -> ИЗУЧЕНО | AC11: =SUM($K11:K11) -> 20 | AD11: =SUM($K11:L11) -> 20 | AE11: =SUM($K11:M11) -> 20 | AF11: =SUM($K11:N11) -> 20 | AG11: =SUM($K11:O11) -> 20 | AH11: =SUM($K11:P11) -> 20 | AI11: =SUM($K11:Q11) -> 20 | AJ11: =SUM($K11:R11) -> 20 | ... AQ11: =SUM($K11:Y11) -> 20 | AR11: =IF(AND(AC11>=$E11,TRUE),"ИЗУЧЕНО",IF(TRUE,"ОТКРЫТО","ЗАКРЫТО")) -> ИЗУЧЕНО | AS11: =IF(AND(AD11>=$E11,TRUE),"ИЗУЧЕНО",IF(TRUE,"ОТКРЫТО","ЗАКРЫТО")) -> ИЗУЧЕНО | AT11: =IF(AND(AE11>=$E11,TRUE),"ИЗУЧЕНО",IF(TRUE,"ОТКРЫТО","ЗАКРЫТО")) -> ИЗУЧЕНО | AU11: =IF(AND(AF11>=$E11,TRUE),"ИЗУЧЕНО",IF(TRUE,"ОТКРЫТО","ЗАКРЫТО")) -> ИЗУЧЕНО | AV11: =IF(AND(AG11>=$E11,TRUE),"ИЗУЧЕНО",IF(TRUE,"ОТКРЫТО","ЗАКРЫТО")) -> ИЗУЧЕНО | AW11: =IF(AND(AH11>=$E11,TRUE),"ИЗУЧЕНО",IF(TRUE,"ОТКРЫТО","ЗАКРЫТО")) -> ИЗУЧЕНО | AX11: =IF(AND(AI11>=$E11,TRUE),"ИЗУЧЕНО",IF(TRUE,"ОТКРЫТО","ЗАКРЫТО")) -> ИЗУЧЕНО | AY11: =IF(AND(AJ11>=$E11,TRUE),"ИЗУЧЕНО",IF(TRUE,"ОТКРЫТО","ЗАКРЫТО")) -> ИЗУЧЕНО | ... BF11: =IF(AND(AQ11>=$E11,TRUE),"ИЗУЧЕНО",IF(TRUE,"ОТКРЫТО","ЗАКРЫТО")) -> ИЗУЧЕНО | BG11: =IFERROR(2025+MATCH("ИЗУЧЕНО",AR11:BF11,0),"") -> 2026 | BH11: =IF(BG11="","",BG11+1) -> 2027
A12: C2 | B12: Вычисления и аппаратная база | C12: II | D12: ASIC-ускорители с памятью HBM | E12: 40 | F12: C1 | I12: Специализированные интегральные схемы ASIC разрабатываются под определённые нейросетевые операции, а память HBM обеспечивает высокую пропускную способность доступа к данным. Вместе с аппаратурой развиваются драйверы, компиляторы и программные библиотеки. Выигрыш состоит в повышении производительности и лучшей согласованности программной и аппаратной частей. Производство таких ускорителей требует дополнительных металлов и редких материалов, поэтому технология уменьшает доступный сырьевой ресурс. | J12: + Вычислительные компоненты: +0,30; + Базовый программный стек вычислений: +0,20; − Минерально-сырьевые ресурсы: -0,15 | K12: =SUMIF('Ход 2026'!$G$29:$G$38,$A12,'Ход 2026'!$I$29:$I$38)*(1+'Эффекты технологий'!J$7) -> 0 | L12: =SUMIF('Ход 2027'!$G$29:$G$38,$A12,'Ход 2027'!$I$29:$I$38)*(1+'Эффекты технологий'!K$7) -> 0 | M12: =SUMIF('Ход 2028'!$G$29:$G$38,$A12,'Ход 2028'!$I$29:$I$38)*(1+'Эффекты технологий'!L$7) -> 0 | N12: =SUMIF('Ход 2029'!$G$29:$G$38,$A12,'Ход 2029'!$I$29:$I$38)*(1+'Эффекты технологий'!M$7) -> 0 | O12: =SUMIF('Ход 2030'!$G$29:$G$38,$A12,'Ход 2030'!$I$29:$I$38)*(1+'Эффекты технологий'!N$7) -> 0 | P12: =SUMIF('Ход 2031'!$G$29:$G$38,$A12,'Ход 2031'!$I$29:$I$38)*(1+'Эффекты технологий'!O$7) -> 0 | Q12: =SUMIF('Ход 2032'!$G$29:$G$38,$A12,'Ход 2032'!$I$29:$I$38)*(1+'Эффекты технологий'!P$7) -> 0 | R12: =SUMIF('Ход 2033'!$G$29:$G$38,$A12,'Ход 2033'!$I$29:$I$38)*(1+'Эффекты технологий'!Q$7) -> 0 | S12: =SUMIF('Ход 2034'!$G$29:$G$38,$A12,'Ход 2034'!$I$29:$I$38)*(1+'Эффекты технологий'!R$7) -> 0 | T12: =SUMIF('Ход 2035'!$G$29:$G$38,$A12,'Ход 2035'!$I$29:$I$38)*(1+'Эффекты технологий'!S$7) -> 0 | U12: =SUMIF('Ход 2036'!$G$29:$G$38,$A12,'Ход 2036'!$I$29:$I$38)*(1+'Эффекты технологий'!T$7) -> 0 | V12: =SUMIF('Ход 2037'!$G$29:$G$38,$A12,'Ход 2037'!$I$29:$I$38)*(1+'Эффекты технологий'!U$7) -> 0 | W12: =SUMIF('Ход 2038'!$G$29:$G$38,$A12,'Ход 2038'!$I$29:$I$38)*(1+'Эффекты технологий'!V$7) -> 0 | X12: =SUMIF('Ход 2039'!$G$29:$G$38,$A12,'Ход 2039'!$I$29:$I$38)*(1+'Эффекты технологий'!W$7) -> 0 | Y12: =SUMIF('Ход 2040'!$G$29:$G$38,$A12,'Ход 2040'!$I$29:$I$38)*(1+'Эффекты технологий'!X$7) -> 0 | Z12: =SUM(K12:Y12) -> 0 | AA12: =MAX(0,E12-Z12) -> 40 | AB12: =BF12 -> ОТКРЫТО | AC12: =SUM($K12:K12) -> 0 | AD12: =SUM($K12:L12) -> 0 | AE12: =SUM($K12:M12) -> 0 | AF12: =SUM($K12:N12) -> 0 | AG12: =SUM($K12:O12) -> 0 | AH12: =SUM($K12:P12) -> 0 | AI12: =SUM($K12:Q12) -> 0 | AJ12: =SUM($K12:R12) -> 0 | ... AQ12: =SUM($K12:Y12) -> 0 | AR12: =IF(AND(AC12>=$E12,TRUE),"ИЗУЧЕНО",IF(TRUE,"ОТКРЫТО","ЗАКРЫТО")) -> ОТКРЫТО | AS12: =IF(AND(AD12>=$E12,TRUE),"ИЗУЧЕНО",IF(TRUE,"ОТКРЫТО","ЗАКРЫТО")) -> ОТКРЫТО | AT12: =IF(AND(AE12>=$E12,TRUE),"ИЗУЧЕНО",IF(TRUE,"ОТКРЫТО","ЗАКРЫТО")) -> ОТКРЫТО | AU12: =IF(AND(AF12>=$E12,TRUE),"ИЗУЧЕНО",IF(TRUE,"ОТКРЫТО","ЗАКРЫТО")) -> ОТКРЫТО | AV12: =IF(AND(AG12>=$E12,TRUE),"ИЗУЧЕНО",IF(TRUE,"ОТКРЫТО","ЗАКРЫТО")) -> ОТКРЫТО | AW12: =IF(AND(AH12>=$E12,TRUE),"ИЗУЧЕНО",IF(TRUE,"ОТКРЫТО","ЗАКРЫТО")) -> ОТКРЫТО | AX12: =IF(AND(AI12>=$E12,TRUE),"ИЗУЧЕНО",IF(TRUE,"ОТКРЫТО","ЗАКРЫТО")) -> ОТКРЫТО | AY12: =IF(AND(AJ12>=$E12,TRUE),"ИЗУЧЕНО",IF(TRUE,"ОТКРЫТО","ЗАКРЫТО")) -> ОТКРЫТО | ... BF12: =IF(AND(AQ12>=$E12,TRUE),"ИЗУЧЕНО",IF(TRUE,"ОТКРЫТО","ЗАКРЫТО")) -> ОТКРЫТО | BG12: =IFERROR(2025+MATCH("ИЗУЧЕНО",AR12:BF12,0),"") | BH12: =IF(BG12="","",BG12+1)
A13: C3 | B13: Вычисления и аппаратная база | C13: II | D13: Чиплетная компоновка ИИ-процессоров 2.5D/3D | E13: 45 | F13: C1 | I13: Вместо одного большого кристалла процессор собирается из нескольких функциональных чиплетов, соединённых высокоплотной подложкой или многослойной компоновкой. Это позволяет комбинировать вычислительные блоки, память и ввод-вывод, а также развивать передовые производственные процессы. Технология даёт сразу три промышленных преимущества, но нуждается в более сложных производственных линиях и материальной базе. Сырьевой штраф здесь больше, чем у C2, отражая масштаб и сложность развёртывания. | J13: + Мощности производства полупроводников: +0,40; + Вычислительные компоненты: +0,20; + Химические и технологические материалы: +0,20; − Минерально-сырьевые ресурсы: -0,40 | K13: =SUMIF('Ход 2026'!$G$29:$G$38,$A13,'Ход 2026'!$I$29:$I$38)*(1+'Эффекты технологий'!J$7) -> 0 | L13: =SUMIF('Ход 2027'!$G$29:$G$38,$A13,'Ход 2027'!$I$29:$I$38)*(1+'Эффекты технологий'!K$7) -> 0 | M13: =SUMIF('Ход 2028'!$G$29:$G$38,$A13,'Ход 2028'!$I$29:$I$38)*(1+'Эффекты технологий'!L$7) -> 0 | N13: =SUMIF('Ход 2029'!$G$29:$G$38,$A13,'Ход 2029'!$I$29:$I$38)*(1+'Эффекты технологий'!M$7) -> 0 | O13: =SUMIF('Ход 2030'!$G$29:$G$38,$A13,'Ход 2030'!$I$29:$I$38)*(1+'Эффекты технологий'!N$7) -> 0 | P13: =SUMIF('Ход 2031'!$G$29:$G$38,$A13,'Ход 2031'!$I$29:$I$38)*(1+'Эффекты технологий'!O$7) -> 0 | Q13: =SUMIF('Ход 2032'!$G$29:$G$38,$A13,'Ход 2032'!$I$29:$I$38)*(1+'Эффекты технологий'!P$7) -> 0 | R13: =SUMIF('Ход 2033'!$G$29:$G$38,$A13,'Ход 2033'!$I$29:$I$38)*(1+'Эффекты технологий'!Q$7) -> 0 | S13: =SUMIF('Ход 2034'!$G$29:$G$38,$A13,'Ход 2034'!$I$29:$I$38)*(1+'Эффекты технологий'!R$7) -> 0 | T13: =SUMIF('Ход 2035'!$G$29:$G$38,$A13,'Ход 2035'!$I$29:$I$38)*(1+'Эффекты технологий'!S$7) -> 0 | U13: =SUMIF('Ход 2036'!$G$29:$G$38,$A13,'Ход 2036'!$I$29:$I$38)*(1+'Эффекты технологий'!T$7) -> 0 | V13: =SUMIF('Ход 2037'!$G$29:$G$38,$A13,'Ход 2037'!$I$29:$I$38)*(1+'Эффекты технологий'!U$7) -> 0 | W13: =SUMIF('Ход 2038'!$G$29:$G$38,$A13,'Ход 2038'!$I$29:$I$38)*(1+'Эффекты технологий'!V$7) -> 0 | X13: =SUMIF('Ход 2039'!$G$29:$G$38,$A13,'Ход 2039'!$I$29:$I$38)*(1+'Эффекты технологий'!W$7) -> 0 | Y13: =SUMIF('Ход 2040'!$G$29:$G$38,$A13,'Ход 2040'!$I$29:$I$38)*(1+'Эффекты технологий'!X$7) -> 0 | Z13: =SUM(K13:Y13) -> 0 | AA13: =MAX(0,E13-Z13) -> 45 | AB13: =BF13 -> ОТКРЫТО | AC13: =SUM($K13:K13) -> 0 | AD13: =SUM($K13:L13) -> 0 | AE13: =SUM($K13:M13) -> 0 | AF13: =SUM($K13:N13) -> 0 | AG13: =SUM($K13:O13) -> 0 | AH13: =SUM($K13:P13) -> 0 | AI13: =SUM($K13:Q13) -> 0 | AJ13: =SUM($K13:R13) -> 0 | ... AQ13: =SUM($K13:Y13) -> 0 | AR13: =IF(AND(AC13>=$E13,TRUE),"ИЗУЧЕНО",IF(TRUE,"ОТКРЫТО","ЗАКРЫТО")) -> ОТКРЫТО | AS13: =IF(AND(AD13>=$E13,TRUE),"ИЗУЧЕНО",IF(TRUE,"ОТКРЫТО","ЗАКРЫТО")) -> ОТКРЫТО | AT13: =IF(AND(AE13>=$E13,TRUE),"ИЗУЧЕНО",IF(TRUE,"ОТКРЫТО","ЗАКРЫТО")) -> ОТКРЫТО | AU13: =IF(AND(AF13>=$E13,TRUE),"ИЗУЧЕНО",IF(TRUE,"ОТКРЫТО","ЗАКРЫТО")) -> ОТКРЫТО | AV13: =IF(AND(AG13>=$E13,TRUE),"ИЗУЧЕНО",IF(TRUE,"ОТКРЫТО","ЗАКРЫТО")) -> ОТКРЫТО | AW13: =IF(AND(AH13>=$E13,TRUE),"ИЗУЧЕНО",IF(TRUE,"ОТКРЫТО","ЗАКРЫТО")) -> ОТКРЫТО | AX13: =IF(AND(AI13>=$E13,TRUE),"ИЗУЧЕНО",IF(TRUE,"ОТКРЫТО","ЗАКРЫТО")) -> ОТКРЫТО | AY13: =IF(AND(AJ13>=$E13,TRUE),"ИЗУЧЕНО",IF(TRUE,"ОТКРЫТО","ЗАКРЫТО")) -> ОТКРЫТО | ... BF13: =IF(AND(AQ13>=$E13,TRUE),"ИЗУЧЕНО",IF(TRUE,"ОТКРЫТО","ЗАКРЫТО")) -> ОТКРЫТО | BG13: =IFERROR(2025+MATCH("ИЗУЧЕНО",AR13:BF13,0),"") | BH13: =IF(BG13="","",BG13+1)
A14: C4 | B14: Вычисления и аппаратная база | C14: III | D14: Гетерогенные вычислительные кластеры | E14: 65 | F14: C2 | G14: C3 | I14: Кластер объединяет центральные процессоры, графические ускорители и специализированные ASIC в общую систему с распределённым управлением вычислениями. Основную роль играют планировщики задач, высокоскоростные соединения и согласованное использование памяти и ресурсов. Государство получает не просто отдельные чипы, а инфраструктуру промышленного масштаба. Такая концентрация оборудования увеличивает потребление электроэнергии и потребность в охлаждении, из-за чего появляются два постоянных ресурсных штрафа. | J14: + ЦОД и вычислительная инфраструктура: +0,40; + Стек эксплуатации ИИ: +0,20; + Сетевые ресурсы: +0,20; + Вычислительные компоненты: +0,20; − Энергетические ресурсы: -0,25; − Вода и ресурс отвода тепла: -0,20 | K14: =SUMIF('Ход 2026'!$G$29:$G$38,$A14,'Ход 2026'!$I$29:$I$38)*(1+'Эффекты технологий'!J$7) -> 0 | L14: =SUMIF('Ход 2027'!$G$29:$G$38,$A14,'Ход 2027'!$I$29:$I$38)*(1+'Эффекты технологий'!K$7) -> 0 | M14: =SUMIF('Ход 2028'!$G$29:$G$38,$A14,'Ход 2028'!$I$29:$I$38)*(1+'Эффекты технологий'!L$7) -> 0 | N14: =SUMIF('Ход 2029'!$G$29:$G$38,$A14,'Ход 2029'!$I$29:$I$38)*(1+'Эффекты технологий'!M$7) -> 0 | O14: =SUMIF('Ход 2030'!$G$29:$G$38,$A14,'Ход 2030'!$I$29:$I$38)*(1+'Эффекты технологий'!N$7) -> 0 | P14: =SUMIF('Ход 2031'!$G$29:$G$38,$A14,'Ход 2031'!$I$29:$I$38)*(1+'Эффекты технологий'!O$7) -> 0 | Q14: =SUMIF('Ход 2032'!$G$29:$G$38,$A14,'Ход 2032'!$I$29:$I$38)*(1+'Эффекты технологий'!P$7) -> 0 | R14: =SUMIF('Ход 2033'!$G$29:$G$38,$A14,'Ход 2033'!$I$29:$I$38)*(1+'Эффекты технологий'!Q$7) -> 0 | S14: =SUMIF('Ход 2034'!$G$29:$G$38,$A14,'Ход 2034'!$I$29:$I$38)*(1+'Эффекты технологий'!R$7) -> 0 | T14: =SUMIF('Ход 2035'!$G$29:$G$38,$A14,'Ход 2035'!$I$29:$I$38)*(1+'Эффекты технологий'!S$7) -> 0 | U14: =SUMIF('Ход 2036'!$G$29:$G$38,$A14,'Ход 2036'!$I$29:$I$38)*(1+'Эффекты технологий'!T$7) -> 0 | V14: =SUMIF('Ход 2037'!$G$29:$G$38,$A14,'Ход 2037'!$I$29:$I$38)*(1+'Эффекты технологий'!U$7) -> 0 | W14: =SUMIF('Ход 2038'!$G$29:$G$38,$A14,'Ход 2038'!$I$29:$I$38)*(1+'Эффекты технологий'!V$7) -> 0 | X14: =SUMIF('Ход 2039'!$G$29:$G$38,$A14,'Ход 2039'!$I$29:$I$38)*(1+'Эффекты технологий'!W$7) -> 0 | Y14: =SUMIF('Ход 2040'!$G$29:$G$38,$A14,'Ход 2040'!$I$29:$I$38)*(1+'Эффекты технологий'!X$7) -> 0 | Z14: =SUM(K14:Y14) -> 0 | AA14: =MAX(0,E14-Z14) -> 65 | AB14: =BF14 -> ОТКРЫТО | AC14: =SUM($K14:K14) -> 0 | AD14: =SUM($K14:L14) -> 0 | AE14: =SUM($K14:M14) -> 0 | AF14: =SUM($K14:N14) -> 0 | AG14: =SUM($K14:O14) -> 0 | AH14: =SUM($K14:P14) -> 0 | AI14: =SUM($K14:Q14) -> 0 | AJ14: =SUM($K14:R14) -> 0 | ... AQ14: =SUM($K14:Y14) -> 0 | AR14: =IF(AND(AC14>=$E14,TRUE),"ИЗУЧЕНО",IF(TRUE,"ОТКРЫТО","ЗАКРЫТО")) -> ОТКРЫТО | AS14: =IF(AND(AD14>=$E14,TRUE),"ИЗУЧЕНО",IF(TRUE,"ОТКРЫТО","ЗАКРЫТО")) -> ОТКРЫТО | AT14: =IF(AND(AE14>=$E14,TRUE),"ИЗУЧЕНО",IF(TRUE,"ОТКРЫТО","ЗАКРЫТО")) -> ОТКРЫТО | AU14: =IF(AND(AF14>=$E14,TRUE),"ИЗУЧЕНО",IF(TRUE,"ОТКРЫТО","ЗАКРЫТО")) -> ОТКРЫТО | AV14: =IF(AND(AG14>=$E14,TRUE),"ИЗУЧЕНО",IF(TRUE,"ОТКРЫТО","ЗАКРЫТО")) -> ОТКРЫТО | AW14: =IF(AND(AH14>=$E14,TRUE),"ИЗУЧЕНО",IF(TRUE,"ОТКРЫТО","ЗАКРЫТО")) -> ОТКРЫТО | AX14: =IF(AND(AI14>=$E14,TRUE),"ИЗУЧЕНО",IF(TRUE,"ОТКРЫТО","ЗАКРЫТО")) -> ОТКРЫТО | AY14: =IF(AND(AJ14>=$E14,TRUE),"ИЗУЧЕНО",IF(TRUE,"ОТКРЫТО","ЗАКРЫТО")) -> ОТКРЫТО | ... BF14: =IF(AND(AQ14>=$E14,TRUE),"ИЗУЧЕНО",IF(TRUE,"ОТКРЫТО","ЗАКРЫТО")) -> ОТКРЫТО | BG14: =IFERROR(2025+MATCH("ИЗУЧЕНО",AR14:BF14,0),"") | BH14: =IF(BG14="","",BG14+1)
A15: C5 | B15: Вычисления и аппаратная база | C15: IV | D15: Распределённые ЦОД с оптическими магистралями | E15: 100 | F15: C4 | I15: Географически разделённые вычислительные центры связываются оптическими каналами высокой пропускной способности и могут совместно предоставлять вычисления для обучения и эксплуатации моделей. Такая архитектура повышает устойчивость инфраструктуры и даёт преимущество в борьбе за цифровые потоки, что отражено бонусом к защите от войны Афины. Однако страна вынуждена размещать новые площадки, создавать энергоузлы и охлаждение, прокладывать сетевые магистрали. Поэтому увеличение цифровой устойчивости оплачивается тремя материальными ограничениями. | J15: + Сетевые ресурсы: +0,50; + ЦОД и вычислительная инфраструктура: +0,35; + Интеграционные ресурсы: +0,25; + Стек эксплуатации ИИ: +0,20; + Защита от войны Афины: +15%; − Энергетические ресурсы: -0,35; − Вода и ресурс отвода тепла: -0,25; − Пространственные и природно-географические ресурсы: -0,20 | K15: =SUMIF('Ход 2026'!$G$29:$G$38,$A15,'Ход 2026'!$I$29:$I$38)*(1+'Эффекты технологий'!J$7) -> 0 | L15: =SUMIF('Ход 2027'!$G$29:$G$38,$A15,'Ход 2027'!$I$29:$I$38)*(1+'Эффекты технологий'!K$7) -> 0 | M15: =SUMIF('Ход 2028'!$G$29:$G$38,$A15,'Ход 2028'!$I$29:$I$38)*(1+'Эффекты технологий'!L$7) -> 0 | N15: =SUMIF('Ход 2029'!$G$29:$G$38,$A15,'Ход 2029'!$I$29:$I$38)*(1+'Эффекты технологий'!M$7) -> 0 | O15: =SUMIF('Ход 2030'!$G$29:$G$38,$A15,'Ход 2030'!$I$29:$I$38)*(1+'Эффекты технологий'!N$7) -> 0 | P15: =SUMIF('Ход 2031'!$G$29:$G$38,$A15,'Ход 2031'!$I$29:$I$38)*(1+'Эффекты технологий'!O$7) -> 0 | Q15: =SUMIF('Ход 2032'!$G$29:$G$38,$A15,'Ход 2032'!$I$29:$I$38)*(1+'Эффекты технологий'!P$7) -> 0 | R15: =SUMIF('Ход 2033'!$G$29:$G$38,$A15,'Ход 2033'!$I$29:$I$38)*(1+'Эффекты технологий'!Q$7) -> 0 | S15: =SUMIF('Ход 2034'!$G$29:$G$38,$A15,'Ход 2034'!$I$29:$I$38)*(1+'Эффекты технологий'!R$7) -> 0 | T15: =SUMIF('Ход 2035'!$G$29:$G$38,$A15,'Ход 2035'!$I$29:$I$38)*(1+'Эффекты технологий'!S$7) -> 0 | U15: =SUMIF('Ход 2036'!$G$29:$G$38,$A15,'Ход 2036'!$I$29:$I$38)*(1+'Эффекты технологий'!T$7) -> 0 | V15: =SUMIF('Ход 2037'!$G$29:$G$38,$A15,'Ход 2037'!$I$29:$I$38)*(1+'Эффекты технологий'!U$7) -> 0 | W15: =SUMIF('Ход 2038'!$G$29:$G$38,$A15,'Ход 2038'!$I$29:$I$38)*(1+'Эффекты технологий'!V$7) -> 0 | X15: =SUMIF('Ход 2039'!$G$29:$G$38,$A15,'Ход 2039'!$I$29:$I$38)*(1+'Эффекты технологий'!W$7) -> 0 | Y15: =SUMIF('Ход 2040'!$G$29:$G$38,$A15,'Ход 2040'!$I$29:$I$38)*(1+'Эффекты технологий'!X$7) -> 0 | Z15: =SUM(K15:Y15) -> 0 | AA15: =MAX(0,E15-Z15) -> 100 | AB15: =BF15 -> ОТКРЫТО | AC15: =SUM($K15:K15) -> 0 | AD15: =SUM($K15:L15) -> 0 | AE15: =SUM($K15:M15) -> 0 | AF15: =SUM($K15:N15) -> 0 | AG15: =SUM($K15:O15) -> 0 | AH15: =SUM($K15:P15) -> 0 | AI15: =SUM($K15:Q15) -> 0 | AJ15: =SUM($K15:R15) -> 0 | ... AQ15: =SUM($K15:Y15) -> 0 | AR15: =IF(AND(AC15>=$E15,TRUE),"ИЗУЧЕНО",IF(TRUE,"ОТКРЫТО","ЗАКРЫТО")) -> ОТКРЫТО | AS15: =IF(AND(AD15>=$E15,TRUE),"ИЗУЧЕНО",IF(TRUE,"ОТКРЫТО","ЗАКРЫТО")) -> ОТКРЫТО | AT15: =IF(AND(AE15>=$E15,TRUE),"ИЗУЧЕНО",IF(TRUE,"ОТКРЫТО","ЗАКРЫТО")) -> ОТКРЫТО | AU15: =IF(AND(AF15>=$E15,TRUE),"ИЗУЧЕНО",IF(TRUE,"ОТКРЫТО","ЗАКРЫТО")) -> ОТКРЫТО | AV15: =IF(AND(AG15>=$E15,TRUE),"ИЗУЧЕНО",IF(TRUE,"ОТКРЫТО","ЗАКРЫТО")) -> ОТКРЫТО | AW15: =IF(AND(AH15>=$E15,TRUE),"ИЗУЧЕНО",IF(TRUE,"ОТКРЫТО","ЗАКРЫТО")) -> ОТКРЫТО | AX15: =IF(AND(AI15>=$E15,TRUE),"ИЗУЧЕНО",IF(TRUE,"ОТКРЫТО","ЗАКРЫТО")) -> ОТКРЫТО | AY15: =IF(AND(AJ15>=$E15,TRUE),"ИЗУЧЕНО",IF(TRUE,"ОТКРЫТО","ЗАКРЫТО")) -> ОТКРЫТО | ... BF15: =IF(AND(AQ15>=$E15,TRUE),"ИЗУЧЕНО",IF(TRUE,"ОТКРЫТО","ЗАКРЫТО")) -> ОТКРЫТО | BG15: =IFERROR(2025+MATCH("ИЗУЧЕНО",AR15:BF15,0),"") | BH15: =IF(BG15="","",BG15+1)
A16: C6 | B16: Вычисления и аппаратная база | C16: V | D16: Фотонно-нейроморфные вычислительные комплексы | E16: 150 | F16: C5 | I16: Высший уровень ветви объединяет исследования новых принципов аппаратной обработки информации: фотонных вычислительных элементов, нейроморфных структур и их интеграции с обычными процессорами. В игровом мире это дорогостоящие комплексы, которые расширяют как вычислительную базу, так и возможности создания моделей. Исследования ветви M становятся эффективнее. Несмотря на потенциальную экономичность отдельных операций, массовое изготовление и развёртывание инфраструктуры остаётся чрезвычайно материалоёмким и создаёт четыре вида ресурсной нагрузки. | J16: + Вычислительные компоненты: +0,50; + Математико-алгоритмические ресурсы: +0,35; + Мощности производства полупроводников: +0,35; + Модельные ресурсы: +0,25; + Прирост ЦОД и вычислительной инфраструктуры: +0,10/год; + Эффективность науки для ветви M: +10%; − Минерально-сырьевые ресурсы: -0,45; − Энергетические ресурсы: -0,50; − Вода и ресурс отвода тепла: -0,40; − Пространственные и природно-географические ресурсы: -0,30 | K16: =SUMIF('Ход 2026'!$G$29:$G$38,$A16,'Ход 2026'!$I$29:$I$38)*(1+'Эффекты технологий'!J$7) -> 0 | L16: =SUMIF('Ход 2027'!$G$29:$G$38,$A16,'Ход 2027'!$I$29:$I$38)*(1+'Эффекты технологий'!K$7) -> 0 | M16: =SUMIF('Ход 2028'!$G$29:$G$38,$A16,'Ход 2028'!$I$29:$I$38)*(1+'Эффекты технологий'!L$7) -> 0 | N16: =SUMIF('Ход 2029'!$G$29:$G$38,$A16,'Ход 2029'!$I$29:$I$38)*(1+'Эффекты технологий'!M$7) -> 0 | O16: =SUMIF('Ход 2030'!$G$29:$G$38,$A16,'Ход 2030'!$I$29:$I$38)*(1+'Эффекты технологий'!N$7) -> 0 | P16: =SUMIF('Ход 2031'!$G$29:$G$38,$A16,'Ход 2031'!$I$29:$I$38)*(1+'Эффекты технологий'!O$7) -> 0 | Q16: =SUMIF('Ход 2032'!$G$29:$G$38,$A16,'Ход 2032'!$I$29:$I$38)*(1+'Эффекты технологий'!P$7) -> 0 | R16: =SUMIF('Ход 2033'!$G$29:$G$38,$A16,'Ход 2033'!$I$29:$I$38)*(1+'Эффекты технологий'!Q$7) -> 0 | S16: =SUMIF('Ход 2034'!$G$29:$G$38,$A16,'Ход 2034'!$I$29:$I$38)*(1+'Эффекты технологий'!R$7) -> 0 | T16: =SUMIF('Ход 2035'!$G$29:$G$38,$A16,'Ход 2035'!$I$29:$I$38)*(1+'Эффекты технологий'!S$7) -> 0 | U16: =SUMIF('Ход 2036'!$G$29:$G$38,$A16,'Ход 2036'!$I$29:$I$38)*(1+'Эффекты технологий'!T$7) -> 0 | V16: =SUMIF('Ход 2037'!$G$29:$G$38,$A16,'Ход 2037'!$I$29:$I$38)*(1+'Эффекты технологий'!U$7) -> 0 | W16: =SUMIF('Ход 2038'!$G$29:$G$38,$A16,'Ход 2038'!$I$29:$I$38)*(1+'Эффекты технологий'!V$7) -> 0 | X16: =SUMIF('Ход 2039'!$G$29:$G$38,$A16,'Ход 2039'!$I$29:$I$38)*(1+'Эффекты технологий'!W$7) -> 0 | Y16: =SUMIF('Ход 2040'!$G$29:$G$38,$A16,'Ход 2040'!$I$29:$I$38)*(1+'Эффекты технологий'!X$7) -> 0 | Z16: =SUM(K16:Y16) -> 0 | AA16: =MAX(0,E16-Z16) -> 150 | AB16: =BF16 -> ОТКРЫТО | AC16: =SUM($K16:K16) -> 0 | AD16: =SUM($K16:L16) -> 0 | AE16: =SUM($K16:M16) -> 0 | AF16: =SUM($K16:N16) -> 0 | AG16: =SUM($K16:O16) -> 0 | AH16: =SUM($K16:P16) -> 0 | AI16: =SUM($K16:Q16) -> 0 | AJ16: =SUM($K16:R16) -> 0 | ... AQ16: =SUM($K16:Y16) -> 0 | AR16: =IF(AND(AC16>=$E16,TRUE),"ИЗУЧЕНО",IF(TRUE,"ОТКРЫТО","ЗАКРЫТО")) -> ОТКРЫТО | AS16: =IF(AND(AD16>=$E16,TRUE),"ИЗУЧЕНО",IF(TRUE,"ОТКРЫТО","ЗАКРЫТО")) -> ОТКРЫТО | AT16: =IF(AND(AE16>=$E16,TRUE),"ИЗУЧЕНО",IF(TRUE,"ОТКРЫТО","ЗАКРЫТО")) -> ОТКРЫТО | AU16: =IF(AND(AF16>=$E16,TRUE),"ИЗУЧЕНО",IF(TRUE,"ОТКРЫТО","ЗАКРЫТО")) -> ОТКРЫТО | AV16: =IF(AND(AG16>=$E16,TRUE),"ИЗУЧЕНО",IF(TRUE,"ОТКРЫТО","ЗАКРЫТО")) -> ОТКРЫТО | AW16: =IF(AND(AH16>=$E16,TRUE),"ИЗУЧЕНО",IF(TRUE,"ОТКРЫТО","ЗАКРЫТО")) -> ОТКРЫТО | AX16: =IF(AND(AI16>=$E16,TRUE),"ИЗУЧЕНО",IF(TRUE,"ОТКРЫТО","ЗАКРЫТО")) -> ОТКРЫТО | AY16: =IF(AND(AJ16>=$E16,TRUE),"ИЗУЧЕНО",IF(TRUE,"ОТКРЫТО","ЗАКРЫТО")) -> ОТКРЫТО | ... BF16: =IF(AND(AQ16>=$E16,TRUE),"ИЗУЧЕНО",IF(TRUE,"ОТКРЫТО","ЗАКРЫТО")) -> ОТКРЫТО | BG16: =IFERROR(2025+MATCH("ИЗУЧЕНО",AR16:BF16,0),"") | BH16: =IF(BG16="","",BG16+1)
A17: M1 | B17: Модели и алгоритмы | C17: I | D17: Обучение нейросетей со смешанной точностью и адаптивными оптимизаторами | E17: 20 | I17: Смешанная точность использует числовые представления разной разрядности для ускорения обучения без обязательного перехода к более мощному оборудованию. Адаптивные оптимизаторы изменяют величину шагов обучения для разных параметров нейросети. Вместе эти приёмы повышают технологическую культуру разработки моделей и позволяют эффективнее использовать имеющиеся ресурсы. Это базовое алгоритмическое усовершенствование: оно даёт один положительный эффект и ещё не требует дополнительного штрафа к ресурсам страны. | J17: + Методы построения и совершенствования моделей: +0,20 | K17: =SUMIF('Ход 2026'!$G$29:$G$38,$A17,'Ход 2026'!$I$29:$I$38)*(1+'Эффекты технологий'!J$7+'Эффекты технологий'!J$8+'Эффекты технологий'!J$9) -> 0 | L17: =SUMIF('Ход 2027'!$G$29:$G$38,$A17,'Ход 2027'!$I$29:$I$38)*(1+'Эффекты технологий'!K$7+'Эффекты технологий'!K$8+'Эффекты технологий'!K$9) -> 0 | M17: =SUMIF('Ход 2028'!$G$29:$G$38,$A17,'Ход 2028'!$I$29:$I$38)*(1+'Эффекты технологий'!L$7+'Эффекты технологий'!L$8+'Эффекты технологий'!L$9) -> 0 | N17: =SUMIF('Ход 2029'!$G$29:$G$38,$A17,'Ход 2029'!$I$29:$I$38)*(1+'Эффекты технологий'!M$7+'Эффекты технологий'!M$8+'Эффекты технологий'!M$9) -> 0 | O17: =SUMIF('Ход 2030'!$G$29:$G$38,$A17,'Ход 2030'!$I$29:$I$38)*(1+'Эффекты технологий'!N$7+'Эффекты технологий'!N$8+'Эффекты технологий'!N$9) -> 0 | P17: =SUMIF('Ход 2031'!$G$29:$G$38,$A17,'Ход 2031'!$I$29:$I$38)*(1+'Эффекты технологий'!O$7+'Эффекты технологий'!O$8+'Эффекты технологий'!O$9) -> 0 | Q17: =SUMIF('Ход 2032'!$G$29:$G$38,$A17,'Ход 2032'!$I$29:$I$38)*(1+'Эффекты технологий'!P$7+'Эффекты технологий'!P$8+'Эффекты технологий'!P$9) -> 0 | R17: =SUMIF('Ход 2033'!$G$29:$G$38,$A17,'Ход 2033'!$I$29:$I$38)*(1+'Эффекты технологий'!Q$7+'Эффекты технологий'!Q$8+'Эффекты технологий'!Q$9) -> 0 | S17: =SUMIF('Ход 2034'!$G$29:$G$38,$A17,'Ход 2034'!$I$29:$I$38)*(1+'Эффекты технологий'!R$7+'Эффекты технологий'!R$8+'Эффекты технологий'!R$9) -> 0 | T17: =SUMIF('Ход 2035'!$G$29:$G$38,$A17,'Ход 2035'!$I$29:$I$38)*(1+'Эффекты технологий'!S$7+'Эффекты технологий'!S$8+'Эффекты технологий'!S$9) -> 0 | U17: =SUMIF('Ход 2036'!$G$29:$G$38,$A17,'Ход 2036'!$I$29:$I$38)*(1+'Эффекты технологий'!T$7+'Эффекты технологий'!T$8+'Эффекты технологий'!T$9) -> 0 | V17: =SUMIF('Ход 2037'!$G$29:$G$38,$A17,'Ход 2037'!$I$29:$I$38)*(1+'Эффекты технологий'!U$7+'Эффекты технологий'!U$8+'Эффекты технологий'!U$9) -> 0 | W17: =SUMIF('Ход 2038'!$G$29:$G$38,$A17,'Ход 2038'!$I$29:$I$38)*(1+'Эффекты технологий'!V$7+'Эффекты технологий'!V$8+'Эффекты технологий'!V$9) -> 0 | X17: =SUMIF('Ход 2039'!$G$29:$G$38,$A17,'Ход 2039'!$I$29:$I$38)*(1+'Эффекты технологий'!W$7+'Эффекты технологий'!W$8+'Эффекты технологий'!W$9) -> 0 | Y17: =SUMIF('Ход 2040'!$G$29:$G$38,$A17,'Ход 2040'!$I$29:$I$38)*(1+'Эффекты технологий'!X$7+'Эффекты технологий'!X$8+'Эффекты технологий'!X$9) -> 0 | Z17: =SUM(K17:Y17) -> 0 | AA17: =MAX(0,E17-Z17) -> 20 | AB17: =BF17 -> ОТКРЫТО | AC17: =SUM($K17:K17) -> 0 | AD17: =SUM($K17:L17) -> 0 | AE17: =SUM($K17:M17) -> 0 | AF17: =SUM($K17:N17) -> 0 | AG17: =SUM($K17:O17) -> 0 | AH17: =SUM($K17:P17) -> 0 | AI17: =SUM($K17:Q17) -> 0 | AJ17: =SUM($K17:R17) -> 0 | ... AQ17: =SUM($K17:Y17) -> 0 | AR17: =IF(AND(AC17>=$E17,TRUE),"ИЗУЧЕНО",IF(TRUE,"ОТКРЫТО","ЗАКРЫТО")) -> ОТКРЫТО | AS17: =IF(AND(AD17>=$E17,TRUE),"ИЗУЧЕНО",IF(TRUE,"ОТКРЫТО","ЗАКРЫТО")) -> ОТКРЫТО | AT17: =IF(AND(AE17>=$E17,TRUE),"ИЗУЧЕНО",IF(TRUE,"ОТКРЫТО","ЗАКРЫТО")) -> ОТКРЫТО | AU17: =IF(AND(AF17>=$E17,TRUE),"ИЗУЧЕНО",IF(TRUE,"ОТКРЫТО","ЗАКРЫТО")) -> ОТКРЫТО | AV17: =IF(AND(AG17>=$E17,TRUE),"ИЗУЧЕНО",IF(TRUE,"ОТКРЫТО","ЗАКРЫТО")) -> ОТКРЫТО | AW17: =IF(AND(AH17>=$E17,TRUE),"ИЗУЧЕНО",IF(TRUE,"ОТКРЫТО","ЗАКРЫТО")) -> ОТКРЫТО | AX17: =IF(AND(AI17>=$E17,TRUE),"ИЗУЧЕНО",IF(TRUE,"ОТКРЫТО","ЗАКРЫТО")) -> ОТКРЫТО | AY17: =IF(AND(AJ17>=$E17,TRUE),"ИЗУЧЕНО",IF(TRUE,"ОТКРЫТО","ЗАКРЫТО")) -> ОТКРЫТО | ... BF17: =IF(AND(AQ17>=$E17,TRUE),"ИЗУЧЕНО",IF(TRUE,"ОТКРЫТО","ЗАКРЫТО")) -> ОТКРЫТО | BG17: =IFERROR(2025+MATCH("ИЗУЧЕНО",AR17:BF17,0),"") | BH17: =IF(BG17="","",BG17+1)
A18: M2 | B18: Модели и алгоритмы | C18: II | D18: Мультимодальные трансформеры с перекрёстным вниманием | E18: 40 | F18: M1 | I18: Мультимодальный трансформер объединяет текст, изображения, звук и другие виды информации в одной модели. Механизмы перекрёстного внимания позволяют связывать представления разных модальностей. Страна получает более богатые модельные ресурсы и средство воздействия на информационные смыслы, поэтому усиливается атака в войне Аполлона. Обучение и обслуживание таких систем требуют дополнительной вычислительной мощности и электроэнергии, что выражено небольшим энергетическим штрафом. | J18: + Модельные ресурсы: +0,30; + Атака в войне Аполлона: +10%; − Энергетические ресурсы: -0,15 | K18: =SUMIF('Ход 2026'!$G$29:$G$38,$A18,'Ход 2026'!$I$29:$I$38)*(1+'Эффекты технологий'!J$7+'Эффекты технологий'!J$8+'Эффекты технологий'!J$9) -> 0 | L18: =SUMIF('Ход 2027'!$G$29:$G$38,$A18,'Ход 2027'!$I$29:$I$38)*(1+'Эффекты технологий'!K$7+'Эффекты технологий'!K$8+'Эффекты технологий'!K$9) -> 0 | M18: =SUMIF('Ход 2028'!$G$29:$G$38,$A18,'Ход 2028'!$I$29:$I$38)*(1+'Эффекты технологий'!L$7+'Эффекты технологий'!L$8+'Эффекты технологий'!L$9) -> 0 | N18: =SUMIF('Ход 2029'!$G$29:$G$38,$A18,'Ход 2029'!$I$29:$I$38)*(1+'Эффекты технологий'!M$7+'Эффекты технологий'!M$8+'Эффекты технологий'!M$9) -> 0 | O18: =SUMIF('Ход 2030'!$G$29:$G$38,$A18,'Ход 2030'!$I$29:$I$38)*(1+'Эффекты технологий'!N$7+'Эффекты технологий'!N$8+'Эффекты технологий'!N$9) -> 0 | P18: =SUMIF('Ход 2031'!$G$29:$G$38,$A18,'Ход 2031'!$I$29:$I$38)*(1+'Эффекты технологий'!O$7+'Эффекты технологий'!O$8+'Эффекты технологий'!O$9) -> 0 | Q18: =SUMIF('Ход 2032'!$G$29:$G$38,$A18,'Ход 2032'!$I$29:$I$38)*(1+'Эффекты технологий'!P$7+'Эффекты технологий'!P$8+'Эффекты технологий'!P$9) -> 0 | R18: =SUMIF('Ход 2033'!$G$29:$G$38,$A18,'Ход 2033'!$I$29:$I$38)*(1+'Эффекты технологий'!Q$7+'Эффекты технологий'!Q$8+'Эффекты технологий'!Q$9) -> 0 | S18: =SUMIF('Ход 2034'!$G$29:$G$38,$A18,'Ход 2034'!$I$29:$I$38)*(1+'Эффекты технологий'!R$7+'Эффекты технологий'!R$8+'Эффекты технологий'!R$9) -> 0 | T18: =SUMIF('Ход 2035'!$G$29:$G$38,$A18,'Ход 2035'!$I$29:$I$38)*(1+'Эффекты технологий'!S$7+'Эффекты технологий'!S$8+'Эффекты технологий'!S$9) -> 0 | U18: =SUMIF('Ход 2036'!$G$29:$G$38,$A18,'Ход 2036'!$I$29:$I$38)*(1+'Эффекты технологий'!T$7+'Эффекты технологий'!T$8+'Эффекты технологий'!T$9) -> 0 | V18: =SUMIF('Ход 2037'!$G$29:$G$38,$A18,'Ход 2037'!$I$29:$I$38)*(1+'Эффекты технологий'!U$7+'Эффекты технологий'!U$8+'Эффекты технологий'!U$9) -> 0 | W18: =SUMIF('Ход 2038'!$G$29:$G$38,$A18,'Ход 2038'!$I$29:$I$38)*(1+'Эффекты технологий'!V$7+'Эффекты технологий'!V$8+'Эффекты технологий'!V$9) -> 0 | X18: =SUMIF('Ход 2039'!$G$29:$G$38,$A18,'Ход 2039'!$I$29:$I$38)*(1+'Эффекты технологий'!W$7+'Эффекты технологий'!W$8+'Эффекты технологий'!W$9) -> 0 | Y18: =SUMIF('Ход 2040'!$G$29:$G$38,$A18,'Ход 2040'!$I$29:$I$38)*(1+'Эффекты технологий'!X$7+'Эффекты технологий'!X$8+'Эффекты технологий'!X$9) -> 0 | Z18: =SUM(K18:Y18) -> 0 | AA18: =MAX(0,E18-Z18) -> 40 | AB18: =BF18 -> ОТКРЫТО | AC18: =SUM($K18:K18) -> 0 | AD18: =SUM($K18:L18) -> 0 | AE18: =SUM($K18:M18) -> 0 | AF18: =SUM($K18:N18) -> 0 | AG18: =SUM($K18:O18) -> 0 | AH18: =SUM($K18:P18) -> 0 | AI18: =SUM($K18:Q18) -> 0 | AJ18: =SUM($K18:R18) -> 0 | ... AQ18: =SUM($K18:Y18) -> 0 | AR18: =IF(AND(AC18>=$E18,TRUE),"ИЗУЧЕНО",IF(TRUE,"ОТКРЫТО","ЗАКРЫТО")) -> ОТКРЫТО | AS18: =IF(AND(AD18>=$E18,TRUE),"ИЗУЧЕНО",IF(TRUE,"ОТКРЫТО","ЗАКРЫТО")) -> ОТКРЫТО | AT18: =IF(AND(AE18>=$E18,TRUE),"ИЗУЧЕНО",IF(TRUE,"ОТКРЫТО","ЗАКРЫТО")) -> ОТКРЫТО | AU18: =IF(AND(AF18>=$E18,TRUE),"ИЗУЧЕНО",IF(TRUE,"ОТКРЫТО","ЗАКРЫТО")) -> ОТКРЫТО | AV18: =IF(AND(AG18>=$E18,TRUE),"ИЗУЧЕНО",IF(TRUE,"ОТКРЫТО","ЗАКРЫТО")) -> ОТКРЫТО | AW18: =IF(AND(AH18>=$E18,TRUE),"ИЗУЧЕНО",IF(TRUE,"ОТКРЫТО","ЗАКРЫТО")) -> ОТКРЫТО | AX18: =IF(AND(AI18>=$E18,TRUE),"ИЗУЧЕНО",IF(TRUE,"ОТКРЫТО","ЗАКРЫТО")) -> ОТКРЫТО | AY18: =IF(AND(AJ18>=$E18,TRUE),"ИЗУЧЕНО",IF(TRUE,"ОТКРЫТО","ЗАКРЫТО")) -> ОТКРЫТО | ... BF18: =IF(AND(AQ18>=$E18,TRUE),"ИЗУЧЕНО",IF(TRUE,"ОТКРЫТО","ЗАКРЫТО")) -> ОТКРЫТО | BG18: =IFERROR(2025+MATCH("ИЗУЧЕНО",AR18:BF18,0),"") | BH18: =IF(BG18="","",BG18+1)
A19: M3 | B19: Модели и алгоритмы | C19: II | D19: Нейросетевые модели рассуждения с поиском и проверкой решений | E19: 45 | F19: M1 | I19: Модель не ограничивается однократной генерацией ответа: она предлагает несколько вариантов решения, выполняет поиск по альтернативам и применяет процедуры проверки. Такой подход полезен в сложных задачах планирования и анализа, где результат можно оценивать по внешним критериям. Технология одновременно улучшает методическую базу, познание и оценку моделей. Плата за это - дополнительные вычисления при каждом сложном запросе, а значит, повышенная энергетическая нагрузка. | J19: + Методы построения и совершенствования моделей: +0,30; + Прирост сферы «Познание»: +0,08/год; + Ресурсы оценки: +0,20; − Энергетические ресурсы: -0,25 | K19: =SUMIF('Ход 2026'!$G$29:$G$38,$A19,'Ход 2026'!$I$29:$I$38)*(1+'Эффекты технологий'!J$7+'Эффекты технологий'!J$8+'Эффекты технологий'!J$9) -> 0 | L19: =SUMIF('Ход 2027'!$G$29:$G$38,$A19,'Ход 2027'!$I$29:$I$38)*(1+'Эффекты технологий'!K$7+'Эффекты технологий'!K$8+'Эффекты технологий'!K$9) -> 0 | M19: =SUMIF('Ход 2028'!$G$29:$G$38,$A19,'Ход 2028'!$I$29:$I$38)*(1+'Эффекты технологий'!L$7+'Эффекты технологий'!L$8+'Эффекты технологий'!L$9) -> 0 | N19: =SUMIF('Ход 2029'!$G$29:$G$38,$A19,'Ход 2029'!$I$29:$I$38)*(1+'Эффекты технологий'!M$7+'Эффекты технологий'!M$8+'Эффекты технологий'!M$9) -> 0 | O19: =SUMIF('Ход 2030'!$G$29:$G$38,$A19,'Ход 2030'!$I$29:$I$38)*(1+'Эффекты технологий'!N$7+'Эффекты технологий'!N$8+'Эффекты технологий'!N$9) -> 0 | P19: =SUMIF('Ход 2031'!$G$29:$G$38,$A19,'Ход 2031'!$I$29:$I$38)*(1+'Эффекты технологий'!O$7+'Эффекты технологий'!O$8+'Эффекты технологий'!O$9) -> 0 | Q19: =SUMIF('Ход 2032'!$G$29:$G$38,$A19,'Ход 2032'!$I$29:$I$38)*(1+'Эффекты технологий'!P$7+'Эффекты технологий'!P$8+'Эффекты технологий'!P$9) -> 0 | R19: =SUMIF('Ход 2033'!$G$29:$G$38,$A19,'Ход 2033'!$I$29:$I$38)*(1+'Эффекты технологий'!Q$7+'Эффекты технологий'!Q$8+'Эффекты технологий'!Q$9) -> 0 | S19: =SUMIF('Ход 2034'!$G$29:$G$38,$A19,'Ход 2034'!$I$29:$I$38)*(1+'Эффекты технологий'!R$7+'Эффекты технологий'!R$8+'Эффекты технологий'!R$9) -> 0 | T19: =SUMIF('Ход 2035'!$G$29:$G$38,$A19,'Ход 2035'!$I$29:$I$38)*(1+'Эффекты технологий'!S$7+'Эффекты технологий'!S$8+'Эффекты технологий'!S$9) -> 0 | U19: =SUMIF('Ход 2036'!$G$29:$G$38,$A19,'Ход 2036'!$I$29:$I$38)*(1+'Эффекты технологий'!T$7+'Эффекты технологий'!T$8+'Эффекты технологий'!T$9) -> 0 | V19: =SUMIF('Ход 2037'!$G$29:$G$38,$A19,'Ход 2037'!$I$29:$I$38)*(1+'Эффекты технологий'!U$7+'Эффекты технологий'!U$8+'Эффекты технологий'!U$9) -> 0 | W19: =SUMIF('Ход 2038'!$G$29:$G$38,$A19,'Ход 2038'!$I$29:$I$38)*(1+'Эффекты технологий'!V$7+'Эффекты технологий'!V$8+'Эффекты технологий'!V$9) -> 0 | X19: =SUMIF('Ход 2039'!$G$29:$G$38,$A19,'Ход 2039'!$I$29:$I$38)*(1+'Эффекты технологий'!W$7+'Эффекты технологий'!W$8+'Эффекты технологий'!W$9) -> 0 | Y19: =SUMIF('Ход 2040'!$G$29:$G$38,$A19,'Ход 2040'!$I$29:$I$38)*(1+'Эффекты технологий'!X$7+'Эффекты технологий'!X$8+'Эффекты технологий'!X$9) -> 0 | Z19: =SUM(K19:Y19) -> 0 | AA19: =MAX(0,E19-Z19) -> 45 | AB19: =BF19 -> ОТКРЫТО | AC19: =SUM($K19:K19) -> 0 | AD19: =SUM($K19:L19) -> 0 | AE19: =SUM($K19:M19) -> 0 | AF19: =SUM($K19:N19) -> 0 | AG19: =SUM($K19:O19) -> 0 | AH19: =SUM($K19:P19) -> 0 | AI19: =SUM($K19:Q19) -> 0 | AJ19: =SUM($K19:R19) -> 0 | ... AQ19: =SUM($K19:Y19) -> 0 | AR19: =IF(AND(AC19>=$E19,TRUE),"ИЗУЧЕНО",IF(TRUE,"ОТКРЫТО","ЗАКРЫТО")) -> ОТКРЫТО | AS19: =IF(AND(AD19>=$E19,TRUE),"ИЗУЧЕНО",IF(TRUE,"ОТКРЫТО","ЗАКРЫТО")) -> ОТКРЫТО | AT19: =IF(AND(AE19>=$E19,TRUE),"ИЗУЧЕНО",IF(TRUE,"ОТКРЫТО","ЗАКРЫТО")) -> ОТКРЫТО | AU19: =IF(AND(AF19>=$E19,TRUE),"ИЗУЧЕНО",IF(TRUE,"ОТКРЫТО","ЗАКРЫТО")) -> ОТКРЫТО | AV19: =IF(AND(AG19>=$E19,TRUE),"ИЗУЧЕНО",IF(TRUE,"ОТКРЫТО","ЗАКРЫТО")) -> ОТКРЫТО | AW19: =IF(AND(AH19>=$E19,TRUE),"ИЗУЧЕНО",IF(TRUE,"ОТКРЫТО","ЗАКРЫТО")) -> ОТКРЫТО | AX19: =IF(AND(AI19>=$E19,TRUE),"ИЗУЧЕНО",IF(TRUE,"ОТКРЫТО","ЗАКРЫТО")) -> ОТКРЫТО | AY19: =IF(AND(AJ19>=$E19,TRUE),"ИЗУЧЕНО",IF(TRUE,"ОТКРЫТО","ЗАКРЫТО")) -> ОТКРЫТО | ... BF19: =IF(AND(AQ19>=$E19,TRUE),"ИЗУЧЕНО",IF(TRUE,"ОТКРЫТО","ЗАКРЫТО")) -> ОТКРЫТО | BG19: =IFERROR(2025+MATCH("ИЗУЧЕНО",AR19:BF19,0),"") | BH19: =IF(BG19="","",BG19+1)
A20: M4 | B20: Модели и алгоритмы | C20: III | D20: Непрерывное обучение нейросетей с адаптерами и буферами воспроизведения | E20: 65 | F20: M2 | G20: M3 | I20: Адаптеры позволяют обновлять отдельные части модели, а буферы воспроизведения - повторно использовать прошлые данные, уменьшая риск забывания ранее освоенных задач. Такие модели быстрее приспосабливаются к изменяющейся среде и полезны для управленческих процессов. Постоянные обновления требуют непрерывной оценки качества, дополнительных вычислений и контроля безопасности. Поэтому технология увеличивает четыре показателя, но одновременно нагружает энергосистему и усложняет защиту модельного контура. | J20: + Модельные ресурсы: +0,40; прирост +0,08/год; + Методы построения и совершенствования моделей: +0,20; + Прирост сферы «Управление»: +0,05/год; + Ресурсы оценки: +0,20; − Энергетические ресурсы: -0,25; − Кибербезопасностные ресурсы: -0,15 | K20: =SUMIF('Ход 2026'!$G$29:$G$38,$A20,'Ход 2026'!$I$29:$I$38)*(1+'Эффекты технологий'!J$7+'Эффекты технологий'!J$8+'Эффекты технологий'!J$9) -> 0 | L20: =SUMIF('Ход 2027'!$G$29:$G$38,$A20,'Ход 2027'!$I$29:$I$38)*(1+'Эффекты технологий'!K$7+'Эффекты технологий'!K$8+'Эффекты технологий'!K$9) -> 0 | M20: =SUMIF('Ход 2028'!$G$29:$G$38,$A20,'Ход 2028'!$I$29:$I$38)*(1+'Эффекты технологий'!L$7+'Эффекты технологий'!L$8+'Эффекты технологий'!L$9) -> 0 | N20: =SUMIF('Ход 2029'!$G$29:$G$38,$A20,'Ход 2029'!$I$29:$I$38)*(1+'Эффекты технологий'!M$7+'Эффекты технологий'!M$8+'Эффекты технологий'!M$9) -> 0 | O20: =SUMIF('Ход 2030'!$G$29:$G$38,$A20,'Ход 2030'!$I$29:$I$38)*(1+'Эффекты технологий'!N$7+'Эффекты технологий'!N$8+'Эффекты технологий'!N$9) -> 0 | P20: =SUMIF('Ход 2031'!$G$29:$G$38,$A20,'Ход 2031'!$I$29:$I$38)*(1+'Эффекты технологий'!O$7+'Эффекты технологий'!O$8+'Эффекты технологий'!O$9) -> 0 | Q20: =SUMIF('Ход 2032'!$G$29:$G$38,$A20,'Ход 2032'!$I$29:$I$38)*(1+'Эффекты технологий'!P$7+'Эффекты технологий'!P$8+'Эффекты технологий'!P$9) -> 0 | R20: =SUMIF('Ход 2033'!$G$29:$G$38,$A20,'Ход 2033'!$I$29:$I$38)*(1+'Эффекты технологий'!Q$7+'Эффекты технологий'!Q$8+'Эффекты технологий'!Q$9) -> 0 | S20: =SUMIF('Ход 2034'!$G$29:$G$38,$A20,'Ход 2034'!$I$29:$I$38)*(1+'Эффекты технологий'!R$7+'Эффекты технологий'!R$8+'Эффекты технологий'!R$9) -> 0 | T20: =SUMIF('Ход 2035'!$G$29:$G$38,$A20,'Ход 2035'!$I$29:$I$38)*(1+'Эффекты технологий'!S$7+'Эффекты технологий'!S$8+'Эффекты технологий'!S$9) -> 0 | U20: =SUMIF('Ход 2036'!$G$29:$G$38,$A20,'Ход 2036'!$I$29:$I$38)*(1+'Эффекты технологий'!T$7+'Эффекты технологий'!T$8+'Эффекты технологий'!T$9) -> 0 | V20: =SUMIF('Ход 2037'!$G$29:$G$38,$A20,'Ход 2037'!$I$29:$I$38)*(1+'Эффекты технологий'!U$7+'Эффекты технологий'!U$8+'Эффекты технологий'!U$9) -> 0 | W20: =SUMIF('Ход 2038'!$G$29:$G$38,$A20,'Ход 2038'!$I$29:$I$38)*(1+'Эффекты технологий'!V$7+'Эффекты технологий'!V$8+'Эффекты технологий'!V$9) -> 0 | X20: =SUMIF('Ход 2039'!$G$29:$G$38,$A20,'Ход 2039'!$I$29:$I$38)*(1+'Эффекты технологий'!W$7+'Эффекты технологий'!W$8+'Эффекты технологий'!W$9) -> 0 | Y20: =SUMIF('Ход 2040'!$G$29:$G$38,$A20,'Ход 2040'!$I$29:$I$38)*(1+'Эффекты технологий'!X$7+'Эффекты технологий'!X$8+'Эффекты технологий'!X$9) -> 0 | Z20: =SUM(K20:Y20) -> 0 | AA20: =MAX(0,E20-Z20) -> 65 | AB20: =BF20 -> ОТКРЫТО | AC20: =SUM($K20:K20) -> 0 | AD20: =SUM($K20:L20) -> 0 | AE20: =SUM($K20:M20) -> 0 | AF20: =SUM($K20:N20) -> 0 | AG20: =SUM($K20:O20) -> 0 | AH20: =SUM($K20:P20) -> 0 | AI20: =SUM($K20:Q20) -> 0 | AJ20: =SUM($K20:R20) -> 0 | ... AQ20: =SUM($K20:Y20) -> 0 | AR20: =IF(AND(AC20>=$E20,TRUE),"ИЗУЧЕНО",IF(TRUE,"ОТКРЫТО","ЗАКРЫТО")) -> ОТКРЫТО | AS20: =IF(AND(AD20>=$E20,TRUE),"ИЗУЧЕНО",IF(TRUE,"ОТКРЫТО","ЗАКРЫТО")) -> ОТКРЫТО | AT20: =IF(AND(AE20>=$E20,TRUE),"ИЗУЧЕНО",IF(TRUE,"ОТКРЫТО","ЗАКРЫТО")) -> ОТКРЫТО | AU20: =IF(AND(AF20>=$E20,TRUE),"ИЗУЧЕНО",IF(TRUE,"ОТКРЫТО","ЗАКРЫТО")) -> ОТКРЫТО | AV20: =IF(AND(AG20>=$E20,TRUE),"ИЗУЧЕНО",IF(TRUE,"ОТКРЫТО","ЗАКРЫТО")) -> ОТКРЫТО | AW20: =IF(AND(AH20>=$E20,TRUE),"ИЗУЧЕНО",IF(TRUE,"ОТКРЫТО","ЗАКРЫТО")) -> ОТКРЫТО | AX20: =IF(AND(AI20>=$E20,TRUE),"ИЗУЧЕНО",IF(TRUE,"ОТКРЫТО","ЗАКРЫТО")) -> ОТКРЫТО | AY20: =IF(AND(AJ20>=$E20,TRUE),"ИЗУЧЕНО",IF(TRUE,"ОТКРЫТО","ЗАКРЫТО")) -> ОТКРЫТО | ... BF20: =IF(AND(AQ20>=$E20,TRUE),"ИЗУЧЕНО",IF(TRUE,"ОТКРЫТО","ЗАКРЫТО")) -> ОТКРЫТО | BG20: =IFERROR(2025+MATCH("ИЗУЧЕНО",AR20:BF20,0),"") | BH20: =IF(BG20="","",BG20+1)
A21: M5 | B21: Модели и алгоритмы | C21: IV | D21: Латентные модели мира с причинным и контрфактическим прогнозированием | E21: 100 | F21: M4 | I21: Модель мира строит внутреннее представление изменений среды и позволяет проверять альтернативные сценарии: что произошло бы при другом решении. Это расширяет возможности прогноза, управления и разработки стратегий в условиях неопределённости. Бонус к войне Афины отражает преимущество в борьбе за информационные потоки и принятие решений. При этом сложность модели повышает ресурсопотребление, а чрезмерная опора на непрозрачные прогнозы может снижать общественное доверие. | J21: + Сфера «Познание»: +0,30; прирост +0,10/год; + Модельные ресурсы: +0,25; + Прирост сферы «Государственное управление»: +0,08/год; + Математико-алгоритмические ресурсы: +0,20; + Атака в войне Афины: +10%; − Энергетические ресурсы: -0,30; − Вода и ресурс отвода тепла: -0,20; − Социальное доверие: -0,15 | K21: =SUMIF('Ход 2026'!$G$29:$G$38,$A21,'Ход 2026'!$I$29:$I$38)*(1+'Эффекты технологий'!J$7+'Эффекты технологий'!J$8+'Эффекты технологий'!J$9) -> 0 | L21: =SUMIF('Ход 2027'!$G$29:$G$38,$A21,'Ход 2027'!$I$29:$I$38)*(1+'Эффекты технологий'!K$7+'Эффекты технологий'!K$8+'Эффекты технологий'!K$9) -> 0 | M21: =SUMIF('Ход 2028'!$G$29:$G$38,$A21,'Ход 2028'!$I$29:$I$38)*(1+'Эффекты технологий'!L$7+'Эффекты технологий'!L$8+'Эффекты технологий'!L$9) -> 0 | N21: =SUMIF('Ход 2029'!$G$29:$G$38,$A21,'Ход 2029'!$I$29:$I$38)*(1+'Эффекты технологий'!M$7+'Эффекты технологий'!M$8+'Эффекты технологий'!M$9) -> 0 | O21: =SUMIF('Ход 2030'!$G$29:$G$38,$A21,'Ход 2030'!$I$29:$I$38)*(1+'Эффекты технологий'!N$7+'Эффекты технологий'!N$8+'Эффекты технологий'!N$9) -> 0 | P21: =SUMIF('Ход 2031'!$G$29:$G$38,$A21,'Ход 2031'!$I$29:$I$38)*(1+'Эффекты технологий'!O$7+'Эффекты технологий'!O$8+'Эффекты технологий'!O$9) -> 0 | Q21: =SUMIF('Ход 2032'!$G$29:$G$38,$A21,'Ход 2032'!$I$29:$I$38)*(1+'Эффекты технологий'!P$7+'Эффекты технологий'!P$8+'Эффекты технологий'!P$9) -> 0 | R21: =SUMIF('Ход 2033'!$G$29:$G$38,$A21,'Ход 2033'!$I$29:$I$38)*(1+'Эффекты технологий'!Q$7+'Эффекты технологий'!Q$8+'Эффекты технологий'!Q$9) -> 0 | S21: =SUMIF('Ход 2034'!$G$29:$G$38,$A21,'Ход 2034'!$I$29:$I$38)*(1+'Эффекты технологий'!R$7+'Эффекты технологий'!R$8+'Эффекты технологий'!R$9) -> 0 | T21: =SUMIF('Ход 2035'!$G$29:$G$38,$A21,'Ход 2035'!$I$29:$I$38)*(1+'Эффекты технологий'!S$7+'Эффекты технологий'!S$8+'Эффекты технологий'!S$9) -> 0 | U21: =SUMIF('Ход 2036'!$G$29:$G$38,$A21,'Ход 2036'!$I$29:$I$38)*(1+'Эффекты технологий'!T$7+'Эффекты технологий'!T$8+'Эффекты технологий'!T$9) -> 0 | V21: =SUMIF('Ход 2037'!$G$29:$G$38,$A21,'Ход 2037'!$I$29:$I$38)*(1+'Эффекты технологий'!U$7+'Эффекты технологий'!U$8+'Эффекты технологий'!U$9) -> 0 | W21: =SUMIF('Ход 2038'!$G$29:$G$38,$A21,'Ход 2038'!$I$29:$I$38)*(1+'Эффекты технологий'!V$7+'Эффекты технологий'!V$8+'Эффекты технологий'!V$9) -> 0 | X21: =SUMIF('Ход 2039'!$G$29:$G$38,$A21,'Ход 2039'!$I$29:$I$38)*(1+'Эффекты технологий'!W$7+'Эффекты технологий'!W$8+'Эффекты технологий'!W$9) -> 0 | Y21: =SUMIF('Ход 2040'!$G$29:$G$38,$A21,'Ход 2040'!$I$29:$I$38)*(1+'Эффекты технологий'!X$7+'Эффекты технологий'!X$8+'Эффекты технологий'!X$9) -> 0 | Z21: =SUM(K21:Y21) -> 0 | AA21: =MAX(0,E21-Z21) -> 100 | AB21: =BF21 -> ОТКРЫТО | AC21: =SUM($K21:K21) -> 0 | AD21: =SUM($K21:L21) -> 0 | AE21: =SUM($K21:M21) -> 0 | AF21: =SUM($K21:N21) -> 0 | AG21: =SUM($K21:O21) -> 0 | AH21: =SUM($K21:P21) -> 0 | AI21: =SUM($K21:Q21) -> 0 | AJ21: =SUM($K21:R21) -> 0 | ... AQ21: =SUM($K21:Y21) -> 0 | AR21: =IF(AND(AC21>=$E21,TRUE),"ИЗУЧЕНО",IF(TRUE,"ОТКРЫТО","ЗАКРЫТО")) -> ОТКРЫТО | AS21: =IF(AND(AD21>=$E21,TRUE),"ИЗУЧЕНО",IF(TRUE,"ОТКРЫТО","ЗАКРЫТО")) -> ОТКРЫТО | AT21: =IF(AND(AE21>=$E21,TRUE),"ИЗУЧЕНО",IF(TRUE,"ОТКРЫТО","ЗАКРЫТО")) -> ОТКРЫТО | AU21: =IF(AND(AF21>=$E21,TRUE),"ИЗУЧЕНО",IF(TRUE,"ОТКРЫТО","ЗАКРЫТО")) -> ОТКРЫТО | AV21: =IF(AND(AG21>=$E21,TRUE),"ИЗУЧЕНО",IF(TRUE,"ОТКРЫТО","ЗАКРЫТО")) -> ОТКРЫТО | AW21: =IF(AND(AH21>=$E21,TRUE),"ИЗУЧЕНО",IF(TRUE,"ОТКРЫТО","ЗАКРЫТО")) -> ОТКРЫТО | AX21: =IF(AND(AI21>=$E21,TRUE),"ИЗУЧЕНО",IF(TRUE,"ОТКРЫТО","ЗАКРЫТО")) -> ОТКРЫТО | AY21: =IF(AND(AJ21>=$E21,TRUE),"ИЗУЧЕНО",IF(TRUE,"ОТКРЫТО","ЗАКРЫТО")) -> ОТКРЫТО | ... BF21: =IF(AND(AQ21>=$E21,TRUE),"ИЗУЧЕНО",IF(TRUE,"ОТКРЫТО","ЗАКРЫТО")) -> ОТКРЫТО | BG21: =IFERROR(2025+MATCH("ИЗУЧЕНО",AR21:BF21,0),"") | BH21: =IF(BG21="","",BG21+1)
A22: M6 | B22: Модели и алгоритмы | C22: V | D22: Автоматизированный поиск архитектур и самообновление нейросетей | E22: 155 | F22: M5 | I22: Исследовательский контур самостоятельно предлагает новые архитектуры нейросетей, обучает кандидатов, сравнивает результаты и обновляет наиболее успешные модели. Человек определяет цели и границы экспериментов, но большая часть технического перебора автоматизирована. Это ускоряет развитие моделей и смежных агентных исследований. Вместе с тем поиск требует больших вычислительных серий, охлаждения и финансирования; повышение автономности экспериментов также усиливает проблему общественного контроля. | J22: + Прирост методов построения и совершенствования моделей: +0,15/год; + Прирост модельных ресурсов: +0,10/год; + Математико-алгоритмические ресурсы: +0,25; + Ресурсы оценки: +0,20; + Прирост сферы «Познание»: +0,08/год; + Эффективность науки для ветвей M, A, X: +15%; − Энергетические ресурсы: -0,40; − Вода и ресурс отвода тепла: -0,25; − Финансовые ресурсы: -0,20; − Социальное доверие: -0,20 | K22: =SUMIF('Ход 2026'!$G$29:$G$38,$A22,'Ход 2026'!$I$29:$I$38)*(1+'Эффекты технологий'!J$7+'Эффекты технологий'!J$8+'Эффекты технологий'!J$9) -> 0 | L22: =SUMIF('Ход 2027'!$G$29:$G$38,$A22,'Ход 2027'!$I$29:$I$38)*(1+'Эффекты технологий'!K$7+'Эффекты технологий'!K$8+'Эффекты технологий'!K$9) -> 0 | M22: =SUMIF('Ход 2028'!$G$29:$G$38,$A22,'Ход 2028'!$I$29:$I$38)*(1+'Эффекты технологий'!L$7+'Эффекты технологий'!L$8+'Эффекты технологий'!L$9) -> 0 | N22: =SUMIF('Ход 2029'!$G$29:$G$38,$A22,'Ход 2029'!$I$29:$I$38)*(1+'Эффекты технологий'!M$7+'Эффекты технологий'!M$8+'Эффекты технологий'!M$9) -> 0 | O22: =SUMIF('Ход 2030'!$G$29:$G$38,$A22,'Ход 2030'!$I$29:$I$38)*(1+'Эффекты технологий'!N$7+'Эффекты технологий'!N$8+'Эффекты технологий'!N$9) -> 0 | P22: =SUMIF('Ход 2031'!$G$29:$G$38,$A22,'Ход 2031'!$I$29:$I$38)*(1+'Эффекты технологий'!O$7+'Эффекты технологий'!O$8+'Эффекты технологий'!O$9) -> 0 | Q22: =SUMIF('Ход 2032'!$G$29:$G$38,$A22,'Ход 2032'!$I$29:$I$38)*(1+'Эффекты технологий'!P$7+'Эффекты технологий'!P$8+'Эффекты технологий'!P$9) -> 0 | R22: =SUMIF('Ход 2033'!$G$29:$G$38,$A22,'Ход 2033'!$I$29:$I$38)*(1+'Эффекты технологий'!Q$7+'Эффекты технологий'!Q$8+'Эффекты технологий'!Q$9) -> 0 | S22: =SUMIF('Ход 2034'!$G$29:$G$38,$A22,'Ход 2034'!$I$29:$I$38)*(1+'Эффекты технологий'!R$7+'Эффекты технологий'!R$8+'Эффекты технологий'!R$9) -> 0 | T22: =SUMIF('Ход 2035'!$G$29:$G$38,$A22,'Ход 2035'!$I$29:$I$38)*(1+'Эффекты технологий'!S$7+'Эффекты технологий'!S$8+'Эффекты технологий'!S$9) -> 0 | U22: =SUMIF('Ход 2036'!$G$29:$G$38,$A22,'Ход 2036'!$I$29:$I$38)*(1+'Эффекты технологий'!T$7+'Эффекты технологий'!T$8+'Эффекты технологий'!T$9) -> 0 | V22: =SUMIF('Ход 2037'!$G$29:$G$38,$A22,'Ход 2037'!$I$29:$I$38)*(1+'Эффекты технологий'!U$7+'Эффекты технологий'!U$8+'Эффекты технологий'!U$9) -> 0 | W22: =SUMIF('Ход 2038'!$G$29:$G$38,$A22,'Ход 2038'!$I$29:$I$38)*(1+'Эффекты технологий'!V$7+'Эффекты технологий'!V$8+'Эффекты технологий'!V$9) -> 0 | X22: =SUMIF('Ход 2039'!$G$29:$G$38,$A22,'Ход 2039'!$I$29:$I$38)*(1+'Эффекты технологий'!W$7+'Эффекты технологий'!W$8+'Эффекты технологий'!W$9) -> 0 | Y22: =SUMIF('Ход 2040'!$G$29:$G$38,$A22,'Ход 2040'!$I$29:$I$38)*(1+'Эффекты технологий'!X$7+'Эффекты технологий'!X$8+'Эффекты технологий'!X$9) -> 0 | Z22: =SUM(K22:Y22) -> 0 | AA22: =MAX(0,E22-Z22) -> 155 | AB22: =BF22 -> ОТКРЫТО | AC22: =SUM($K22:K22) -> 0 | AD22: =SUM($K22:L22) -> 0 | AE22: =SUM($K22:M22) -> 0 | AF22: =SUM($K22:N22) -> 0 | AG22: =SUM($K22:O22) -> 0 | AH22: =SUM($K22:P22) -> 0 | AI22: =SUM($K22:Q22) -> 0 | AJ22: =SUM($K22:R22) -> 0 | ... AQ22: =SUM($K22:Y22) -> 0 | AR22: =IF(AND(AC22>=$E22,TRUE),"ИЗУЧЕНО",IF(TRUE,"ОТКРЫТО","ЗАКРЫТО")) -> ОТКРЫТО | AS22: =IF(AND(AD22>=$E22,TRUE),"ИЗУЧЕНО",IF(TRUE,"ОТКРЫТО","ЗАКРЫТО")) -> ОТКРЫТО | AT22: =IF(AND(AE22>=$E22,TRUE),"ИЗУЧЕНО",IF(TRUE,"ОТКРЫТО","ЗАКРЫТО")) -> ОТКРЫТО | AU22: =IF(AND(AF22>=$E22,TRUE),"ИЗУЧЕНО",IF(TRUE,"ОТКРЫТО","ЗАКРЫТО")) -> ОТКРЫТО | AV22: =IF(AND(AG22>=$E22,TRUE),"ИЗУЧЕНО",IF(TRUE,"ОТКРЫТО","ЗАКРЫТО")) -> ОТКРЫТО | AW22: =IF(AND(AH22>=$E22,TRUE),"ИЗУЧЕНО",IF(TRUE,"ОТКРЫТО","ЗАКРЫТО")) -> ОТКРЫТО | AX22: =IF(AND(AI22>=$E22,TRUE),"ИЗУЧЕНО",IF(TRUE,"ОТКРЫТО","ЗАКРЫТО")) -> ОТКРЫТО | AY22: =IF(AND(AJ22>=$E22,TRUE),"ИЗУЧЕНО",IF(TRUE,"ОТКРЫТО","ЗАКРЫТО")) -> ОТКРЫТО | ... BF22: =IF(AND(AQ22>=$E22,TRUE),"ИЗУЧЕНО",IF(TRUE,"ОТКРЫТО","ЗАКРЫТО")) -> ОТКРЫТО | BG22: =IFERROR(2025+MATCH("ИЗУЧЕНО",AR22:BF22,0),"") | BH22: =IF(BG22="","",BG22+1)
A23: D1 | B23: Данные и знания | C23: I | D23: Унифицированные API и схемы обмена данными | E23: 20 | I23: Разные информационные системы начинают описывать данные в согласованных форматах и обмениваться ими через документированные программные интерфейсы. Это снижает стоимость подключения новых источников и облегчает передачу информации между ведомствами и организациями. Выигрыш направлен прежде всего на интеграционные ресурсы: объём данных сам по себе ещё не возрастает, но существующие массивы становятся совместимее. Первый шаг не предполагает заметного дополнительного постоянного расхода ресурсов. | J23: + Интеграционные ресурсы: +0,20 | K23: =SUMIF('Ход 2026'!$G$29:$G$38,$A23,'Ход 2026'!$I$29:$I$38)*(1+'Эффекты технологий'!J$7) -> 0 | L23: =SUMIF('Ход 2027'!$G$29:$G$38,$A23,'Ход 2027'!$I$29:$I$38)*(1+'Эффекты технологий'!K$7) -> 0 | M23: =SUMIF('Ход 2028'!$G$29:$G$38,$A23,'Ход 2028'!$I$29:$I$38)*(1+'Эффекты технологий'!L$7) -> 0 | N23: =SUMIF('Ход 2029'!$G$29:$G$38,$A23,'Ход 2029'!$I$29:$I$38)*(1+'Эффекты технологий'!M$7) -> 0 | O23: =SUMIF('Ход 2030'!$G$29:$G$38,$A23,'Ход 2030'!$I$29:$I$38)*(1+'Эффекты технологий'!N$7) -> 0 | P23: =SUMIF('Ход 2031'!$G$29:$G$38,$A23,'Ход 2031'!$I$29:$I$38)*(1+'Эффекты технологий'!O$7) -> 0 | Q23: =SUMIF('Ход 2032'!$G$29:$G$38,$A23,'Ход 2032'!$I$29:$I$38)*(1+'Эффекты технологий'!P$7) -> 0 | R23: =SUMIF('Ход 2033'!$G$29:$G$38,$A23,'Ход 2033'!$I$29:$I$38)*(1+'Эффекты технологий'!Q$7) -> 0 | S23: =SUMIF('Ход 2034'!$G$29:$G$38,$A23,'Ход 2034'!$I$29:$I$38)*(1+'Эффекты технологий'!R$7) -> 0 | T23: =SUMIF('Ход 2035'!$G$29:$G$38,$A23,'Ход 2035'!$I$29:$I$38)*(1+'Эффекты технологий'!S$7) -> 0 | U23: =SUMIF('Ход 2036'!$G$29:$G$38,$A23,'Ход 2036'!$I$29:$I$38)*(1+'Эффекты технологий'!T$7) -> 0 | V23: =SUMIF('Ход 2037'!$G$29:$G$38,$A23,'Ход 2037'!$I$29:$I$38)*(1+'Эффекты технологий'!U$7) -> 0 | W23: =SUMIF('Ход 2038'!$G$29:$G$38,$A23,'Ход 2038'!$I$29:$I$38)*(1+'Эффекты технологий'!V$7) -> 0 | X23: =SUMIF('Ход 2039'!$G$29:$G$38,$A23,'Ход 2039'!$I$29:$I$38)*(1+'Эффекты технологий'!W$7) -> 0 | Y23: =SUMIF('Ход 2040'!$G$29:$G$38,$A23,'Ход 2040'!$I$29:$I$38)*(1+'Эффекты технологий'!X$7) -> 0 | Z23: =SUM(K23:Y23) -> 0 | AA23: =MAX(0,E23-Z23) -> 20 | AB23: =BF23 -> ОТКРЫТО | AC23: =SUM($K23:K23) -> 0 | AD23: =SUM($K23:L23) -> 0 | AE23: =SUM($K23:M23) -> 0 | AF23: =SUM($K23:N23) -> 0 | AG23: =SUM($K23:O23) -> 0 | AH23: =SUM($K23:P23) -> 0 | AI23: =SUM($K23:Q23) -> 0 | AJ23: =SUM($K23:R23) -> 0 | ... AQ23: =SUM($K23:Y23) -> 0 | AR23: =IF(AND(AC23>=$E23,TRUE),"ИЗУЧЕНО",IF(TRUE,"ОТКРЫТО","ЗАКРЫТО")) -> ОТКРЫТО | AS23: =IF(AND(AD23>=$E23,TRUE),"ИЗУЧЕНО",IF(TRUE,"ОТКРЫТО","ЗАКРЫТО")) -> ОТКРЫТО | AT23: =IF(AND(AE23>=$E23,TRUE),"ИЗУЧЕНО",IF(TRUE,"ОТКРЫТО","ЗАКРЫТО")) -> ОТКРЫТО | AU23: =IF(AND(AF23>=$E23,TRUE),"ИЗУЧЕНО",IF(TRUE,"ОТКРЫТО","ЗАКРЫТО")) -> ОТКРЫТО | AV23: =IF(AND(AG23>=$E23,TRUE),"ИЗУЧЕНО",IF(TRUE,"ОТКРЫТО","ЗАКРЫТО")) -> ОТКРЫТО | AW23: =IF(AND(AH23>=$E23,TRUE),"ИЗУЧЕНО",IF(TRUE,"ОТКРЫТО","ЗАКРЫТО")) -> ОТКРЫТО | AX23: =IF(AND(AI23>=$E23,TRUE),"ИЗУЧЕНО",IF(TRUE,"ОТКРЫТО","ЗАКРЫТО")) -> ОТКРЫТО | AY23: =IF(AND(AJ23>=$E23,TRUE),"ИЗУЧЕНО",IF(TRUE,"ОТКРЫТО","ЗАКРЫТО")) -> ОТКРЫТО | ... BF23: =IF(AND(AQ23>=$E23,TRUE),"ИЗУЧЕНО",IF(TRUE,"ОТКРЫТО","ЗАКРЫТО")) -> ОТКРЫТО | BG23: =IFERROR(2025+MATCH("ИЗУЧЕНО",AR23:BF23,0),"") | BH23: =IF(BG23="","",BG23+1)
A24: D2 | B24: Данные и знания | C24: II | D24: Генерация синтетических данных диффузионными и генеративно-состязательными моделями | E24: 35 | F24: D1 | I24: Генеративные методы создают новые искусственные наблюдения, изображения и сценарии на основе структуры исходных данных. Они помогают расширять редкие обучающие выборки и проверять модели на нестандартных ситуациях. Вместе с ростом производных данных развиваются методы оценки их качества. Однако широкое появление синтетических материалов затрудняет проверку происхождения информации и может уменьшать доверие к цифровому контенту. | J24: + Производные данные: +0,30; прирост +0,10/год; + Ресурсы оценки: +0,20; − Социальное доверие: -0,10 | K24: =SUMIF('Ход 2026'!$G$29:$G$38,$A24,'Ход 2026'!$I$29:$I$38)*(1+'Эффекты технологий'!J$7) -> 0 | L24: =SUMIF('Ход 2027'!$G$29:$G$38,$A24,'Ход 2027'!$I$29:$I$38)*(1+'Эффекты технологий'!K$7) -> 0 | M24: =SUMIF('Ход 2028'!$G$29:$G$38,$A24,'Ход 2028'!$I$29:$I$38)*(1+'Эффекты технологий'!L$7) -> 0 | N24: =SUMIF('Ход 2029'!$G$29:$G$38,$A24,'Ход 2029'!$I$29:$I$38)*(1+'Эффекты технологий'!M$7) -> 0 | O24: =SUMIF('Ход 2030'!$G$29:$G$38,$A24,'Ход 2030'!$I$29:$I$38)*(1+'Эффекты технологий'!N$7) -> 0 | P24: =SUMIF('Ход 2031'!$G$29:$G$38,$A24,'Ход 2031'!$I$29:$I$38)*(1+'Эффекты технологий'!O$7) -> 0 | Q24: =SUMIF('Ход 2032'!$G$29:$G$38,$A24,'Ход 2032'!$I$29:$I$38)*(1+'Эффекты технологий'!P$7) -> 0 | R24: =SUMIF('Ход 2033'!$G$29:$G$38,$A24,'Ход 2033'!$I$29:$I$38)*(1+'Эффекты технологий'!Q$7) -> 0 | S24: =SUMIF('Ход 2034'!$G$29:$G$38,$A24,'Ход 2034'!$I$29:$I$38)*(1+'Эффекты технологий'!R$7) -> 0 | T24: =SUMIF('Ход 2035'!$G$29:$G$38,$A24,'Ход 2035'!$I$29:$I$38)*(1+'Эффекты технологий'!S$7) -> 0 | U24: =SUMIF('Ход 2036'!$G$29:$G$38,$A24,'Ход 2036'!$I$29:$I$38)*(1+'Эффекты технологий'!T$7) -> 0 | V24: =SUMIF('Ход 2037'!$G$29:$G$38,$A24,'Ход 2037'!$I$29:$I$38)*(1+'Эффекты технологий'!U$7) -> 0 | W24: =SUMIF('Ход 2038'!$G$29:$G$38,$A24,'Ход 2038'!$I$29:$I$38)*(1+'Эффекты технологий'!V$7) -> 0 | X24: =SUMIF('Ход 2039'!$G$29:$G$38,$A24,'Ход 2039'!$I$29:$I$38)*(1+'Эффекты технологий'!W$7) -> 0 | Y24: =SUMIF('Ход 2040'!$G$29:$G$38,$A24,'Ход 2040'!$I$29:$I$38)*(1+'Эффекты технологий'!X$7) -> 0 | Z24: =SUM(K24:Y24) -> 0 | AA24: =MAX(0,E24-Z24) -> 35 | AB24: =BF24 -> ОТКРЫТО | AC24: =SUM($K24:K24) -> 0 | AD24: =SUM($K24:L24) -> 0 | AE24: =SUM($K24:M24) -> 0 | AF24: =SUM($K24:N24) -> 0 | AG24: =SUM($K24:O24) -> 0 | AH24: =SUM($K24:P24) -> 0 | AI24: =SUM($K24:Q24) -> 0 | AJ24: =SUM($K24:R24) -> 0 | ... AQ24: =SUM($K24:Y24) -> 0 | AR24: =IF(AND(AC24>=$E24,TRUE),"ИЗУЧЕНО",IF(TRUE,"ОТКРЫТО","ЗАКРЫТО")) -> ОТКРЫТО | AS24: =IF(AND(AD24>=$E24,TRUE),"ИЗУЧЕНО",IF(TRUE,"ОТКРЫТО","ЗАКРЫТО")) -> ОТКРЫТО | AT24: =IF(AND(AE24>=$E24,TRUE),"ИЗУЧЕНО",IF(TRUE,"ОТКРЫТО","ЗАКРЫТО")) -> ОТКРЫТО | AU24: =IF(AND(AF24>=$E24,TRUE),"ИЗУЧЕНО",IF(TRUE,"ОТКРЫТО","ЗАКРЫТО")) -> ОТКРЫТО | AV24: =IF(AND(AG24>=$E24,TRUE),"ИЗУЧЕНО",IF(TRUE,"ОТКРЫТО","ЗАКРЫТО")) -> ОТКРЫТО | AW24: =IF(AND(AH24>=$E24,TRUE),"ИЗУЧЕНО",IF(TRUE,"ОТКРЫТО","ЗАКРЫТО")) -> ОТКРЫТО | AX24: =IF(AND(AI24>=$E24,TRUE),"ИЗУЧЕНО",IF(TRUE,"ОТКРЫТО","ЗАКРЫТО")) -> ОТКРЫТО | AY24: =IF(AND(AJ24>=$E24,TRUE),"ИЗУЧЕНО",IF(TRUE,"ОТКРЫТО","ЗАКРЫТО")) -> ОТКРЫТО | ... BF24: =IF(AND(AQ24>=$E24,TRUE),"ИЗУЧЕНО",IF(TRUE,"ОТКРЫТО","ЗАКРЫТО")) -> ОТКРЫТО | BG24: =IFERROR(2025+MATCH("ИЗУЧЕНО",AR24:BF24,0),"") | BH24: =IF(BG24="","",BG24+1)
A25: D3 | B25: Данные и знания | C25: II | D25: Графовые базы знаний на RDF/OWL с семантическими запросами | E25: 40 | F25: D1 | I25: Факты описываются как связи между сущностями, а онтологии задают смысл классов и отношений. Машина получает возможность искать не только совпадающие слова, но и содержательные зависимости между объектами. Это улучшает контекстные ресурсы и ускоряет познание. Создание графа требует разметки, согласования терминов и постоянного сопровождения, поэтому технология создаёт дополнительные финансовые обязательства. | J25: + Контекстные информационные ресурсы: +0,30; + Прирост сферы «Познание»: +0,05/год; + Документационные ресурсы: +0,20; − Финансовые ресурсы: -0,15 | K25: =SUMIF('Ход 2026'!$G$29:$G$38,$A25,'Ход 2026'!$I$29:$I$38)*(1+'Эффекты технологий'!J$7) -> 0 | L25: =SUMIF('Ход 2027'!$G$29:$G$38,$A25,'Ход 2027'!$I$29:$I$38)*(1+'Эффекты технологий'!K$7) -> 0 | M25: =SUMIF('Ход 2028'!$G$29:$G$38,$A25,'Ход 2028'!$I$29:$I$38)*(1+'Эффекты технологий'!L$7) -> 0 | N25: =SUMIF('Ход 2029'!$G$29:$G$38,$A25,'Ход 2029'!$I$29:$I$38)*(1+'Эффекты технологий'!M$7) -> 0 | O25: =SUMIF('Ход 2030'!$G$29:$G$38,$A25,'Ход 2030'!$I$29:$I$38)*(1+'Эффекты технологий'!N$7) -> 0 | P25: =SUMIF('Ход 2031'!$G$29:$G$38,$A25,'Ход 2031'!$I$29:$I$38)*(1+'Эффекты технологий'!O$7) -> 0 | Q25: =SUMIF('Ход 2032'!$G$29:$G$38,$A25,'Ход 2032'!$I$29:$I$38)*(1+'Эффекты технологий'!P$7) -> 0 | R25: =SUMIF('Ход 2033'!$G$29:$G$38,$A25,'Ход 2033'!$I$29:$I$38)*(1+'Эффекты технологий'!Q$7) -> 0 | S25: =SUMIF('Ход 2034'!$G$29:$G$38,$A25,'Ход 2034'!$I$29:$I$38)*(1+'Эффекты технологий'!R$7) -> 0 | T25: =SUMIF('Ход 2035'!$G$29:$G$38,$A25,'Ход 2035'!$I$29:$I$38)*(1+'Эффекты технологий'!S$7) -> 0 | U25: =SUMIF('Ход 2036'!$G$29:$G$38,$A25,'Ход 2036'!$I$29:$I$38)*(1+'Эффекты технологий'!T$7) -> 0 | V25: =SUMIF('Ход 2037'!$G$29:$G$38,$A25,'Ход 2037'!$I$29:$I$38)*(1+'Эффекты технологий'!U$7) -> 0 | W25: =SUMIF('Ход 2038'!$G$29:$G$38,$A25,'Ход 2038'!$I$29:$I$38)*(1+'Эффекты технологий'!V$7) -> 0 | X25: =SUMIF('Ход 2039'!$G$29:$G$38,$A25,'Ход 2039'!$I$29:$I$38)*(1+'Эффекты технологий'!W$7) -> 0 | Y25: =SUMIF('Ход 2040'!$G$29:$G$38,$A25,'Ход 2040'!$I$29:$I$38)*(1+'Эффекты технологий'!X$7) -> 0 | Z25: =SUM(K25:Y25) -> 0 | AA25: =MAX(0,E25-Z25) -> 40 | AB25: =BF25 -> ОТКРЫТО | AC25: =SUM($K25:K25) -> 0 | AD25: =SUM($K25:L25) -> 0 | AE25: =SUM($K25:M25) -> 0 | AF25: =SUM($K25:N25) -> 0 | AG25: =SUM($K25:O25) -> 0 | AH25: =SUM($K25:P25) -> 0 | AI25: =SUM($K25:Q25) -> 0 | AJ25: =SUM($K25:R25) -> 0 | ... AQ25: =SUM($K25:Y25) -> 0 | AR25: =IF(AND(AC25>=$E25,TRUE),"ИЗУЧЕНО",IF(TRUE,"ОТКРЫТО","ЗАКРЫТО")) -> ОТКРЫТО | AS25: =IF(AND(AD25>=$E25,TRUE),"ИЗУЧЕНО",IF(TRUE,"ОТКРЫТО","ЗАКРЫТО")) -> ОТКРЫТО | AT25: =IF(AND(AE25>=$E25,TRUE),"ИЗУЧЕНО",IF(TRUE,"ОТКРЫТО","ЗАКРЫТО")) -> ОТКРЫТО | AU25: =IF(AND(AF25>=$E25,TRUE),"ИЗУЧЕНО",IF(TRUE,"ОТКРЫТО","ЗАКРЫТО")) -> ОТКРЫТО | AV25: =IF(AND(AG25>=$E25,TRUE),"ИЗУЧЕНО",IF(TRUE,"ОТКРЫТО","ЗАКРЫТО")) -> ОТКРЫТО | AW25: =IF(AND(AH25>=$E25,TRUE),"ИЗУЧЕНО",IF(TRUE,"ОТКРЫТО","ЗАКРЫТО")) -> ОТКРЫТО | AX25: =IF(AND(AI25>=$E25,TRUE),"ИЗУЧЕНО",IF(TRUE,"ОТКРЫТО","ЗАКРЫТО")) -> ОТКРЫТО | AY25: =IF(AND(AJ25>=$E25,TRUE),"ИЗУЧЕНО",IF(TRUE,"ОТКРЫТО","ЗАКРЫТО")) -> ОТКРЫТО | ... BF25: =IF(AND(AQ25>=$E25,TRUE),"ИЗУЧЕНО",IF(TRUE,"ОТКРЫТО","ЗАКРЫТО")) -> ОТКРЫТО | BG25: =IFERROR(2025+MATCH("ИЗУЧЕНО",AR25:BF25,0),"") | BH25: =IF(BG25="","",BG25+1)
