Workbook

Sheet Технологии
A1: ДЕРЕВО ТЕХНОЛОГИЙ — 15 ХОДОВ
A3: Вложения автоматически собираются с листов Ход 2026–2040. Незавершённые исследования накапливаются; prerequisites проверяются по накопленному прогрессу. Игровые эффекты технологий в состояние страны вносятся вручную.
A5: ВСЕГО ТЕХНОЛОГИЙ | E5: ОСНОВНЫХ ВЕТВЕЙ | I5: МЕЖВЕТВЕВЫХ | M5: СТАРТОВО ОТКРЫТО
A6: 40 | E6: 6 | I6: 4 | M6: 6
A10: ID | B10: Ветвь | C10: Уровень | D10: Технология | E10: Цена науки | F10: Требование 1 | G10: Требование 2 | H10: Требование 3 | I10: Суть | J10: Игровой эффект | K10: Вложено 2026 | L10: Вложено 2027 | M10: Вложено 2028 | N10: Вложено 2029 | O10: Вложено 2030 | P10: Вложено 2031 | Q10: Вложено 2032 | R10: Вложено 2033 | S10: Вложено 2034 | T10: Вложено 2035 | U10: Вложено 2036 | V10: Вложено 2037 | W10: Вложено 2038 | X10: Вложено 2039 | Y10: Вложено 2040 | Z10: Накоплено всего | AA10: Осталось | AB10: Текущий статус | AC10: Σ 2026 | AD10: Σ 2027 | AE10: Σ 2028 | AF10: Σ 2029 | AG10: Σ 2030 | AH10: Σ 2031 | AI10: Σ 2032 | AJ10: Σ 2033 | AK10: Σ 2034 | AL10: Σ 2035 | AM10: Σ 2036 | AN10: Σ 2037 | AO10: Σ 2038 | AP10: Σ 2039 | AQ10: Σ 2040 | AR10: Статус 2026 | AS10: Статус 2027 | AT10: Статус 2028 | AU10: Статус 2029 | AV10: Статус 2030 | AW10: Статус 2031 | AX10: Статус 2032 | AY10: Статус 2033 | AZ10: Статус 2034 | BA10: Статус 2035 | BB10: Статус 2036 | BC10: Статус 2037 | BD10: Статус 2038 | BE10: Статус 2039 | BF10: Статус 2040
A11: C1 | B11: Вычисления и аппаратная база | C11: I | D11: Энергоэффективные ИИ-ускорители | E11: 20 | I11: Специализированные ускорители с лучшим отношением вычислений к энергопотреблению. | J11: Вычислительные компоненты +0,2; прирост ЦОД +0,05/год | K11: =SUMIF('Ход 2026'!$G$29:$G$38,$A11,'Ход 2026'!$I$29:$I$38) -> 0 | L11: =SUMIF('Ход 2027'!$G$29:$G$38,$A11,'Ход 2027'!$I$29:$I$38) -> 0 | M11: =SUMIF('Ход 2028'!$G$29:$G$38,$A11,'Ход 2028'!$I$29:$I$38) -> 0 | N11: =SUMIF('Ход 2029'!$G$29:$G$38,$A11,'Ход 2029'!$I$29:$I$38) -> 0 | O11: =SUMIF('Ход 2030'!$G$29:$G$38,$A11,'Ход 2030'!$I$29:$I$38) -> 0 | P11: =SUMIF('Ход 2031'!$G$29:$G$38,$A11,'Ход 2031'!$I$29:$I$38) -> 0 | Q11: =SUMIF('Ход 2032'!$G$29:$G$38,$A11,'Ход 2032'!$I$29:$I$38) -> 0 | R11: =SUMIF('Ход 2033'!$G$29:$G$38,$A11,'Ход 2033'!$I$29:$I$38) -> 0 | S11: =SUMIF('Ход 2034'!$G$29:$G$38,$A11,'Ход 2034'!$I$29:$I$38) -> 0 | T11: =SUMIF('Ход 2035'!$G$29:$G$38,$A11,'Ход 2035'!$I$29:$I$38) -> 0 | U11: =SUMIF('Ход 2036'!$G$29:$G$38,$A11,'Ход 2036'!$I$29:$I$38) -> 0 | V11: =SUMIF('Ход 2037'!$G$29:$G$38,$A11,'Ход 2037'!$I$29:$I$38) -> 0 | W11: =SUMIF('Ход 2038'!$G$29:$G$38,$A11,'Ход 2038'!$I$29:$I$38) -> 0 | X11: =SUMIF('Ход 2039'!$G$29:$G$38,$A11,'Ход 2039'!$I$29:$I$38) -> 0 | Y11: =SUMIF('Ход 2040'!$G$29:$G$38,$A11,'Ход 2040'!$I$29:$I$38) -> 0 | Z11: =SUM(K11:Y11) -> 0 | AA11: =MAX(0,E11-Z11) -> 20 | AB11: =BF11 -> ОТКРЫТО | AC11: =SUM($K11:K11) -> 0 | AD11: =SUM($K11:L11) -> 0 | AE11: =SUM($K11:M11) -> 0 | AF11: =SUM($K11:N11) -> 0 | AG11: =SUM($K11:O11) -> 0 | AH11: =SUM($K11:P11) -> 0 | AI11: =SUM($K11:Q11) -> 0 | AJ11: =SUM($K11:R11) -> 0 | ... AQ11: =SUM($K11:Y11) -> 0 | AR11: =IF(AC11>=E11,"ИЗУЧЕНО",IF(AND(OR(F11="",SUMIF($A$11:$A$50,F11,AC$11:AC$50)>=SUMIF($A$11:$A$50,F11,$E$11:$E$50)),OR(G11="",SUMIF($A$11:$A$50,G11,AC$11:AC$50)>=SUMIF($A$11:$A$50,G11,$E$11:$E$50)),OR(H11="",SUMIF($A$11:$A$50,H11,AC$11:AC$50)>=SUMIF($A$11:$A$50,H11,$E$11:$E$50))),"ОТКРЫТО","ЗАКРЫТО")) -> ОТКРЫТО | AS11: =IF(AD11>=E11,"ИЗУЧЕНО",IF(AND(OR(F11="",SUMIF($A$11:$A$50,F11,AD$11:AD$50)>=SUMIF($A$11:$A$50,F11,$E$11:$E$50)),OR(G11="",SUMIF($A$11:$A$50,G11,AD$11:AD$50)>=SUMIF($A$11:$A$50,G11,$E$11:$E$50)),OR(H11="",SUMIF($A$11:$A$50,H11,AD$11:AD$50)>=SUMIF($A$11:$A$50,H11,$E$11:$E$50))),"ОТКРЫТО","ЗАКРЫТО")) -> ОТКРЫТО | AT11: =IF(AE11>=E11,"ИЗУЧЕНО",IF(AND(OR(F11="",SUMIF($A$11:$A$50,F11,AE$11:AE$50)>=SUMIF($A$11:$A$50,F11,$E$11:$E$50)),OR(G11="",SUMIF($A$11:$A$50,G11,AE$11:AE$50)>=SUMIF($A$11:$A$50,G11,$E$11:$E$50)),OR(H11="",SUMIF($A$11:$A$50,H11,AE$11:AE$50)>=SUMIF($A$11:$A$50,H11,$E$11:$E$50))),"ОТКРЫТО","ЗАКРЫТО")) -> ОТКРЫТО | AU11: =IF(AF11>=E11,"ИЗУЧЕНО",IF(AND(OR(F11="",SUMIF($A$11:$A$50,F11,AF$11:AF$50)>=SUMIF($A$11:$A$50,F11,$E$11:$E$50)),OR(G11="",SUMIF($A$11:$A$50,G11,AF$11:AF$50)>=SUMIF($A$11:$A$50,G11,$E$11:$E$50)),OR(H11="",SUMIF($A$11:$A$50,H11,AF$11:AF$50)>=SUMIF($A$11:$A$50,H11,$E$11:$E$50))),"ОТКРЫТО","ЗАКРЫТО")) -> ОТКРЫТО | AV11: =IF(AG11>=E11,"ИЗУЧЕНО",IF(AND(OR(F11="",SUMIF($A$11:$A$50,F11,AG$11:AG$50)>=SUMIF($A$11:$A$50,F11,$E$11:$E$50)),OR(G11="",SUMIF($A$11:$A$50,G11,AG$11:AG$50)>=SUMIF($A$11:$A$50,G11,$E$11:$E$50)),OR(H11="",SUMIF($A$11:$A$50,H11,AG$11:AG$50)>=SUMIF($A$11:$A$50,H11,$E$11:$E$50))),"ОТКРЫТО","ЗАКРЫТО")) -> ОТКРЫТО | AW11: =IF(AH11>=E11,"ИЗУЧЕНО",IF(AND(OR(F11="",SUMIF($A$11:$A$50,F11,AH$11:AH$50)>=SUMIF($A$11:$A$50,F11,$E$11:$E$50)),OR(G11="",SUMIF($A$11:$A$50,G11,AH$11:AH$50)>=SUMIF($A$11:$A$50,G11,$E$11:$E$50)),OR(H11="",SUMIF($A$11:$A$50,H11,AH$11:AH$50)>=SUMIF($A$11:$A$50,H11,$E$11:$E$50))),"ОТКРЫТО","ЗАКРЫТО")) -> ОТКРЫТО | AX11: =IF(AI11>=E11,"ИЗУЧЕНО",IF(AND(OR(F11="",SUMIF($A$11:$A$50,F11,AI$11:AI$50)>=SUMIF($A$11:$A$50,F11,$E$11:$E$50)),OR(G11="",SUMIF($A$11:$A$50,G11,AI$11:AI$50)>=SUMIF($A$11:$A$50,G11,$E$11:$E$50)),OR(H11="",SUMIF($A$11:$A$50,H11,AI$11:AI$50)>=SUMIF($A$11:$A$50,H11,$E$11:$E$50))),"ОТКРЫТО","ЗАКРЫТО")) -> ОТКРЫТО | AY11: =IF(AJ11>=E11,"ИЗУЧЕНО",IF(AND(OR(F11="",SUMIF($A$11:$A$50,F11,AJ$11:AJ$50)>=SUMIF($A$11:$A$50,F11,$E$11:$E$50)),OR(G11="",SUMIF($A$11:$A$50,G11,AJ$11:AJ$50)>=SUMIF($A$11:$A$50,G11,$E$11:$E$50)),OR(H11="",SUMIF($A$11:$A$50,H11,AJ$11:AJ$50)>=SUMIF($A$11:$A$50,H11,$E$11:$E$50))),"ОТКРЫТО","ЗАКРЫТО")) -> ОТКРЫТО | AZ11: =IF(AK11>=E11,"ИЗУЧЕНО",IF(AND(OR(F11="",SUMIF($A$11:$A$50,F11,AK$11:AK$50)>=SUMIF($A$11:$A$50,F11,$E$11:$E$50)),OR(G11="",SUMIF($A$11:$A$50,G11,AK$11:AK$50)>=SUMIF($A$11:$A$50,G11,$E$11:$E$50)),OR(H11="",SUMIF($A$11:$A$50,H11,AK$11:AK$50)>=SUMIF($A$11:$A$50,H11,$E$11:$E$50))),"ОТКРЫТО","ЗАКРЫТО")) -> ОТКРЫТО | BA11: =IF(AL11>=E11,"ИЗУЧЕНО",IF(AND(OR(F11="",SUMIF($A$11:$A$50,F11,AL$11:AL$50)>=SUMIF($A$11:$A$50,F11,$E$11:$E$50)),OR(G11="",SUMIF($A$11:$A$50,G11,AL$11:AL$50)>=SUMIF($A$11:$A$50,G11,$E$11:$E$50)),OR(H11="",SUMIF($A$11:$A$50,H11,AL$11:AL$50)>=SUMIF($A$11:$A$50,H11,$E$11:$E$50))),"ОТКРЫТО","ЗАКРЫТО")) -> ОТКРЫТО | BB11: =IF(AM11>=E11,"ИЗУЧЕНО",IF(AND(OR(F11="",SUMIF($A$11:$A$50,F11,AM$11:AM$50)>=SUMIF($A$11:$A$50,F11,$E$11:$E$50)),OR(G11="",SUMIF($A$11:$A$50,G11,AM$11:AM$50)>=SUMIF($A$11:$A$50,G11,$E$11:$E$50)),OR(H11="",SUMIF($A$11:$A$50,H11,AM$11:AM$50)>=SUMIF($A$11:$A$50,H11,$E$11:$E$50))),"ОТКРЫТО","ЗАКРЫТО")) -> ОТКРЫТО | BC11: =IF(AN11>=E11,"ИЗУЧЕНО",IF(AND(OR(F11="",SUMIF($A$11:$A$50,F11,AN$11:AN$50)>=SUMIF($A$11:$A$50,F11,$E$11:$E$50)),OR(G11="",SUMIF($A$11:$A$50,G11,AN$11:AN$50)>=SUMIF($A$11:$A$50,G11,$E$11:$E$50)),OR(H11="",SUMIF($A$11:$A$50,H11,AN$11:AN$50)>=SUMIF($A$11:$A$50,H11,$E$11:$E$50))),"ОТКРЫТО","ЗАКРЫТО")) -> ОТКРЫТО | BD11: =IF(AO11>=E11,"ИЗУЧЕНО",IF(AND(OR(F11="",SUMIF($A$11:$A$50,F11,AO$11:AO$50)>=SUMIF($A$11:$A$50,F11,$E$11:$E$50)),OR(G11="",SUMIF($A$11:$A$50,G11,AO$11:AO$50)>=SUMIF($A$11:$A$50,G11,$E$11:$E$50)),OR(H11="",SUMIF($A$11:$A$50,H11,AO$11:AO$50)>=SUMIF($A$11:$A$50,H11,$E$11:$E$50))),"ОТКРЫТО","ЗАКРЫТО")) -> ОТКРЫТО | BE11: =IF(AP11>=E11,"ИЗУЧЕНО",IF(AND(OR(F11="",SUMIF($A$11:$A$50,F11,AP$11:AP$50)>=SUMIF($A$11:$A$50,F11,$E$11:$E$50)),OR(G11="",SUMIF($A$11:$A$50,G11,AP$11:AP$50)>=SUMIF($A$11:$A$50,G11,$E$11:$E$50)),OR(H11="",SUMIF($A$11:$A$50,H11,AP$11:AP$50)>=SUMIF($A$11:$A$50,H11,$E$11:$E$50))),"ОТКРЫТО","ЗАКРЫТО")) -> ОТКРЫТО | BF11: =IF(AQ11>=E11,"ИЗУЧЕНО",IF(AND(OR(F11="",SUMIF($A$11:$A$50,F11,AQ$11:AQ$50)>=SUMIF($A$11:$A$50,F11,$E$11:$E$50)),OR(G11="",SUMIF($A$11:$A$50,G11,AQ$11:AQ$50)>=SUMIF($A$11:$A$50,G11,$E$11:$E$50)),OR(H11="",SUMIF($A$11:$A$50,H11,AQ$11:AQ$50)>=SUMIF($A$11:$A$50,H11,$E$11:$E$50))),"ОТКРЫТО","ЗАКРЫТО")) -> ОТКРЫТО
A12: C2 | B12: Вычисления и аппаратная база | C12: II | D12: Проектирование специализированных ускорителей | E12: 40 | F12: C1 | I12: Собственные архитектуры ускорителей и средств их проектирования. | J12: Вычислительные компоненты +0,3; их прирост +0,08/год | K12: =SUMIF('Ход 2026'!$G$29:$G$38,$A12,'Ход 2026'!$I$29:$I$38) -> 0 | L12: =SUMIF('Ход 2027'!$G$29:$G$38,$A12,'Ход 2027'!$I$29:$I$38) -> 0 | M12: =SUMIF('Ход 2028'!$G$29:$G$38,$A12,'Ход 2028'!$I$29:$I$38) -> 0 | N12: =SUMIF('Ход 2029'!$G$29:$G$38,$A12,'Ход 2029'!$I$29:$I$38) -> 0 | O12: =SUMIF('Ход 2030'!$G$29:$G$38,$A12,'Ход 2030'!$I$29:$I$38) -> 0 | P12: =SUMIF('Ход 2031'!$G$29:$G$38,$A12,'Ход 2031'!$I$29:$I$38) -> 0 | Q12: =SUMIF('Ход 2032'!$G$29:$G$38,$A12,'Ход 2032'!$I$29:$I$38) -> 0 | R12: =SUMIF('Ход 2033'!$G$29:$G$38,$A12,'Ход 2033'!$I$29:$I$38) -> 0 | S12: =SUMIF('Ход 2034'!$G$29:$G$38,$A12,'Ход 2034'!$I$29:$I$38) -> 0 | T12: =SUMIF('Ход 2035'!$G$29:$G$38,$A12,'Ход 2035'!$I$29:$I$38) -> 0 | U12: =SUMIF('Ход 2036'!$G$29:$G$38,$A12,'Ход 2036'!$I$29:$I$38) -> 0 | V12: =SUMIF('Ход 2037'!$G$29:$G$38,$A12,'Ход 2037'!$I$29:$I$38) -> 0 | W12: =SUMIF('Ход 2038'!$G$29:$G$38,$A12,'Ход 2038'!$I$29:$I$38) -> 0 | X12: =SUMIF('Ход 2039'!$G$29:$G$38,$A12,'Ход 2039'!$I$29:$I$38) -> 0 | Y12: =SUMIF('Ход 2040'!$G$29:$G$38,$A12,'Ход 2040'!$I$29:$I$38) -> 0 | Z12: =SUM(K12:Y12) -> 0 | AA12: =MAX(0,E12-Z12) -> 40 | AB12: =BF12 -> ЗАКРЫТО | AC12: =SUM($K12:K12) -> 0 | AD12: =SUM($K12:L12) -> 0 | AE12: =SUM($K12:M12) -> 0 | AF12: =SUM($K12:N12) -> 0 | AG12: =SUM($K12:O12) -> 0 | AH12: =SUM($K12:P12) -> 0 | AI12: =SUM($K12:Q12) -> 0 | AJ12: =SUM($K12:R12) -> 0 | ... AQ12: =SUM($K12:Y12) -> 0 | AR12: =IF(AC12>=E12,"ИЗУЧЕНО",IF(AND(OR(F12="",SUMIF($A$11:$A$50,F12,AC$11:AC$50)>=SUMIF($A$11:$A$50,F12,$E$11:$E$50)),OR(G12="",SUMIF($A$11:$A$50,G12,AC$11:AC$50)>=SUMIF($A$11:$A$50,G12,$E$11:$E$50)),OR(H12="",SUMIF($A$11:$A$50,H12,AC$11:AC$50)>=SUMIF($A$11:$A$50,H12,$E$11:$E$50))),"ОТКРЫТО","ЗАКРЫТО")) -> ЗАКРЫТО | AS12: =IF(AD12>=E12,"ИЗУЧЕНО",IF(AND(OR(F12="",SUMIF($A$11:$A$50,F12,AD$11:AD$50)>=SUMIF($A$11:$A$50,F12,$E$11:$E$50)),OR(G12="",SUMIF($A$11:$A$50,G12,AD$11:AD$50)>=SUMIF($A$11:$A$50,G12,$E$11:$E$50)),OR(H12="",SUMIF($A$11:$A$50,H12,AD$11:AD$50)>=SUMIF($A$11:$A$50,H12,$E$11:$E$50))),"ОТКРЫТО","ЗАКРЫТО")) -> ЗАКРЫТО | AT12: =IF(AE12>=E12,"ИЗУЧЕНО",IF(AND(OR(F12="",SUMIF($A$11:$A$50,F12,AE$11:AE$50)>=SUMIF($A$11:$A$50,F12,$E$11:$E$50)),OR(G12="",SUMIF($A$11:$A$50,G12,AE$11:AE$50)>=SUMIF($A$11:$A$50,G12,$E$11:$E$50)),OR(H12="",SUMIF($A$11:$A$50,H12,AE$11:AE$50)>=SUMIF($A$11:$A$50,H12,$E$11:$E$50))),"ОТКРЫТО","ЗАКРЫТО")) -> ЗАКРЫТО | AU12: =IF(AF12>=E12,"ИЗУЧЕНО",IF(AND(OR(F12="",SUMIF($A$11:$A$50,F12,AF$11:AF$50)>=SUMIF($A$11:$A$50,F12,$E$11:$E$50)),OR(G12="",SUMIF($A$11:$A$50,G12,AF$11:AF$50)>=SUMIF($A$11:$A$50,G12,$E$11:$E$50)),OR(H12="",SUMIF($A$11:$A$50,H12,AF$11:AF$50)>=SUMIF($A$11:$A$50,H12,$E$11:$E$50))),"ОТКРЫТО","ЗАКРЫТО")) -> ЗАКРЫТО | AV12: =IF(AG12>=E12,"ИЗУЧЕНО",IF(AND(OR(F12="",SUMIF($A$11:$A$50,F12,AG$11:AG$50)>=SUMIF($A$11:$A$50,F12,$E$11:$E$50)),OR(G12="",SUMIF($A$11:$A$50,G12,AG$11:AG$50)>=SUMIF($A$11:$A$50,G12,$E$11:$E$50)),OR(H12="",SUMIF($A$11:$A$50,H12,AG$11:AG$50)>=SUMIF($A$11:$A$50,H12,$E$11:$E$50))),"ОТКРЫТО","ЗАКРЫТО")) -> ЗАКРЫТО | AW12: =IF(AH12>=E12,"ИЗУЧЕНО",IF(AND(OR(F12="",SUMIF($A$11:$A$50,F12,AH$11:AH$50)>=SUMIF($A$11:$A$50,F12,$E$11:$E$50)),OR(G12="",SUMIF($A$11:$A$50,G12,AH$11:AH$50)>=SUMIF($A$11:$A$50,G12,$E$11:$E$50)),OR(H12="",SUMIF($A$11:$A$50,H12,AH$11:AH$50)>=SUMIF($A$11:$A$50,H12,$E$11:$E$50))),"ОТКРЫТО","ЗАКРЫТО")) -> ЗАКРЫТО | AX12: =IF(AI12>=E12,"ИЗУЧЕНО",IF(AND(OR(F12="",SUMIF($A$11:$A$50,F12,AI$11:AI$50)>=SUMIF($A$11:$A$50,F12,$E$11:$E$50)),OR(G12="",SUMIF($A$11:$A$50,G12,AI$11:AI$50)>=SUMIF($A$11:$A$50,G12,$E$11:$E$50)),OR(H12="",SUMIF($A$11:$A$50,H12,AI$11:AI$50)>=SUMIF($A$11:$A$50,H12,$E$11:$E$50))),"ОТКРЫТО","ЗАКРЫТО")) -> ЗАКРЫТО | AY12: =IF(AJ12>=E12,"ИЗУЧЕНО",IF(AND(OR(F12="",SUMIF($A$11:$A$50,F12,AJ$11:AJ$50)>=SUMIF($A$11:$A$50,F12,$E$11:$E$50)),OR(G12="",SUMIF($A$11:$A$50,G12,AJ$11:AJ$50)>=SUMIF($A$11:$A$50,G12,$E$11:$E$50)),OR(H12="",SUMIF($A$11:$A$50,H12,AJ$11:AJ$50)>=SUMIF($A$11:$A$50,H12,$E$11:$E$50))),"ОТКРЫТО","ЗАКРЫТО")) -> ЗАКРЫТО | AZ12: =IF(AK12>=E12,"ИЗУЧЕНО",IF(AND(OR(F12="",SUMIF($A$11:$A$50,F12,AK$11:AK$50)>=SUMIF($A$11:$A$50,F12,$E$11:$E$50)),OR(G12="",SUMIF($A$11:$A$50,G12,AK$11:AK$50)>=SUMIF($A$11:$A$50,G12,$E$11:$E$50)),OR(H12="",SUMIF($A$11:$A$50,H12,AK$11:AK$50)>=SUMIF($A$11:$A$50,H12,$E$11:$E$50))),"ОТКРЫТО","ЗАКРЫТО")) -> ЗАКРЫТО | BA12: =IF(AL12>=E12,"ИЗУЧЕНО",IF(AND(OR(F12="",SUMIF($A$11:$A$50,F12,AL$11:AL$50)>=SUMIF($A$11:$A$50,F12,$E$11:$E$50)),OR(G12="",SUMIF($A$11:$A$50,G12,AL$11:AL$50)>=SUMIF($A$11:$A$50,G12,$E$11:$E$50)),OR(H12="",SUMIF($A$11:$A$50,H12,AL$11:AL$50)>=SUMIF($A$11:$A$50,H12,$E$11:$E$50))),"ОТКРЫТО","ЗАКРЫТО")) -> ЗАКРЫТО | BB12: =IF(AM12>=E12,"ИЗУЧЕНО",IF(AND(OR(F12="",SUMIF($A$11:$A$50,F12,AM$11:AM$50)>=SUMIF($A$11:$A$50,F12,$E$11:$E$50)),OR(G12="",SUMIF($A$11:$A$50,G12,AM$11:AM$50)>=SUMIF($A$11:$A$50,G12,$E$11:$E$50)),OR(H12="",SUMIF($A$11:$A$50,H12,AM$11:AM$50)>=SUMIF($A$11:$A$50,H12,$E$11:$E$50))),"ОТКРЫТО","ЗАКРЫТО")) -> ЗАКРЫТО | BC12: =IF(AN12>=E12,"ИЗУЧЕНО",IF(AND(OR(F12="",SUMIF($A$11:$A$50,F12,AN$11:AN$50)>=SUMIF($A$11:$A$50,F12,$E$11:$E$50)),OR(G12="",SUMIF($A$11:$A$50,G12,AN$11:AN$50)>=SUMIF($A$11:$A$50,G12,$E$11:$E$50)),OR(H12="",SUMIF($A$11:$A$50,H12,AN$11:AN$50)>=SUMIF($A$11:$A$50,H12,$E$11:$E$50))),"ОТКРЫТО","ЗАКРЫТО")) -> ЗАКРЫТО | BD12: =IF(AO12>=E12,"ИЗУЧЕНО",IF(AND(OR(F12="",SUMIF($A$11:$A$50,F12,AO$11:AO$50)>=SUMIF($A$11:$A$50,F12,$E$11:$E$50)),OR(G12="",SUMIF($A$11:$A$50,G12,AO$11:AO$50)>=SUMIF($A$11:$A$50,G12,$E$11:$E$50)),OR(H12="",SUMIF($A$11:$A$50,H12,AO$11:AO$50)>=SUMIF($A$11:$A$50,H12,$E$11:$E$50))),"ОТКРЫТО","ЗАКРЫТО")) -> ЗАКРЫТО | BE12: =IF(AP12>=E12,"ИЗУЧЕНО",IF(AND(OR(F12="",SUMIF($A$11:$A$50,F12,AP$11:AP$50)>=SUMIF($A$11:$A$50,F12,$E$11:$E$50)),OR(G12="",SUMIF($A$11:$A$50,G12,AP$11:AP$50)>=SUMIF($A$11:$A$50,G12,$E$11:$E$50)),OR(H12="",SUMIF($A$11:$A$50,H12,AP$11:AP$50)>=SUMIF($A$11:$A$50,H12,$E$11:$E$50))),"ОТКРЫТО","ЗАКРЫТО")) -> ЗАКРЫТО | BF12: =IF(AQ12>=E12,"ИЗУЧЕНО",IF(AND(OR(F12="",SUMIF($A$11:$A$50,F12,AQ$11:AQ$50)>=SUMIF($A$11:$A$50,F12,$E$11:$E$50)),OR(G12="",SUMIF($A$11:$A$50,G12,AQ$11:AQ$50)>=SUMIF($A$11:$A$50,G12,$E$11:$E$50)),OR(H12="",SUMIF($A$11:$A$50,H12,AQ$11:AQ$50)>=SUMIF($A$11:$A$50,H12,$E$11:$E$50))),"ОТКРЫТО","ЗАКРЫТО")) -> ЗАКРЫТО
A13: C3 | B13: Вычисления и аппаратная база | C13: II | D13: Передовая микроэлектроника для ИИ | E13: 45 | F13: C1 | I13: Технологическая база для специализированных чипов, памяти и упаковки. | J13: Полупроводниковое производство +0,4; его прирост +0,08/год | K13: =SUMIF('Ход 2026'!$G$29:$G$38,$A13,'Ход 2026'!$I$29:$I$38) -> 0 | L13: =SUMIF('Ход 2027'!$G$29:$G$38,$A13,'Ход 2027'!$I$29:$I$38) -> 0 | M13: =SUMIF('Ход 2028'!$G$29:$G$38,$A13,'Ход 2028'!$I$29:$I$38) -> 0 | N13: =SUMIF('Ход 2029'!$G$29:$G$38,$A13,'Ход 2029'!$I$29:$I$38) -> 0 | O13: =SUMIF('Ход 2030'!$G$29:$G$38,$A13,'Ход 2030'!$I$29:$I$38) -> 0 | P13: =SUMIF('Ход 2031'!$G$29:$G$38,$A13,'Ход 2031'!$I$29:$I$38) -> 0 | Q13: =SUMIF('Ход 2032'!$G$29:$G$38,$A13,'Ход 2032'!$I$29:$I$38) -> 0 | R13: =SUMIF('Ход 2033'!$G$29:$G$38,$A13,'Ход 2033'!$I$29:$I$38) -> 0 | S13: =SUMIF('Ход 2034'!$G$29:$G$38,$A13,'Ход 2034'!$I$29:$I$38) -> 0 | T13: =SUMIF('Ход 2035'!$G$29:$G$38,$A13,'Ход 2035'!$I$29:$I$38) -> 0 | U13: =SUMIF('Ход 2036'!$G$29:$G$38,$A13,'Ход 2036'!$I$29:$I$38) -> 0 | V13: =SUMIF('Ход 2037'!$G$29:$G$38,$A13,'Ход 2037'!$I$29:$I$38) -> 0 | W13: =SUMIF('Ход 2038'!$G$29:$G$38,$A13,'Ход 2038'!$I$29:$I$38) -> 0 | X13: =SUMIF('Ход 2039'!$G$29:$G$38,$A13,'Ход 2039'!$I$29:$I$38) -> 0 | Y13: =SUMIF('Ход 2040'!$G$29:$G$38,$A13,'Ход 2040'!$I$29:$I$38) -> 0 | Z13: =SUM(K13:Y13) -> 0 | AA13: =MAX(0,E13-Z13) -> 45 | AB13: =BF13 -> ЗАКРЫТО | AC13: =SUM($K13:K13) -> 0 | AD13: =SUM($K13:L13) -> 0 | AE13: =SUM($K13:M13) -> 0 | AF13: =SUM($K13:N13) -> 0 | AG13: =SUM($K13:O13) -> 0 | AH13: =SUM($K13:P13) -> 0 | AI13: =SUM($K13:Q13) -> 0 | AJ13: =SUM($K13:R13) -> 0 | ... AQ13: =SUM($K13:Y13) -> 0 | AR13: =IF(AC13>=E13,"ИЗУЧЕНО",IF(AND(OR(F13="",SUMIF($A$11:$A$50,F13,AC$11:AC$50)>=SUMIF($A$11:$A$50,F13,$E$11:$E$50)),OR(G13="",SUMIF($A$11:$A$50,G13,AC$11:AC$50)>=SUMIF($A$11:$A$50,G13,$E$11:$E$50)),OR(H13="",SUMIF($A$11:$A$50,H13,AC$11:AC$50)>=SUMIF($A$11:$A$50,H13,$E$11:$E$50))),"ОТКРЫТО","ЗАКРЫТО")) -> ЗАКРЫТО | AS13: =IF(AD13>=E13,"ИЗУЧЕНО",IF(AND(OR(F13="",SUMIF($A$11:$A$50,F13,AD$11:AD$50)>=SUMIF($A$11:$A$50,F13,$E$11:$E$50)),OR(G13="",SUMIF($A$11:$A$50,G13,AD$11:AD$50)>=SUMIF($A$11:$A$50,G13,$E$11:$E$50)),OR(H13="",SUMIF($A$11:$A$50,H13,AD$11:AD$50)>=SUMIF($A$11:$A$50,H13,$E$11:$E$50))),"ОТКРЫТО","ЗАКРЫТО")) -> ЗАКРЫТО | AT13: =IF(AE13>=E13,"ИЗУЧЕНО",IF(AND(OR(F13="",SUMIF($A$11:$A$50,F13,AE$11:AE$50)>=SUMIF($A$11:$A$50,F13,$E$11:$E$50)),OR(G13="",SUMIF($A$11:$A$50,G13,AE$11:AE$50)>=SUMIF($A$11:$A$50,G13,$E$11:$E$50)),OR(H13="",SUMIF($A$11:$A$50,H13,AE$11:AE$50)>=SUMIF($A$11:$A$50,H13,$E$11:$E$50))),"ОТКРЫТО","ЗАКРЫТО")) -> ЗАКРЫТО | AU13: =IF(AF13>=E13,"ИЗУЧЕНО",IF(AND(OR(F13="",SUMIF($A$11:$A$50,F13,AF$11:AF$50)>=SUMIF($A$11:$A$50,F13,$E$11:$E$50)),OR(G13="",SUMIF($A$11:$A$50,G13,AF$11:AF$50)>=SUMIF($A$11:$A$50,G13,$E$11:$E$50)),OR(H13="",SUMIF($A$11:$A$50,H13,AF$11:AF$50)>=SUMIF($A$11:$A$50,H13,$E$11:$E$50))),"ОТКРЫТО","ЗАКРЫТО")) -> ЗАКРЫТО | AV13: =IF(AG13>=E13,"ИЗУЧЕНО",IF(AND(OR(F13="",SUMIF($A$11:$A$50,F13,AG$11:AG$50)>=SUMIF($A$11:$A$50,F13,$E$11:$E$50)),OR(G13="",SUMIF($A$11:$A$50,G13,AG$11:AG$50)>=SUMIF($A$11:$A$50,G13,$E$11:$E$50)),OR(H13="",SUMIF($A$11:$A$50,H13,AG$11:AG$50)>=SUMIF($A$11:$A$50,H13,$E$11:$E$50))),"ОТКРЫТО","ЗАКРЫТО")) -> ЗАКРЫТО | AW13: =IF(AH13>=E13,"ИЗУЧЕНО",IF(AND(OR(F13="",SUMIF($A$11:$A$50,F13,AH$11:AH$50)>=SUMIF($A$11:$A$50,F13,$E$11:$E$50)),OR(G13="",SUMIF($A$11:$A$50,G13,AH$11:AH$50)>=SUMIF($A$11:$A$50,G13,$E$11:$E$50)),OR(H13="",SUMIF($A$11:$A$50,H13,AH$11:AH$50)>=SUMIF($A$11:$A$50,H13,$E$11:$E$50))),"ОТКРЫТО","ЗАКРЫТО")) -> ЗАКРЫТО | AX13: =IF(AI13>=E13,"ИЗУЧЕНО",IF(AND(OR(F13="",SUMIF($A$11:$A$50,F13,AI$11:AI$50)>=SUMIF($A$11:$A$50,F13,$E$11:$E$50)),OR(G13="",SUMIF($A$11:$A$50,G13,AI$11:AI$50)>=SUMIF($A$11:$A$50,G13,$E$11:$E$50)),OR(H13="",SUMIF($A$11:$A$50,H13,AI$11:AI$50)>=SUMIF($A$11:$A$50,H13,$E$11:$E$50))),"ОТКРЫТО","ЗАКРЫТО")) -> ЗАКРЫТО | AY13: =IF(AJ13>=E13,"ИЗУЧЕНО",IF(AND(OR(F13="",SUMIF($A$11:$A$50,F13,AJ$11:AJ$50)>=SUMIF($A$11:$A$50,F13,$E$11:$E$50)),OR(G13="",SUMIF($A$11:$A$50,G13,AJ$11:AJ$50)>=SUMIF($A$11:$A$50,G13,$E$11:$E$50)),OR(H13="",SUMIF($A$11:$A$50,H13,AJ$11:AJ$50)>=SUMIF($A$11:$A$50,H13,$E$11:$E$50))),"ОТКРЫТО","ЗАКРЫТО")) -> ЗАКРЫТО | AZ13: =IF(AK13>=E13,"ИЗУЧЕНО",IF(AND(OR(F13="",SUMIF($A$11:$A$50,F13,AK$11:AK$50)>=SUMIF($A$11:$A$50,F13,$E$11:$E$50)),OR(G13="",SUMIF($A$11:$A$50,G13,AK$11:AK$50)>=SUMIF($A$11:$A$50,G13,$E$11:$E$50)),OR(H13="",SUMIF($A$11:$A$50,H13,AK$11:AK$50)>=SUMIF($A$11:$A$50,H13,$E$11:$E$50))),"ОТКРЫТО","ЗАКРЫТО")) -> ЗАКРЫТО | BA13: =IF(AL13>=E13,"ИЗУЧЕНО",IF(AND(OR(F13="",SUMIF($A$11:$A$50,F13,AL$11:AL$50)>=SUMIF($A$11:$A$50,F13,$E$11:$E$50)),OR(G13="",SUMIF($A$11:$A$50,G13,AL$11:AL$50)>=SUMIF($A$11:$A$50,G13,$E$11:$E$50)),OR(H13="",SUMIF($A$11:$A$50,H13,AL$11:AL$50)>=SUMIF($A$11:$A$50,H13,$E$11:$E$50))),"ОТКРЫТО","ЗАКРЫТО")) -> ЗАКРЫТО | BB13: =IF(AM13>=E13,"ИЗУЧЕНО",IF(AND(OR(F13="",SUMIF($A$11:$A$50,F13,AM$11:AM$50)>=SUMIF($A$11:$A$50,F13,$E$11:$E$50)),OR(G13="",SUMIF($A$11:$A$50,G13,AM$11:AM$50)>=SUMIF($A$11:$A$50,G13,$E$11:$E$50)),OR(H13="",SUMIF($A$11:$A$50,H13,AM$11:AM$50)>=SUMIF($A$11:$A$50,H13,$E$11:$E$50))),"ОТКРЫТО","ЗАКРЫТО")) -> ЗАКРЫТО | BC13: =IF(AN13>=E13,"ИЗУЧЕНО",IF(AND(OR(F13="",SUMIF($A$11:$A$50,F13,AN$11:AN$50)>=SUMIF($A$11:$A$50,F13,$E$11:$E$50)),OR(G13="",SUMIF($A$11:$A$50,G13,AN$11:AN$50)>=SUMIF($A$11:$A$50,G13,$E$11:$E$50)),OR(H13="",SUMIF($A$11:$A$50,H13,AN$11:AN$50)>=SUMIF($A$11:$A$50,H13,$E$11:$E$50))),"ОТКРЫТО","ЗАКРЫТО")) -> ЗАКРЫТО | BD13: =IF(AO13>=E13,"ИЗУЧЕНО",IF(AND(OR(F13="",SUMIF($A$11:$A$50,F13,AO$11:AO$50)>=SUMIF($A$11:$A$50,F13,$E$11:$E$50)),OR(G13="",SUMIF($A$11:$A$50,G13,AO$11:AO$50)>=SUMIF($A$11:$A$50,G13,$E$11:$E$50)),OR(H13="",SUMIF($A$11:$A$50,H13,AO$11:AO$50)>=SUMIF($A$11:$A$50,H13,$E$11:$E$50))),"ОТКРЫТО","ЗАКРЫТО")) -> ЗАКРЫТО | BE13: =IF(AP13>=E13,"ИЗУЧЕНО",IF(AND(OR(F13="",SUMIF($A$11:$A$50,F13,AP$11:AP$50)>=SUMIF($A$11:$A$50,F13,$E$11:$E$50)),OR(G13="",SUMIF($A$11:$A$50,G13,AP$11:AP$50)>=SUMIF($A$11:$A$50,G13,$E$11:$E$50)),OR(H13="",SUMIF($A$11:$A$50,H13,AP$11:AP$50)>=SUMIF($A$11:$A$50,H13,$E$11:$E$50))),"ОТКРЫТО","ЗАКРЫТО")) -> ЗАКРЫТО | BF13: =IF(AQ13>=E13,"ИЗУЧЕНО",IF(AND(OR(F13="",SUMIF($A$11:$A$50,F13,AQ$11:AQ$50)>=SUMIF($A$11:$A$50,F13,$E$11:$E$50)),OR(G13="",SUMIF($A$11:$A$50,G13,AQ$11:AQ$50)>=SUMIF($A$11:$A$50,G13,$E$11:$E$50)),OR(H13="",SUMIF($A$11:$A$50,H13,AQ$11:AQ$50)>=SUMIF($A$11:$A$50,H13,$E$11:$E$50))),"ОТКРЫТО","ЗАКРЫТО")) -> ЗАКРЫТО
A14: C4 | B14: Вычисления и аппаратная база | C14: III | D14: Гетерогенные вычислительные кластеры | E14: 65 | F14: C2 | G14: C3 | I14: Совместное использование CPU, GPU, специализированных ускорителей и распределённой памяти. | J14: ЦОД +0,4; Стек эксплуатации ИИ +0,2; прирост ЦОД +0,05/год | K14: =SUMIF('Ход 2026'!$G$29:$G$38,$A14,'Ход 2026'!$I$29:$I$38) -> 0 | L14: =SUMIF('Ход 2027'!$G$29:$G$38,$A14,'Ход 2027'!$I$29:$I$38) -> 0 | M14: =SUMIF('Ход 2028'!$G$29:$G$38,$A14,'Ход 2028'!$I$29:$I$38) -> 0 | N14: =SUMIF('Ход 2029'!$G$29:$G$38,$A14,'Ход 2029'!$I$29:$I$38) -> 0 | O14: =SUMIF('Ход 2030'!$G$29:$G$38,$A14,'Ход 2030'!$I$29:$I$38) -> 0 | P14: =SUMIF('Ход 2031'!$G$29:$G$38,$A14,'Ход 2031'!$I$29:$I$38) -> 0 | Q14: =SUMIF('Ход 2032'!$G$29:$G$38,$A14,'Ход 2032'!$I$29:$I$38) -> 0 | R14: =SUMIF('Ход 2033'!$G$29:$G$38,$A14,'Ход 2033'!$I$29:$I$38) -> 0 | S14: =SUMIF('Ход 2034'!$G$29:$G$38,$A14,'Ход 2034'!$I$29:$I$38) -> 0 | T14: =SUMIF('Ход 2035'!$G$29:$G$38,$A14,'Ход 2035'!$I$29:$I$38) -> 0 | U14: =SUMIF('Ход 2036'!$G$29:$G$38,$A14,'Ход 2036'!$I$29:$I$38) -> 0 | V14: =SUMIF('Ход 2037'!$G$29:$G$38,$A14,'Ход 2037'!$I$29:$I$38) -> 0 | W14: =SUMIF('Ход 2038'!$G$29:$G$38,$A14,'Ход 2038'!$I$29:$I$38) -> 0 | X14: =SUMIF('Ход 2039'!$G$29:$G$38,$A14,'Ход 2039'!$I$29:$I$38) -> 0 | Y14: =SUMIF('Ход 2040'!$G$29:$G$38,$A14,'Ход 2040'!$I$29:$I$38) -> 0 | Z14: =SUM(K14:Y14) -> 0 | AA14: =MAX(0,E14-Z14) -> 65 | AB14: =BF14 -> ЗАКРЫТО | AC14: =SUM($K14:K14) -> 0 | AD14: =SUM($K14:L14) -> 0 | AE14: =SUM($K14:M14) -> 0 | AF14: =SUM($K14:N14) -> 0 | AG14: =SUM($K14:O14) -> 0 | AH14: =SUM($K14:P14) -> 0 | AI14: =SUM($K14:Q14) -> 0 | AJ14: =SUM($K14:R14) -> 0 | ... AQ14: =SUM($K14:Y14) -> 0 | AR14: =IF(AC14>=E14,"ИЗУЧЕНО",IF(AND(OR(F14="",SUMIF($A$11:$A$50,F14,AC$11:AC$50)>=SUMIF($A$11:$A$50,F14,$E$11:$E$50)),OR(G14="",SUMIF($A$11:$A$50,G14,AC$11:AC$50)>=SUMIF($A$11:$A$50,G14,$E$11:$E$50)),OR(H14="",SUMIF($A$11:$A$50,H14,AC$11:AC$50)>=SUMIF($A$11:$A$50,H14,$E$11:$E$50))),"ОТКРЫТО","ЗАКРЫТО")) -> ЗАКРЫТО | AS14: =IF(AD14>=E14,"ИЗУЧЕНО",IF(AND(OR(F14="",SUMIF($A$11:$A$50,F14,AD$11:AD$50)>=SUMIF($A$11:$A$50,F14,$E$11:$E$50)),OR(G14="",SUMIF($A$11:$A$50,G14,AD$11:AD$50)>=SUMIF($A$11:$A$50,G14,$E$11:$E$50)),OR(H14="",SUMIF($A$11:$A$50,H14,AD$11:AD$50)>=SUMIF($A$11:$A$50,H14,$E$11:$E$50))),"ОТКРЫТО","ЗАКРЫТО")) -> ЗАКРЫТО | AT14: =IF(AE14>=E14,"ИЗУЧЕНО",IF(AND(OR(F14="",SUMIF($A$11:$A$50,F14,AE$11:AE$50)>=SUMIF($A$11:$A$50,F14,$E$11:$E$50)),OR(G14="",SUMIF($A$11:$A$50,G14,AE$11:AE$50)>=SUMIF($A$11:$A$50,G14,$E$11:$E$50)),OR(H14="",SUMIF($A$11:$A$50,H14,AE$11:AE$50)>=SUMIF($A$11:$A$50,H14,$E$11:$E$50))),"ОТКРЫТО","ЗАКРЫТО")) -> ЗАКРЫТО | AU14: =IF(AF14>=E14,"ИЗУЧЕНО",IF(AND(OR(F14="",SUMIF($A$11:$A$50,F14,AF$11:AF$50)>=SUMIF($A$11:$A$50,F14,$E$11:$E$50)),OR(G14="",SUMIF($A$11:$A$50,G14,AF$11:AF$50)>=SUMIF($A$11:$A$50,G14,$E$11:$E$50)),OR(H14="",SUMIF($A$11:$A$50,H14,AF$11:AF$50)>=SUMIF($A$11:$A$50,H14,$E$11:$E$50))),"ОТКРЫТО","ЗАКРЫТО")) -> ЗАКРЫТО | AV14: =IF(AG14>=E14,"ИЗУЧЕНО",IF(AND(OR(F14="",SUMIF($A$11:$A$50,F14,AG$11:AG$50)>=SUMIF($A$11:$A$50,F14,$E$11:$E$50)),OR(G14="",SUMIF($A$11:$A$50,G14,AG$11:AG$50)>=SUMIF($A$11:$A$50,G14,$E$11:$E$50)),OR(H14="",SUMIF($A$11:$A$50,H14,AG$11:AG$50)>=SUMIF($A$11:$A$50,H14,$E$11:$E$50))),"ОТКРЫТО","ЗАКРЫТО")) -> ЗАКРЫТО | AW14: =IF(AH14>=E14,"ИЗУЧЕНО",IF(AND(OR(F14="",SUMIF($A$11:$A$50,F14,AH$11:AH$50)>=SUMIF($A$11:$A$50,F14,$E$11:$E$50)),OR(G14="",SUMIF($A$11:$A$50,G14,AH$11:AH$50)>=SUMIF($A$11:$A$50,G14,$E$11:$E$50)),OR(H14="",SUMIF($A$11:$A$50,H14,AH$11:AH$50)>=SUMIF($A$11:$A$50,H14,$E$11:$E$50))),"ОТКРЫТО","ЗАКРЫТО")) -> ЗАКРЫТО | AX14: =IF(AI14>=E14,"ИЗУЧЕНО",IF(AND(OR(F14="",SUMIF($A$11:$A$50,F14,AI$11:AI$50)>=SUMIF($A$11:$A$50,F14,$E$11:$E$50)),OR(G14="",SUMIF($A$11:$A$50,G14,AI$11:AI$50)>=SUMIF($A$11:$A$50,G14,$E$11:$E$50)),OR(H14="",SUMIF($A$11:$A$50,H14,AI$11:AI$50)>=SUMIF($A$11:$A$50,H14,$E$11:$E$50))),"ОТКРЫТО","ЗАКРЫТО")) -> ЗАКРЫТО | AY14: =IF(AJ14>=E14,"ИЗУЧЕНО",IF(AND(OR(F14="",SUMIF($A$11:$A$50,F14,AJ$11:AJ$50)>=SUMIF($A$11:$A$50,F14,$E$11:$E$50)),OR(G14="",SUMIF($A$11:$A$50,G14,AJ$11:AJ$50)>=SUMIF($A$11:$A$50,G14,$E$11:$E$50)),OR(H14="",SUMIF($A$11:$A$50,H14,AJ$11:AJ$50)>=SUMIF($A$11:$A$50,H14,$E$11:$E$50))),"ОТКРЫТО","ЗАКРЫТО")) -> ЗАКРЫТО | AZ14: =IF(AK14>=E14,"ИЗУЧЕНО",IF(AND(OR(F14="",SUMIF($A$11:$A$50,F14,AK$11:AK$50)>=SUMIF($A$11:$A$50,F14,$E$11:$E$50)),OR(G14="",SUMIF($A$11:$A$50,G14,AK$11:AK$50)>=SUMIF($A$11:$A$50,G14,$E$11:$E$50)),OR(H14="",SUMIF($A$11:$A$50,H14,AK$11:AK$50)>=SUMIF($A$11:$A$50,H14,$E$11:$E$50))),"ОТКРЫТО","ЗАКРЫТО")) -> ЗАКРЫТО | BA14: =IF(AL14>=E14,"ИЗУЧЕНО",IF(AND(OR(F14="",SUMIF($A$11:$A$50,F14,AL$11:AL$50)>=SUMIF($A$11:$A$50,F14,$E$11:$E$50)),OR(G14="",SUMIF($A$11:$A$50,G14,AL$11:AL$50)>=SUMIF($A$11:$A$50,G14,$E$11:$E$50)),OR(H14="",SUMIF($A$11:$A$50,H14,AL$11:AL$50)>=SUMIF($A$11:$A$50,H14,$E$11:$E$50))),"ОТКРЫТО","ЗАКРЫТО")) -> ЗАКРЫТО | BB14: =IF(AM14>=E14,"ИЗУЧЕНО",IF(AND(OR(F14="",SUMIF($A$11:$A$50,F14,AM$11:AM$50)>=SUMIF($A$11:$A$50,F14,$E$11:$E$50)),OR(G14="",SUMIF($A$11:$A$50,G14,AM$11:AM$50)>=SUMIF($A$11:$A$50,G14,$E$11:$E$50)),OR(H14="",SUMIF($A$11:$A$50,H14,AM$11:AM$50)>=SUMIF($A$11:$A$50,H14,$E$11:$E$50))),"ОТКРЫТО","ЗАКРЫТО")) -> ЗАКРЫТО | BC14: =IF(AN14>=E14,"ИЗУЧЕНО",IF(AND(OR(F14="",SUMIF($A$11:$A$50,F14,AN$11:AN$50)>=SUMIF($A$11:$A$50,F14,$E$11:$E$50)),OR(G14="",SUMIF($A$11:$A$50,G14,AN$11:AN$50)>=SUMIF($A$11:$A$50,G14,$E$11:$E$50)),OR(H14="",SUMIF($A$11:$A$50,H14,AN$11:AN$50)>=SUMIF($A$11:$A$50,H14,$E$11:$E$50))),"ОТКРЫТО","ЗАКРЫТО")) -> ЗАКРЫТО | BD14: =IF(AO14>=E14,"ИЗУЧЕНО",IF(AND(OR(F14="",SUMIF($A$11:$A$50,F14,AO$11:AO$50)>=SUMIF($A$11:$A$50,F14,$E$11:$E$50)),OR(G14="",SUMIF($A$11:$A$50,G14,AO$11:AO$50)>=SUMIF($A$11:$A$50,G14,$E$11:$E$50)),OR(H14="",SUMIF($A$11:$A$50,H14,AO$11:AO$50)>=SUMIF($A$11:$A$50,H14,$E$11:$E$50))),"ОТКРЫТО","ЗАКРЫТО")) -> ЗАКРЫТО | BE14: =IF(AP14>=E14,"ИЗУЧЕНО",IF(AND(OR(F14="",SUMIF($A$11:$A$50,F14,AP$11:AP$50)>=SUMIF($A$11:$A$50,F14,$E$11:$E$50)),OR(G14="",SUMIF($A$11:$A$50,G14,AP$11:AP$50)>=SUMIF($A$11:$A$50,G14,$E$11:$E$50)),OR(H14="",SUMIF($A$11:$A$50,H14,AP$11:AP$50)>=SUMIF($A$11:$A$50,H14,$E$11:$E$50))),"ОТКРЫТО","ЗАКРЫТО")) -> ЗАКРЫТО | BF14: =IF(AQ14>=E14,"ИЗУЧЕНО",IF(AND(OR(F14="",SUMIF($A$11:$A$50,F14,AQ$11:AQ$50)>=SUMIF($A$11:$A$50,F14,$E$11:$E$50)),OR(G14="",SUMIF($A$11:$A$50,G14,AQ$11:AQ$50)>=SUMIF($A$11:$A$50,G14,$E$11:$E$50)),OR(H14="",SUMIF($A$11:$A$50,H14,AQ$11:AQ$50)>=SUMIF($A$11:$A$50,H14,$E$11:$E$50))),"ОТКРЫТО","ЗАКРЫТО")) -> ЗАКРЫТО
A15: C5 | B15: Вычисления и аппаратная база | C15: IV | D15: Суверенная распределённая вычислительная сеть | E15: 100 | F15: C4 | I15: Национальная сеть взаимозаменяемых ЦОД и вычислительных узлов. | J15: Сетевые ресурсы +0,4; прирост ЦОД +0,10/год; защита Афины +15% | K15: =SUMIF('Ход 2026'!$G$29:$G$38,$A15,'Ход 2026'!$I$29:$I$38) -> 0 | L15: =SUMIF('Ход 2027'!$G$29:$G$38,$A15,'Ход 2027'!$I$29:$I$38) -> 0 | M15: =SUMIF('Ход 2028'!$G$29:$G$38,$A15,'Ход 2028'!$I$29:$I$38) -> 0 | N15: =SUMIF('Ход 2029'!$G$29:$G$38,$A15,'Ход 2029'!$I$29:$I$38) -> 0 | O15: =SUMIF('Ход 2030'!$G$29:$G$38,$A15,'Ход 2030'!$I$29:$I$38) -> 0 | P15: =SUMIF('Ход 2031'!$G$29:$G$38,$A15,'Ход 2031'!$I$29:$I$38) -> 0 | Q15: =SUMIF('Ход 2032'!$G$29:$G$38,$A15,'Ход 2032'!$I$29:$I$38) -> 0 | R15: =SUMIF('Ход 2033'!$G$29:$G$38,$A15,'Ход 2033'!$I$29:$I$38) -> 0 | S15: =SUMIF('Ход 2034'!$G$29:$G$38,$A15,'Ход 2034'!$I$29:$I$38) -> 0 | T15: =SUMIF('Ход 2035'!$G$29:$G$38,$A15,'Ход 2035'!$I$29:$I$38) -> 0 | U15: =SUMIF('Ход 2036'!$G$29:$G$38,$A15,'Ход 2036'!$I$29:$I$38) -> 0 | V15: =SUMIF('Ход 2037'!$G$29:$G$38,$A15,'Ход 2037'!$I$29:$I$38) -> 0 | W15: =SUMIF('Ход 2038'!$G$29:$G$38,$A15,'Ход 2038'!$I$29:$I$38) -> 0 | X15: =SUMIF('Ход 2039'!$G$29:$G$38,$A15,'Ход 2039'!$I$29:$I$38) -> 0 | Y15: =SUMIF('Ход 2040'!$G$29:$G$38,$A15,'Ход 2040'!$I$29:$I$38) -> 0 | Z15: =SUM(K15:Y15) -> 0 | AA15: =MAX(0,E15-Z15) -> 100 | AB15: =BF15 -> ЗАКРЫТО | AC15: =SUM($K15:K15) -> 0 | AD15: =SUM($K15:L15) -> 0 | AE15: =SUM($K15:M15) -> 0 | AF15: =SUM($K15:N15) -> 0 | AG15: =SUM($K15:O15) -> 0 | AH15: =SUM($K15:P15) -> 0 | AI15: =SUM($K15:Q15) -> 0 | AJ15: =SUM($K15:R15) -> 0 | ... AQ15: =SUM($K15:Y15) -> 0 | AR15: =IF(AC15>=E15,"ИЗУЧЕНО",IF(AND(OR(F15="",SUMIF($A$11:$A$50,F15,AC$11:AC$50)>=SUMIF($A$11:$A$50,F15,$E$11:$E$50)),OR(G15="",SUMIF($A$11:$A$50,G15,AC$11:AC$50)>=SUMIF($A$11:$A$50,G15,$E$11:$E$50)),OR(H15="",SUMIF($A$11:$A$50,H15,AC$11:AC$50)>=SUMIF($A$11:$A$50,H15,$E$11:$E$50))),"ОТКРЫТО","ЗАКРЫТО")) -> ЗАКРЫТО | AS15: =IF(AD15>=E15,"ИЗУЧЕНО",IF(AND(OR(F15="",SUMIF($A$11:$A$50,F15,AD$11:AD$50)>=SUMIF($A$11:$A$50,F15,$E$11:$E$50)),OR(G15="",SUMIF($A$11:$A$50,G15,AD$11:AD$50)>=SUMIF($A$11:$A$50,G15,$E$11:$E$50)),OR(H15="",SUMIF($A$11:$A$50,H15,AD$11:AD$50)>=SUMIF($A$11:$A$50,H15,$E$11:$E$50))),"ОТКРЫТО","ЗАКРЫТО")) -> ЗАКРЫТО | AT15: =IF(AE15>=E15,"ИЗУЧЕНО",IF(AND(OR(F15="",SUMIF($A$11:$A$50,F15,AE$11:AE$50)>=SUMIF($A$11:$A$50,F15,$E$11:$E$50)),OR(G15="",SUMIF($A$11:$A$50,G15,AE$11:AE$50)>=SUMIF($A$11:$A$50,G15,$E$11:$E$50)),OR(H15="",SUMIF($A$11:$A$50,H15,AE$11:AE$50)>=SUMIF($A$11:$A$50,H15,$E$11:$E$50))),"ОТКРЫТО","ЗАКРЫТО")) -> ЗАКРЫТО | AU15: =IF(AF15>=E15,"ИЗУЧЕНО",IF(AND(OR(F15="",SUMIF($A$11:$A$50,F15,AF$11:AF$50)>=SUMIF($A$11:$A$50,F15,$E$11:$E$50)),OR(G15="",SUMIF($A$11:$A$50,G15,AF$11:AF$50)>=SUMIF($A$11:$A$50,G15,$E$11:$E$50)),OR(H15="",SUMIF($A$11:$A$50,H15,AF$11:AF$50)>=SUMIF($A$11:$A$50,H15,$E$11:$E$50))),"ОТКРЫТО","ЗАКРЫТО")) -> ЗАКРЫТО | AV15: =IF(AG15>=E15,"ИЗУЧЕНО",IF(AND(OR(F15="",SUMIF($A$11:$A$50,F15,AG$11:AG$50)>=SUMIF($A$11:$A$50,F15,$E$11:$E$50)),OR(G15="",SUMIF($A$11:$A$50,G15,AG$11:AG$50)>=SUMIF($A$11:$A$50,G15,$E$11:$E$50)),OR(H15="",SUMIF($A$11:$A$50,H15,AG$11:AG$50)>=SUMIF($A$11:$A$50,H15,$E$11:$E$50))),"ОТКРЫТО","ЗАКРЫТО")) -> ЗАКРЫТО | AW15: =IF(AH15>=E15,"ИЗУЧЕНО",IF(AND(OR(F15="",SUMIF($A$11:$A$50,F15,AH$11:AH$50)>=SUMIF($A$11:$A$50,F15,$E$11:$E$50)),OR(G15="",SUMIF($A$11:$A$50,G15,AH$11:AH$50)>=SUMIF($A$11:$A$50,G15,$E$11:$E$50)),OR(H15="",SUMIF($A$11:$A$50,H15,AH$11:AH$50)>=SUMIF($A$11:$A$50,H15,$E$11:$E$50))),"ОТКРЫТО","ЗАКРЫТО")) -> ЗАКРЫТО | AX15: =IF(AI15>=E15,"ИЗУЧЕНО",IF(AND(OR(F15="",SUMIF($A$11:$A$50,F15,AI$11:AI$50)>=SUMIF($A$11:$A$50,F15,$E$11:$E$50)),OR(G15="",SUMIF($A$11:$A$50,G15,AI$11:AI$50)>=SUMIF($A$11:$A$50,G15,$E$11:$E$50)),OR(H15="",SUMIF($A$11:$A$50,H15,AI$11:AI$50)>=SUMIF($A$11:$A$50,H15,$E$11:$E$50))),"ОТКРЫТО","ЗАКРЫТО")) -> ЗАКРЫТО | AY15: =IF(AJ15>=E15,"ИЗУЧЕНО",IF(AND(OR(F15="",SUMIF($A$11:$A$50,F15,AJ$11:AJ$50)>=SUMIF($A$11:$A$50,F15,$E$11:$E$50)),OR(G15="",SUMIF($A$11:$A$50,G15,AJ$11:AJ$50)>=SUMIF($A$11:$A$50,G15,$E$11:$E$50)),OR(H15="",SUMIF($A$11:$A$50,H15,AJ$11:AJ$50)>=SUMIF($A$11:$A$50,H15,$E$11:$E$50))),"ОТКРЫТО","ЗАКРЫТО")) -> ЗАКРЫТО | AZ15: =IF(AK15>=E15,"ИЗУЧЕНО",IF(AND(OR(F15="",SUMIF($A$11:$A$50,F15,AK$11:AK$50)>=SUMIF($A$11:$A$50,F15,$E$11:$E$50)),OR(G15="",SUMIF($A$11:$A$50,G15,AK$11:AK$50)>=SUMIF($A$11:$A$50,G15,$E$11:$E$50)),OR(H15="",SUMIF($A$11:$A$50,H15,AK$11:AK$50)>=SUMIF($A$11:$A$50,H15,$E$11:$E$50))),"ОТКРЫТО","ЗАКРЫТО")) -> ЗАКРЫТО | BA15: =IF(AL15>=E15,"ИЗУЧЕНО",IF(AND(OR(F15="",SUMIF($A$11:$A$50,F15,AL$11:AL$50)>=SUMIF($A$11:$A$50,F15,$E$11:$E$50)),OR(G15="",SUMIF($A$11:$A$50,G15,AL$11:AL$50)>=SUMIF($A$11:$A$50,G15,$E$11:$E$50)),OR(H15="",SUMIF($A$11:$A$50,H15,AL$11:AL$50)>=SUMIF($A$11:$A$50,H15,$E$11:$E$50))),"ОТКРЫТО","ЗАКРЫТО")) -> ЗАКРЫТО | BB15: =IF(AM15>=E15,"ИЗУЧЕНО",IF(AND(OR(F15="",SUMIF($A$11:$A$50,F15,AM$11:AM$50)>=SUMIF($A$11:$A$50,F15,$E$11:$E$50)),OR(G15="",SUMIF($A$11:$A$50,G15,AM$11:AM$50)>=SUMIF($A$11:$A$50,G15,$E$11:$E$50)),OR(H15="",SUMIF($A$11:$A$50,H15,AM$11:AM$50)>=SUMIF($A$11:$A$50,H15,$E$11:$E$50))),"ОТКРЫТО","ЗАКРЫТО")) -> ЗАКРЫТО | BC15: =IF(AN15>=E15,"ИЗУЧЕНО",IF(AND(OR(F15="",SUMIF($A$11:$A$50,F15,AN$11:AN$50)>=SUMIF($A$11:$A$50,F15,$E$11:$E$50)),OR(G15="",SUMIF($A$11:$A$50,G15,AN$11:AN$50)>=SUMIF($A$11:$A$50,G15,$E$11:$E$50)),OR(H15="",SUMIF($A$11:$A$50,H15,AN$11:AN$50)>=SUMIF($A$11:$A$50,H15,$E$11:$E$50))),"ОТКРЫТО","ЗАКРЫТО")) -> ЗАКРЫТО | BD15: =IF(AO15>=E15,"ИЗУЧЕНО",IF(AND(OR(F15="",SUMIF($A$11:$A$50,F15,AO$11:AO$50)>=SUMIF($A$11:$A$50,F15,$E$11:$E$50)),OR(G15="",SUMIF($A$11:$A$50,G15,AO$11:AO$50)>=SUMIF($A$11:$A$50,G15,$E$11:$E$50)),OR(H15="",SUMIF($A$11:$A$50,H15,AO$11:AO$50)>=SUMIF($A$11:$A$50,H15,$E$11:$E$50))),"ОТКРЫТО","ЗАКРЫТО")) -> ЗАКРЫТО | BE15: =IF(AP15>=E15,"ИЗУЧЕНО",IF(AND(OR(F15="",SUMIF($A$11:$A$50,F15,AP$11:AP$50)>=SUMIF($A$11:$A$50,F15,$E$11:$E$50)),OR(G15="",SUMIF($A$11:$A$50,G15,AP$11:AP$50)>=SUMIF($A$11:$A$50,G15,$E$11:$E$50)),OR(H15="",SUMIF($A$11:$A$50,H15,AP$11:AP$50)>=SUMIF($A$11:$A$50,H15,$E$11:$E$50))),"ОТКРЫТО","ЗАКРЫТО")) -> ЗАКРЫТО | BF15: =IF(AQ15>=E15,"ИЗУЧЕНО",IF(AND(OR(F15="",SUMIF($A$11:$A$50,F15,AQ$11:AQ$50)>=SUMIF($A$11:$A$50,F15,$E$11:$E$50)),OR(G15="",SUMIF($A$11:$A$50,G15,AQ$11:AQ$50)>=SUMIF($A$11:$A$50,G15,$E$11:$E$50)),OR(H15="",SUMIF($A$11:$A$50,H15,AQ$11:AQ$50)>=SUMIF($A$11:$A$50,H15,$E$11:$E$50))),"ОТКРЫТО","ЗАКРЫТО")) -> ЗАКРЫТО
A16: C6 | B16: Вычисления и аппаратная база | C16: V | D16: Новые вычислительные архитектуры | E16: 150 | F16: C5 | I16: Нейроморфные, вычислительно-памятные и иные постфоннеймановские архитектуры. | J16: Вычислительные компоненты +0,5; Математико-алгоритмические ресурсы +0,3; исследования ветви Модели +10% | K16: =SUMIF('Ход 2026'!$G$29:$G$38,$A16,'Ход 2026'!$I$29:$I$38) -> 0 | L16: =SUMIF('Ход 2027'!$G$29:$G$38,$A16,'Ход 2027'!$I$29:$I$38) -> 0 | M16: =SUMIF('Ход 2028'!$G$29:$G$38,$A16,'Ход 2028'!$I$29:$I$38) -> 0 | N16: =SUMIF('Ход 2029'!$G$29:$G$38,$A16,'Ход 2029'!$I$29:$I$38) -> 0 | O16: =SUMIF('Ход 2030'!$G$29:$G$38,$A16,'Ход 2030'!$I$29:$I$38) -> 0 | P16: =SUMIF('Ход 2031'!$G$29:$G$38,$A16,'Ход 2031'!$I$29:$I$38) -> 0 | Q16: =SUMIF('Ход 2032'!$G$29:$G$38,$A16,'Ход 2032'!$I$29:$I$38) -> 0 | R16: =SUMIF('Ход 2033'!$G$29:$G$38,$A16,'Ход 2033'!$I$29:$I$38) -> 0 | S16: =SUMIF('Ход 2034'!$G$29:$G$38,$A16,'Ход 2034'!$I$29:$I$38) -> 0 | T16: =SUMIF('Ход 2035'!$G$29:$G$38,$A16,'Ход 2035'!$I$29:$I$38) -> 0 | U16: =SUMIF('Ход 2036'!$G$29:$G$38,$A16,'Ход 2036'!$I$29:$I$38) -> 0 | V16: =SUMIF('Ход 2037'!$G$29:$G$38,$A16,'Ход 2037'!$I$29:$I$38) -> 0 | W16: =SUMIF('Ход 2038'!$G$29:$G$38,$A16,'Ход 2038'!$I$29:$I$38) -> 0 | X16: =SUMIF('Ход 2039'!$G$29:$G$38,$A16,'Ход 2039'!$I$29:$I$38) -> 0 | Y16: =SUMIF('Ход 2040'!$G$29:$G$38,$A16,'Ход 2040'!$I$29:$I$38) -> 0 | Z16: =SUM(K16:Y16) -> 0 | AA16: =MAX(0,E16-Z16) -> 150 | AB16: =BF16 -> ЗАКРЫТО | AC16: =SUM($K16:K16) -> 0 | AD16: =SUM($K16:L16) -> 0 | AE16: =SUM($K16:M16) -> 0 | AF16: =SUM($K16:N16) -> 0 | AG16: =SUM($K16:O16) -> 0 | AH16: =SUM($K16:P16) -> 0 | AI16: =SUM($K16:Q16) -> 0 | AJ16: =SUM($K16:R16) -> 0 | ... AQ16: =SUM($K16:Y16) -> 0 | AR16: =IF(AC16>=E16,"ИЗУЧЕНО",IF(AND(OR(F16="",SUMIF($A$11:$A$50,F16,AC$11:AC$50)>=SUMIF($A$11:$A$50,F16,$E$11:$E$50)),OR(G16="",SUMIF($A$11:$A$50,G16,AC$11:AC$50)>=SUMIF($A$11:$A$50,G16,$E$11:$E$50)),OR(H16="",SUMIF($A$11:$A$50,H16,AC$11:AC$50)>=SUMIF($A$11:$A$50,H16,$E$11:$E$50))),"ОТКРЫТО","ЗАКРЫТО")) -> ЗАКРЫТО | AS16: =IF(AD16>=E16,"ИЗУЧЕНО",IF(AND(OR(F16="",SUMIF($A$11:$A$50,F16,AD$11:AD$50)>=SUMIF($A$11:$A$50,F16,$E$11:$E$50)),OR(G16="",SUMIF($A$11:$A$50,G16,AD$11:AD$50)>=SUMIF($A$11:$A$50,G16,$E$11:$E$50)),OR(H16="",SUMIF($A$11:$A$50,H16,AD$11:AD$50)>=SUMIF($A$11:$A$50,H16,$E$11:$E$50))),"ОТКРЫТО","ЗАКРЫТО")) -> ЗАКРЫТО | AT16: =IF(AE16>=E16,"ИЗУЧЕНО",IF(AND(OR(F16="",SUMIF($A$11:$A$50,F16,AE$11:AE$50)>=SUMIF($A$11:$A$50,F16,$E$11:$E$50)),OR(G16="",SUMIF($A$11:$A$50,G16,AE$11:AE$50)>=SUMIF($A$11:$A$50,G16,$E$11:$E$50)),OR(H16="",SUMIF($A$11:$A$50,H16,AE$11:AE$50)>=SUMIF($A$11:$A$50,H16,$E$11:$E$50))),"ОТКРЫТО","ЗАКРЫТО")) -> ЗАКРЫТО | AU16: =IF(AF16>=E16,"ИЗУЧЕНО",IF(AND(OR(F16="",SUMIF($A$11:$A$50,F16,AF$11:AF$50)>=SUMIF($A$11:$A$50,F16,$E$11:$E$50)),OR(G16="",SUMIF($A$11:$A$50,G16,AF$11:AF$50)>=SUMIF($A$11:$A$50,G16,$E$11:$E$50)),OR(H16="",SUMIF($A$11:$A$50,H16,AF$11:AF$50)>=SUMIF($A$11:$A$50,H16,$E$11:$E$50))),"ОТКРЫТО","ЗАКРЫТО")) -> ЗАКРЫТО | AV16: =IF(AG16>=E16,"ИЗУЧЕНО",IF(AND(OR(F16="",SUMIF($A$11:$A$50,F16,AG$11:AG$50)>=SUMIF($A$11:$A$50,F16,$E$11:$E$50)),OR(G16="",SUMIF($A$11:$A$50,G16,AG$11:AG$50)>=SUMIF($A$11:$A$50,G16,$E$11:$E$50)),OR(H16="",SUMIF($A$11:$A$50,H16,AG$11:AG$50)>=SUMIF($A$11:$A$50,H16,$E$11:$E$50))),"ОТКРЫТО","ЗАКРЫТО")) -> ЗАКРЫТО | AW16: =IF(AH16>=E16,"ИЗУЧЕНО",IF(AND(OR(F16="",SUMIF($A$11:$A$50,F16,AH$11:AH$50)>=SUMIF($A$11:$A$50,F16,$E$11:$E$50)),OR(G16="",SUMIF($A$11:$A$50,G16,AH$11:AH$50)>=SUMIF($A$11:$A$50,G16,$E$11:$E$50)),OR(H16="",SUMIF($A$11:$A$50,H16,AH$11:AH$50)>=SUMIF($A$11:$A$50,H16,$E$11:$E$50))),"ОТКРЫТО","ЗАКРЫТО")) -> ЗАКРЫТО | AX16: =IF(AI16>=E16,"ИЗУЧЕНО",IF(AND(OR(F16="",SUMIF($A$11:$A$50,F16,AI$11:AI$50)>=SUMIF($A$11:$A$50,F16,$E$11:$E$50)),OR(G16="",SUMIF($A$11:$A$50,G16,AI$11:AI$50)>=SUMIF($A$11:$A$50,G16,$E$11:$E$50)),OR(H16="",SUMIF($A$11:$A$50,H16,AI$11:AI$50)>=SUMIF($A$11:$A$50,H16,$E$11:$E$50))),"ОТКРЫТО","ЗАКРЫТО")) -> ЗАКРЫТО | AY16: =IF(AJ16>=E16,"ИЗУЧЕНО",IF(AND(OR(F16="",SUMIF($A$11:$A$50,F16,AJ$11:AJ$50)>=SUMIF($A$11:$A$50,F16,$E$11:$E$50)),OR(G16="",SUMIF($A$11:$A$50,G16,AJ$11:AJ$50)>=SUMIF($A$11:$A$50,G16,$E$11:$E$50)),OR(H16="",SUMIF($A$11:$A$50,H16,AJ$11:AJ$50)>=SUMIF($A$11:$A$50,H16,$E$11:$E$50))),"ОТКРЫТО","ЗАКРЫТО")) -> ЗАКРЫТО | AZ16: =IF(AK16>=E16,"ИЗУЧЕНО",IF(AND(OR(F16="",SUMIF($A$11:$A$50,F16,AK$11:AK$50)>=SUMIF($A$11:$A$50,F16,$E$11:$E$50)),OR(G16="",SUMIF($A$11:$A$50,G16,AK$11:AK$50)>=SUMIF($A$11:$A$50,G16,$E$11:$E$50)),OR(H16="",SUMIF($A$11:$A$50,H16,AK$11:AK$50)>=SUMIF($A$11:$A$50,H16,$E$11:$E$50))),"ОТКРЫТО","ЗАКРЫТО")) -> ЗАКРЫТО | BA16: =IF(AL16>=E16,"ИЗУЧЕНО",IF(AND(OR(F16="",SUMIF($A$11:$A$50,F16,AL$11:AL$50)>=SUMIF($A$11:$A$50,F16,$E$11:$E$50)),OR(G16="",SUMIF($A$11:$A$50,G16,AL$11:AL$50)>=SUMIF($A$11:$A$50,G16,$E$11:$E$50)),OR(H16="",SUMIF($A$11:$A$50,H16,AL$11:AL$50)>=SUMIF($A$11:$A$50,H16,$E$11:$E$50))),"ОТКРЫТО","ЗАКРЫТО")) -> ЗАКРЫТО | BB16: =IF(AM16>=E16,"ИЗУЧЕНО",IF(AND(OR(F16="",SUMIF($A$11:$A$50,F16,AM$11:AM$50)>=SUMIF($A$11:$A$50,F16,$E$11:$E$50)),OR(G16="",SUMIF($A$11:$A$50,G16,AM$11:AM$50)>=SUMIF($A$11:$A$50,G16,$E$11:$E$50)),OR(H16="",SUMIF($A$11:$A$50,H16,AM$11:AM$50)>=SUMIF($A$11:$A$50,H16,$E$11:$E$50))),"ОТКРЫТО","ЗАКРЫТО")) -> ЗАКРЫТО | BC16: =IF(AN16>=E16,"ИЗУЧЕНО",IF(AND(OR(F16="",SUMIF($A$11:$A$50,F16,AN$11:AN$50)>=SUMIF($A$11:$A$50,F16,$E$11:$E$50)),OR(G16="",SUMIF($A$11:$A$50,G16,AN$11:AN$50)>=SUMIF($A$11:$A$50,G16,$E$11:$E$50)),OR(H16="",SUMIF($A$11:$A$50,H16,AN$11:AN$50)>=SUMIF($A$11:$A$50,H16,$E$11:$E$50))),"ОТКРЫТО","ЗАКРЫТО")) -> ЗАКРЫТО | BD16: =IF(AO16>=E16,"ИЗУЧЕНО",IF(AND(OR(F16="",SUMIF($A$11:$A$50,F16,AO$11:AO$50)>=SUMIF($A$11:$A$50,F16,$E$11:$E$50)),OR(G16="",SUMIF($A$11:$A$50,G16,AO$11:AO$50)>=SUMIF($A$11:$A$50,G16,$E$11:$E$50)),OR(H16="",SUMIF($A$11:$A$50,H16,AO$11:AO$50)>=SUMIF($A$11:$A$50,H16,$E$11:$E$50))),"ОТКРЫТО","ЗАКРЫТО")) -> ЗАКРЫТО | BE16: =IF(AP16>=E16,"ИЗУЧЕНО",IF(AND(OR(F16="",SUMIF($A$11:$A$50,F16,AP$11:AP$50)>=SUMIF($A$11:$A$50,F16,$E$11:$E$50)),OR(G16="",SUMIF($A$11:$A$50,G16,AP$11:AP$50)>=SUMIF($A$11:$A$50,G16,$E$11:$E$50)),OR(H16="",SUMIF($A$11:$A$50,H16,AP$11:AP$50)>=SUMIF($A$11:$A$50,H16,$E$11:$E$50))),"ОТКРЫТО","ЗАКРЫТО")) -> ЗАКРЫТО | BF16: =IF(AQ16>=E16,"ИЗУЧЕНО",IF(AND(OR(F16="",SUMIF($A$11:$A$50,F16,AQ$11:AQ$50)>=SUMIF($A$11:$A$50,F16,$E$11:$E$50)),OR(G16="",SUMIF($A$11:$A$50,G16,AQ$11:AQ$50)>=SUMIF($A$11:$A$50,G16,$E$11:$E$50)),OR(H16="",SUMIF($A$11:$A$50,H16,AQ$11:AQ$50)>=SUMIF($A$11:$A$50,H16,$E$11:$E$50))),"ОТКРЫТО","ЗАКРЫТО")) -> ЗАКРЫТО
A17: M1 | B17: Модели и алгоритмы | C17: I | D17: Эффективное обучение моделей | E17: 20 | I17: Улучшенные методы оптимизации, сжатия и обучения моделей. | J17: Методы построения моделей +0,2; их прирост +0,05/год | K17: =SUMIF('Ход 2026'!$G$29:$G$38,$A17,'Ход 2026'!$I$29:$I$38) -> 0 | L17: =SUMIF('Ход 2027'!$G$29:$G$38,$A17,'Ход 2027'!$I$29:$I$38) -> 0 | M17: =SUMIF('Ход 2028'!$G$29:$G$38,$A17,'Ход 2028'!$I$29:$I$38) -> 0 | N17: =SUMIF('Ход 2029'!$G$29:$G$38,$A17,'Ход 2029'!$I$29:$I$38) -> 0 | O17: =SUMIF('Ход 2030'!$G$29:$G$38,$A17,'Ход 2030'!$I$29:$I$38) -> 0 | P17: =SUMIF('Ход 2031'!$G$29:$G$38,$A17,'Ход 2031'!$I$29:$I$38) -> 0 | Q17: =SUMIF('Ход 2032'!$G$29:$G$38,$A17,'Ход 2032'!$I$29:$I$38) -> 0 | R17: =SUMIF('Ход 2033'!$G$29:$G$38,$A17,'Ход 2033'!$I$29:$I$38) -> 0 | S17: =SUMIF('Ход 2034'!$G$29:$G$38,$A17,'Ход 2034'!$I$29:$I$38) -> 0 | T17: =SUMIF('Ход 2035'!$G$29:$G$38,$A17,'Ход 2035'!$I$29:$I$38) -> 0 | U17: =SUMIF('Ход 2036'!$G$29:$G$38,$A17,'Ход 2036'!$I$29:$I$38) -> 0 | V17: =SUMIF('Ход 2037'!$G$29:$G$38,$A17,'Ход 2037'!$I$29:$I$38) -> 0 | W17: =SUMIF('Ход 2038'!$G$29:$G$38,$A17,'Ход 2038'!$I$29:$I$38) -> 0 | X17: =SUMIF('Ход 2039'!$G$29:$G$38,$A17,'Ход 2039'!$I$29:$I$38) -> 0 | Y17: =SUMIF('Ход 2040'!$G$29:$G$38,$A17,'Ход 2040'!$I$29:$I$38) -> 0 | Z17: =SUM(K17:Y17) -> 0 | AA17: =MAX(0,E17-Z17) -> 20 | AB17: =BF17 -> ОТКРЫТО | AC17: =SUM($K17:K17) -> 0 | AD17: =SUM($K17:L17) -> 0 | AE17: =SUM($K17:M17) -> 0 | AF17: =SUM($K17:N17) -> 0 | AG17: =SUM($K17:O17) -> 0 | AH17: =SUM($K17:P17) -> 0 | AI17: =SUM($K17:Q17) -> 0 | AJ17: =SUM($K17:R17) -> 0 | ... AQ17: =SUM($K17:Y17) -> 0 | AR17: =IF(AC17>=E17,"ИЗУЧЕНО",IF(AND(OR(F17="",SUMIF($A$11:$A$50,F17,AC$11:AC$50)>=SUMIF($A$11:$A$50,F17,$E$11:$E$50)),OR(G17="",SUMIF($A$11:$A$50,G17,AC$11:AC$50)>=SUMIF($A$11:$A$50,G17,$E$11:$E$50)),OR(H17="",SUMIF($A$11:$A$50,H17,AC$11:AC$50)>=SUMIF($A$11:$A$50,H17,$E$11:$E$50))),"ОТКРЫТО","ЗАКРЫТО")) -> ОТКРЫТО | AS17: =IF(AD17>=E17,"ИЗУЧЕНО",IF(AND(OR(F17="",SUMIF($A$11:$A$50,F17,AD$11:AD$50)>=SUMIF($A$11:$A$50,F17,$E$11:$E$50)),OR(G17="",SUMIF($A$11:$A$50,G17,AD$11:AD$50)>=SUMIF($A$11:$A$50,G17,$E$11:$E$50)),OR(H17="",SUMIF($A$11:$A$50,H17,AD$11:AD$50)>=SUMIF($A$11:$A$50,H17,$E$11:$E$50))),"ОТКРЫТО","ЗАКРЫТО")) -> ОТКРЫТО | AT17: =IF(AE17>=E17,"ИЗУЧЕНО",IF(AND(OR(F17="",SUMIF($A$11:$A$50,F17,AE$11:AE$50)>=SUMIF($A$11:$A$50,F17,$E$11:$E$50)),OR(G17="",SUMIF($A$11:$A$50,G17,AE$11:AE$50)>=SUMIF($A$11:$A$50,G17,$E$11:$E$50)),OR(H17="",SUMIF($A$11:$A$50,H17,AE$11:AE$50)>=SUMIF($A$11:$A$50,H17,$E$11:$E$50))),"ОТКРЫТО","ЗАКРЫТО")) -> ОТКРЫТО | AU17: =IF(AF17>=E17,"ИЗУЧЕНО",IF(AND(OR(F17="",SUMIF($A$11:$A$50,F17,AF$11:AF$50)>=SUMIF($A$11:$A$50,F17,$E$11:$E$50)),OR(G17="",SUMIF($A$11:$A$50,G17,AF$11:AF$50)>=SUMIF($A$11:$A$50,G17,$E$11:$E$50)),OR(H17="",SUMIF($A$11:$A$50,H17,AF$11:AF$50)>=SUMIF($A$11:$A$50,H17,$E$11:$E$50))),"ОТКРЫТО","ЗАКРЫТО")) -> ОТКРЫТО | AV17: =IF(AG17>=E17,"ИЗУЧЕНО",IF(AND(OR(F17="",SUMIF($A$11:$A$50,F17,AG$11:AG$50)>=SUMIF($A$11:$A$50,F17,$E$11:$E$50)),OR(G17="",SUMIF($A$11:$A$50,G17,AG$11:AG$50)>=SUMIF($A$11:$A$50,G17,$E$11:$E$50)),OR(H17="",SUMIF($A$11:$A$50,H17,AG$11:AG$50)>=SUMIF($A$11:$A$50,H17,$E$11:$E$50))),"ОТКРЫТО","ЗАКРЫТО")) -> ОТКРЫТО | AW17: =IF(AH17>=E17,"ИЗУЧЕНО",IF(AND(OR(F17="",SUMIF($A$11:$A$50,F17,AH$11:AH$50)>=SUMIF($A$11:$A$50,F17,$E$11:$E$50)),OR(G17="",SUMIF($A$11:$A$50,G17,AH$11:AH$50)>=SUMIF($A$11:$A$50,G17,$E$11:$E$50)),OR(H17="",SUMIF($A$11:$A$50,H17,AH$11:AH$50)>=SUMIF($A$11:$A$50,H17,$E$11:$E$50))),"ОТКРЫТО","ЗАКРЫТО")) -> ОТКРЫТО | AX17: =IF(AI17>=E17,"ИЗУЧЕНО",IF(AND(OR(F17="",SUMIF($A$11:$A$50,F17,AI$11:AI$50)>=SUMIF($A$11:$A$50,F17,$E$11:$E$50)),OR(G17="",SUMIF($A$11:$A$50,G17,AI$11:AI$50)>=SUMIF($A$11:$A$50,G17,$E$11:$E$50)),OR(H17="",SUMIF($A$11:$A$50,H17,AI$11:AI$50)>=SUMIF($A$11:$A$50,H17,$E$11:$E$50))),"ОТКРЫТО","ЗАКРЫТО")) -> ОТКРЫТО | AY17: =IF(AJ17>=E17,"ИЗУЧЕНО",IF(AND(OR(F17="",SUMIF($A$11:$A$50,F17,AJ$11:AJ$50)>=SUMIF($A$11:$A$50,F17,$E$11:$E$50)),OR(G17="",SUMIF($A$11:$A$50,G17,AJ$11:AJ$50)>=SUMIF($A$11:$A$50,G17,$E$11:$E$50)),OR(H17="",SUMIF($A$11:$A$50,H17,AJ$11:AJ$50)>=SUMIF($A$11:$A$50,H17,$E$11:$E$50))),"ОТКРЫТО","ЗАКРЫТО")) -> ОТКРЫТО | AZ17: =IF(AK17>=E17,"ИЗУЧЕНО",IF(AND(OR(F17="",SUMIF($A$11:$A$50,F17,AK$11:AK$50)>=SUMIF($A$11:$A$50,F17,$E$11:$E$50)),OR(G17="",SUMIF($A$11:$A$50,G17,AK$11:AK$50)>=SUMIF($A$11:$A$50,G17,$E$11:$E$50)),OR(H17="",SUMIF($A$11:$A$50,H17,AK$11:AK$50)>=SUMIF($A$11:$A$50,H17,$E$11:$E$50))),"ОТКРЫТО","ЗАКРЫТО")) -> ОТКРЫТО | BA17: =IF(AL17>=E17,"ИЗУЧЕНО",IF(AND(OR(F17="",SUMIF($A$11:$A$50,F17,AL$11:AL$50)>=SUMIF($A$11:$A$50,F17,$E$11:$E$50)),OR(G17="",SUMIF($A$11:$A$50,G17,AL$11:AL$50)>=SUMIF($A$11:$A$50,G17,$E$11:$E$50)),OR(H17="",SUMIF($A$11:$A$50,H17,AL$11:AL$50)>=SUMIF($A$11:$A$50,H17,$E$11:$E$50))),"ОТКРЫТО","ЗАКРЫТО")) -> ОТКРЫТО | BB17: =IF(AM17>=E17,"ИЗУЧЕНО",IF(AND(OR(F17="",SUMIF($A$11:$A$50,F17,AM$11:AM$50)>=SUMIF($A$11:$A$50,F17,$E$11:$E$50)),OR(G17="",SUMIF($A$11:$A$50,G17,AM$11:AM$50)>=SUMIF($A$11:$A$50,G17,$E$11:$E$50)),OR(H17="",SUMIF($A$11:$A$50,H17,AM$11:AM$50)>=SUMIF($A$11:$A$50,H17,$E$11:$E$50))),"ОТКРЫТО","ЗАКРЫТО")) -> ОТКРЫТО | BC17: =IF(AN17>=E17,"ИЗУЧЕНО",IF(AND(OR(F17="",SUMIF($A$11:$A$50,F17,AN$11:AN$50)>=SUMIF($A$11:$A$50,F17,$E$11:$E$50)),OR(G17="",SUMIF($A$11:$A$50,G17,AN$11:AN$50)>=SUMIF($A$11:$A$50,G17,$E$11:$E$50)),OR(H17="",SUMIF($A$11:$A$50,H17,AN$11:AN$50)>=SUMIF($A$11:$A$50,H17,$E$11:$E$50))),"ОТКРЫТО","ЗАКРЫТО")) -> ОТКРЫТО | BD17: =IF(AO17>=E17,"ИЗУЧЕНО",IF(AND(OR(F17="",SUMIF($A$11:$A$50,F17,AO$11:AO$50)>=SUMIF($A$11:$A$50,F17,$E$11:$E$50)),OR(G17="",SUMIF($A$11:$A$50,G17,AO$11:AO$50)>=SUMIF($A$11:$A$50,G17,$E$11:$E$50)),OR(H17="",SUMIF($A$11:$A$50,H17,AO$11:AO$50)>=SUMIF($A$11:$A$50,H17,$E$11:$E$50))),"ОТКРЫТО","ЗАКРЫТО")) -> ОТКРЫТО | BE17: =IF(AP17>=E17,"ИЗУЧЕНО",IF(AND(OR(F17="",SUMIF($A$11:$A$50,F17,AP$11:AP$50)>=SUMIF($A$11:$A$50,F17,$E$11:$E$50)),OR(G17="",SUMIF($A$11:$A$50,G17,AP$11:AP$50)>=SUMIF($A$11:$A$50,G17,$E$11:$E$50)),OR(H17="",SUMIF($A$11:$A$50,H17,AP$11:AP$50)>=SUMIF($A$11:$A$50,H17,$E$11:$E$50))),"ОТКРЫТО","ЗАКРЫТО")) -> ОТКРЫТО | BF17: =IF(AQ17>=E17,"ИЗУЧЕНО",IF(AND(OR(F17="",SUMIF($A$11:$A$50,F17,AQ$11:AQ$50)>=SUMIF($A$11:$A$50,F17,$E$11:$E$50)),OR(G17="",SUMIF($A$11:$A$50,G17,AQ$11:AQ$50)>=SUMIF($A$11:$A$50,G17,$E$11:$E$50)),OR(H17="",SUMIF($A$11:$A$50,H17,AQ$11:AQ$50)>=SUMIF($A$11:$A$50,H17,$E$11:$E$50))),"ОТКРЫТО","ЗАКРЫТО")) -> ОТКРЫТО
A18: M2 | B18: Модели и алгоритмы | C18: II | D18: Мультимодальные фундаментальные модели | E18: 40 | F18: M1 | I18: Совместная работа с текстом, изображениями, звуком, видео и другими модальностями. | J18: Модельные ресурсы +0,3; прирост Принятия ИИ +0,05/год; атака Аполлона +10% | K18: =SUMIF('Ход 2026'!$G$29:$G$38,$A18,'Ход 2026'!$I$29:$I$38) -> 0 | L18: =SUMIF('Ход 2027'!$G$29:$G$38,$A18,'Ход 2027'!$I$29:$I$38) -> 0 | M18: =SUMIF('Ход 2028'!$G$29:$G$38,$A18,'Ход 2028'!$I$29:$I$38) -> 0 | N18: =SUMIF('Ход 2029'!$G$29:$G$38,$A18,'Ход 2029'!$I$29:$I$38) -> 0 | O18: =SUMIF('Ход 2030'!$G$29:$G$38,$A18,'Ход 2030'!$I$29:$I$38) -> 0 | P18: =SUMIF('Ход 2031'!$G$29:$G$38,$A18,'Ход 2031'!$I$29:$I$38) -> 0 | Q18: =SUMIF('Ход 2032'!$G$29:$G$38,$A18,'Ход 2032'!$I$29:$I$38) -> 0 | R18: =SUMIF('Ход 2033'!$G$29:$G$38,$A18,'Ход 2033'!$I$29:$I$38) -> 0 | S18: =SUMIF('Ход 2034'!$G$29:$G$38,$A18,'Ход 2034'!$I$29:$I$38) -> 0 | T18: =SUMIF('Ход 2035'!$G$29:$G$38,$A18,'Ход 2035'!$I$29:$I$38) -> 0 | U18: =SUMIF('Ход 2036'!$G$29:$G$38,$A18,'Ход 2036'!$I$29:$I$38) -> 0 | V18: =SUMIF('Ход 2037'!$G$29:$G$38,$A18,'Ход 2037'!$I$29:$I$38) -> 0 | W18: =SUMIF('Ход 2038'!$G$29:$G$38,$A18,'Ход 2038'!$I$29:$I$38) -> 0 | X18: =SUMIF('Ход 2039'!$G$29:$G$38,$A18,'Ход 2039'!$I$29:$I$38) -> 0 | Y18: =SUMIF('Ход 2040'!$G$29:$G$38,$A18,'Ход 2040'!$I$29:$I$38) -> 0 | Z18: =SUM(K18:Y18) -> 0 | AA18: =MAX(0,E18-Z18) -> 40 | AB18: =BF18 -> ЗАКРЫТО | AC18: =SUM($K18:K18) -> 0 | AD18: =SUM($K18:L18) -> 0 | AE18: =SUM($K18:M18) -> 0 | AF18: =SUM($K18:N18) -> 0 | AG18: =SUM($K18:O18) -> 0 | AH18: =SUM($K18:P18) -> 0 | AI18: =SUM($K18:Q18) -> 0 | AJ18: =SUM($K18:R18) -> 0 | ... AQ18: =SUM($K18:Y18) -> 0 | AR18: =IF(AC18>=E18,"ИЗУЧЕНО",IF(AND(OR(F18="",SUMIF($A$11:$A$50,F18,AC$11:AC$50)>=SUMIF($A$11:$A$50,F18,$E$11:$E$50)),OR(G18="",SUMIF($A$11:$A$50,G18,AC$11:AC$50)>=SUMIF($A$11:$A$50,G18,$E$11:$E$50)),OR(H18="",SUMIF($A$11:$A$50,H18,AC$11:AC$50)>=SUMIF($A$11:$A$50,H18,$E$11:$E$50))),"ОТКРЫТО","ЗАКРЫТО")) -> ЗАКРЫТО | AS18: =IF(AD18>=E18,"ИЗУЧЕНО",IF(AND(OR(F18="",SUMIF($A$11:$A$50,F18,AD$11:AD$50)>=SUMIF($A$11:$A$50,F18,$E$11:$E$50)),OR(G18="",SUMIF($A$11:$A$50,G18,AD$11:AD$50)>=SUMIF($A$11:$A$50,G18,$E$11:$E$50)),OR(H18="",SUMIF($A$11:$A$50,H18,AD$11:AD$50)>=SUMIF($A$11:$A$50,H18,$E$11:$E$50))),"ОТКРЫТО","ЗАКРЫТО")) -> ЗАКРЫТО | AT18: =IF(AE18>=E18,"ИЗУЧЕНО",IF(AND(OR(F18="",SUMIF($A$11:$A$50,F18,AE$11:AE$50)>=SUMIF($A$11:$A$50,F18,$E$11:$E$50)),OR(G18="",SUMIF($A$11:$A$50,G18,AE$11:AE$50)>=SUMIF($A$11:$A$50,G18,$E$11:$E$50)),OR(H18="",SUMIF($A$11:$A$50,H18,AE$11:AE$50)>=SUMIF($A$11:$A$50,H18,$E$11:$E$50))),"ОТКРЫТО","ЗАКРЫТО")) -> ЗАКРЫТО | AU18: =IF(AF18>=E18,"ИЗУЧЕНО",IF(AND(OR(F18="",SUMIF($A$11:$A$50,F18,AF$11:AF$50)>=SUMIF($A$11:$A$50,F18,$E$11:$E$50)),OR(G18="",SUMIF($A$11:$A$50,G18,AF$11:AF$50)>=SUMIF($A$11:$A$50,G18,$E$11:$E$50)),OR(H18="",SUMIF($A$11:$A$50,H18,AF$11:AF$50)>=SUMIF($A$11:$A$50,H18,$E$11:$E$50))),"ОТКРЫТО","ЗАКРЫТО")) -> ЗАКРЫТО | AV18: =IF(AG18>=E18,"ИЗУЧЕНО",IF(AND(OR(F18="",SUMIF($A$11:$A$50,F18,AG$11:AG$50)>=SUMIF($A$11:$A$50,F18,$E$11:$E$50)),OR(G18="",SUMIF($A$11:$A$50,G18,AG$11:AG$50)>=SUMIF($A$11:$A$50,G18,$E$11:$E$50)),OR(H18="",SUMIF($A$11:$A$50,H18,AG$11:AG$50)>=SUMIF($A$11:$A$50,H18,$E$11:$E$50))),"ОТКРЫТО","ЗАКРЫТО")) -> ЗАКРЫТО | AW18: =IF(AH18>=E18,"ИЗУЧЕНО",IF(AND(OR(F18="",SUMIF($A$11:$A$50,F18,AH$11:AH$50)>=SUMIF($A$11:$A$50,F18,$E$11:$E$50)),OR(G18="",SUMIF($A$11:$A$50,G18,AH$11:AH$50)>=SUMIF($A$11:$A$50,G18,$E$11:$E$50)),OR(H18="",SUMIF($A$11:$A$50,H18,AH$11:AH$50)>=SUMIF($A$11:$A$50,H18,$E$11:$E$50))),"ОТКРЫТО","ЗАКРЫТО")) -> ЗАКРЫТО | AX18: =IF(AI18>=E18,"ИЗУЧЕНО",IF(AND(OR(F18="",SUMIF($A$11:$A$50,F18,AI$11:AI$50)>=SUMIF($A$11:$A$50,F18,$E$11:$E$50)),OR(G18="",SUMIF($A$11:$A$50,G18,AI$11:AI$50)>=SUMIF($A$11:$A$50,G18,$E$11:$E$50)),OR(H18="",SUMIF($A$11:$A$50,H18,AI$11:AI$50)>=SUMIF($A$11:$A$50,H18,$E$11:$E$50))),"ОТКРЫТО","ЗАКРЫТО")) -> ЗАКРЫТО | AY18: =IF(AJ18>=E18,"ИЗУЧЕНО",IF(AND(OR(F18="",SUMIF($A$11:$A$50,F18,AJ$11:AJ$50)>=SUMIF($A$11:$A$50,F18,$E$11:$E$50)),OR(G18="",SUMIF($A$11:$A$50,G18,AJ$11:AJ$50)>=SUMIF($A$11:$A$50,G18,$E$11:$E$50)),OR(H18="",SUMIF($A$11:$A$50,H18,AJ$11:AJ$50)>=SUMIF($A$11:$A$50,H18,$E$11:$E$50))),"ОТКРЫТО","ЗАКРЫТО")) -> ЗАКРЫТО | AZ18: =IF(AK18>=E18,"ИЗУЧЕНО",IF(AND(OR(F18="",SUMIF($A$11:$A$50,F18,AK$11:AK$50)>=SUMIF($A$11:$A$50,F18,$E$11:$E$50)),OR(G18="",SUMIF($A$11:$A$50,G18,AK$11:AK$50)>=SUMIF($A$11:$A$50,G18,$E$11:$E$50)),OR(H18="",SUMIF($A$11:$A$50,H18,AK$11:AK$50)>=SUMIF($A$11:$A$50,H18,$E$11:$E$50))),"ОТКРЫТО","ЗАКРЫТО")) -> ЗАКРЫТО | BA18: =IF(AL18>=E18,"ИЗУЧЕНО",IF(AND(OR(F18="",SUMIF($A$11:$A$50,F18,AL$11:AL$50)>=SUMIF($A$11:$A$50,F18,$E$11:$E$50)),OR(G18="",SUMIF($A$11:$A$50,G18,AL$11:AL$50)>=SUMIF($A$11:$A$50,G18,$E$11:$E$50)),OR(H18="",SUMIF($A$11:$A$50,H18,AL$11:AL$50)>=SUMIF($A$11:$A$50,H18,$E$11:$E$50))),"ОТКРЫТО","ЗАКРЫТО")) -> ЗАКРЫТО | BB18: =IF(AM18>=E18,"ИЗУЧЕНО",IF(AND(OR(F18="",SUMIF($A$11:$A$50,F18,AM$11:AM$50)>=SUMIF($A$11:$A$50,F18,$E$11:$E$50)),OR(G18="",SUMIF($A$11:$A$50,G18,AM$11:AM$50)>=SUMIF($A$11:$A$50,G18,$E$11:$E$50)),OR(H18="",SUMIF($A$11:$A$50,H18,AM$11:AM$50)>=SUMIF($A$11:$A$50,H18,$E$11:$E$50))),"ОТКРЫТО","ЗАКРЫТО")) -> ЗАКРЫТО | BC18: =IF(AN18>=E18,"ИЗУЧЕНО",IF(AND(OR(F18="",SUMIF($A$11:$A$50,F18,AN$11:AN$50)>=SUMIF($A$11:$A$50,F18,$E$11:$E$50)),OR(G18="",SUMIF($A$11:$A$50,G18,AN$11:AN$50)>=SUMIF($A$11:$A$50,G18,$E$11:$E$50)),OR(H18="",SUMIF($A$11:$A$50,H18,AN$11:AN$50)>=SUMIF($A$11:$A$50,H18,$E$11:$E$50))),"ОТКРЫТО","ЗАКРЫТО")) -> ЗАКРЫТО | BD18: =IF(AO18>=E18,"ИЗУЧЕНО",IF(AND(OR(F18="",SUMIF($A$11:$A$50,F18,AO$11:AO$50)>=SUMIF($A$11:$A$50,F18,$E$11:$E$50)),OR(G18="",SUMIF($A$11:$A$50,G18,AO$11:AO$50)>=SUMIF($A$11:$A$50,G18,$E$11:$E$50)),OR(H18="",SUMIF($A$11:$A$50,H18,AO$11:AO$50)>=SUMIF($A$11:$A$50,H18,$E$11:$E$50))),"ОТКРЫТО","ЗАКРЫТО")) -> ЗАКРЫТО | BE18: =IF(AP18>=E18,"ИЗУЧЕНО",IF(AND(OR(F18="",SUMIF($A$11:$A$50,F18,AP$11:AP$50)>=SUMIF($A$11:$A$50,F18,$E$11:$E$50)),OR(G18="",SUMIF($A$11:$A$50,G18,AP$11:AP$50)>=SUMIF($A$11:$A$50,G18,$E$11:$E$50)),OR(H18="",SUMIF($A$11:$A$50,H18,AP$11:AP$50)>=SUMIF($A$11:$A$50,H18,$E$11:$E$50))),"ОТКРЫТО","ЗАКРЫТО")) -> ЗАКРЫТО | BF18: =IF(AQ18>=E18,"ИЗУЧЕНО",IF(AND(OR(F18="",SUMIF($A$11:$A$50,F18,AQ$11:AQ$50)>=SUMIF($A$11:$A$50,F18,$E$11:$E$50)),OR(G18="",SUMIF($A$11:$A$50,G18,AQ$11:AQ$50)>=SUMIF($A$11:$A$50,G18,$E$11:$E$50)),OR(H18="",SUMIF($A$11:$A$50,H18,AQ$11:AQ$50)>=SUMIF($A$11:$A$50,H18,$E$11:$E$50))),"ОТКРЫТО","ЗАКРЫТО")) -> ЗАКРЫТО
A19: M3 | B19: Модели и алгоритмы | C19: II | D19: Модели рассуждения и планирования | E19: 45 | F19: M1 | I19: Многошаговое решение задач, планирование и проверка промежуточных результатов. | J19: Методы построения моделей +0,3; прирост Познания +0,08/год | K19: =SUMIF('Ход 2026'!$G$29:$G$38,$A19,'Ход 2026'!$I$29:$I$38) -> 0 | L19: =SUMIF('Ход 2027'!$G$29:$G$38,$A19,'Ход 2027'!$I$29:$I$38) -> 0 | M19: =SUMIF('Ход 2028'!$G$29:$G$38,$A19,'Ход 2028'!$I$29:$I$38) -> 0 | N19: =SUMIF('Ход 2029'!$G$29:$G$38,$A19,'Ход 2029'!$I$29:$I$38) -> 0 | O19: =SUMIF('Ход 2030'!$G$29:$G$38,$A19,'Ход 2030'!$I$29:$I$38) -> 0 | P19: =SUMIF('Ход 2031'!$G$29:$G$38,$A19,'Ход 2031'!$I$29:$I$38) -> 0 | Q19: =SUMIF('Ход 2032'!$G$29:$G$38,$A19,'Ход 2032'!$I$29:$I$38) -> 0 | R19: =SUMIF('Ход 2033'!$G$29:$G$38,$A19,'Ход 2033'!$I$29:$I$38) -> 0 | S19: =SUMIF('Ход 2034'!$G$29:$G$38,$A19,'Ход 2034'!$I$29:$I$38) -> 0 | T19: =SUMIF('Ход 2035'!$G$29:$G$38,$A19,'Ход 2035'!$I$29:$I$38) -> 0 | U19: =SUMIF('Ход 2036'!$G$29:$G$38,$A19,'Ход 2036'!$I$29:$I$38) -> 0 | V19: =SUMIF('Ход 2037'!$G$29:$G$38,$A19,'Ход 2037'!$I$29:$I$38) -> 0 | W19: =SUMIF('Ход 2038'!$G$29:$G$38,$A19,'Ход 2038'!$I$29:$I$38) -> 0 | X19: =SUMIF('Ход 2039'!$G$29:$G$38,$A19,'Ход 2039'!$I$29:$I$38) -> 0 | Y19: =SUMIF('Ход 2040'!$G$29:$G$38,$A19,'Ход 2040'!$I$29:$I$38) -> 0 | Z19: =SUM(K19:Y19) -> 0 | AA19: =MAX(0,E19-Z19) -> 45 | AB19: =BF19 -> ЗАКРЫТО | AC19: =SUM($K19:K19) -> 0 | AD19: =SUM($K19:L19) -> 0 | AE19: =SUM($K19:M19) -> 0 | AF19: =SUM($K19:N19) -> 0 | AG19: =SUM($K19:O19) -> 0 | AH19: =SUM($K19:P19) -> 0 | AI19: =SUM($K19:Q19) -> 0 | AJ19: =SUM($K19:R19) -> 0 | ... AQ19: =SUM($K19:Y19) -> 0 | AR19: =IF(AC19>=E19,"ИЗУЧЕНО",IF(AND(OR(F19="",SUMIF($A$11:$A$50,F19,AC$11:AC$50)>=SUMIF($A$11:$A$50,F19,$E$11:$E$50)),OR(G19="",SUMIF($A$11:$A$50,G19,AC$11:AC$50)>=SUMIF($A$11:$A$50,G19,$E$11:$E$50)),OR(H19="",SUMIF($A$11:$A$50,H19,AC$11:AC$50)>=SUMIF($A$11:$A$50,H19,$E$11:$E$50))),"ОТКРЫТО","ЗАКРЫТО")) -> ЗАКРЫТО | AS19: =IF(AD19>=E19,"ИЗУЧЕНО",IF(AND(OR(F19="",SUMIF($A$11:$A$50,F19,AD$11:AD$50)>=SUMIF($A$11:$A$50,F19,$E$11:$E$50)),OR(G19="",SUMIF($A$11:$A$50,G19,AD$11:AD$50)>=SUMIF($A$11:$A$50,G19,$E$11:$E$50)),OR(H19="",SUMIF($A$11:$A$50,H19,AD$11:AD$50)>=SUMIF($A$11:$A$50,H19,$E$11:$E$50))),"ОТКРЫТО","ЗАКРЫТО")) -> ЗАКРЫТО | AT19: =IF(AE19>=E19,"ИЗУЧЕНО",IF(AND(OR(F19="",SUMIF($A$11:$A$50,F19,AE$11:AE$50)>=SUMIF($A$11:$A$50,F19,$E$11:$E$50)),OR(G19="",SUMIF($A$11:$A$50,G19,AE$11:AE$50)>=SUMIF($A$11:$A$50,G19,$E$11:$E$50)),OR(H19="",SUMIF($A$11:$A$50,H19,AE$11:AE$50)>=SUMIF($A$11:$A$50,H19,$E$11:$E$50))),"ОТКРЫТО","ЗАКРЫТО")) -> ЗАКРЫТО | AU19: =IF(AF19>=E19,"ИЗУЧЕНО",IF(AND(OR(F19="",SUMIF($A$11:$A$50,F19,AF$11:AF$50)>=SUMIF($A$11:$A$50,F19,$E$11:$E$50)),OR(G19="",SUMIF($A$11:$A$50,G19,AF$11:AF$50)>=SUMIF($A$11:$A$50,G19,$E$11:$E$50)),OR(H19="",SUMIF($A$11:$A$50,H19,AF$11:AF$50)>=SUMIF($A$11:$A$50,H19,$E$11:$E$50))),"ОТКРЫТО","ЗАКРЫТО")) -> ЗАКРЫТО | AV19: =IF(AG19>=E19,"ИЗУЧЕНО",IF(AND(OR(F19="",SUMIF($A$11:$A$50,F19,AG$11:AG$50)>=SUMIF($A$11:$A$50,F19,$E$11:$E$50)),OR(G19="",SUMIF($A$11:$A$50,G19,AG$11:AG$50)>=SUMIF($A$11:$A$50,G19,$E$11:$E$50)),OR(H19="",SUMIF($A$11:$A$50,H19,AG$11:AG$50)>=SUMIF($A$11:$A$50,H19,$E$11:$E$50))),"ОТКРЫТО","ЗАКРЫТО")) -> ЗАКРЫТО | AW19: =IF(AH19>=E19,"ИЗУЧЕНО",IF(AND(OR(F19="",SUMIF($A$11:$A$50,F19,AH$11:AH$50)>=SUMIF($A$11:$A$50,F19,$E$11:$E$50)),OR(G19="",SUMIF($A$11:$A$50,G19,AH$11:AH$50)>=SUMIF($A$11:$A$50,G19,$E$11:$E$50)),OR(H19="",SUMIF($A$11:$A$50,H19,AH$11:AH$50)>=SUMIF($A$11:$A$50,H19,$E$11:$E$50))),"ОТКРЫТО","ЗАКРЫТО")) -> ЗАКРЫТО | AX19: =IF(AI19>=E19,"ИЗУЧЕНО",IF(AND(OR(F19="",SUMIF($A$11:$A$50,F19,AI$11:AI$50)>=SUMIF($A$11:$A$50,F19,$E$11:$E$50)),OR(G19="",SUMIF($A$11:$A$50,G19,AI$11:AI$50)>=SUMIF($A$11:$A$50,G19,$E$11:$E$50)),OR(H19="",SUMIF($A$11:$A$50,H19,AI$11:AI$50)>=SUMIF($A$11:$A$50,H19,$E$11:$E$50))),"ОТКРЫТО","ЗАКРЫТО")) -> ЗАКРЫТО | AY19: =IF(AJ19>=E19,"ИЗУЧЕНО",IF(AND(OR(F19="",SUMIF($A$11:$A$50,F19,AJ$11:AJ$50)>=SUMIF($A$11:$A$50,F19,$E$11:$E$50)),OR(G19="",SUMIF($A$11:$A$50,G19,AJ$11:AJ$50)>=SUMIF($A$11:$A$50,G19,$E$11:$E$50)),OR(H19="",SUMIF($A$11:$A$50,H19,AJ$11:AJ$50)>=SUMIF($A$11:$A$50,H19,$E$11:$E$50))),"ОТКРЫТО","ЗАКРЫТО")) -> ЗАКРЫТО | AZ19: =IF(AK19>=E19,"ИЗУЧЕНО",IF(AND(OR(F19="",SUMIF($A$11:$A$50,F19,AK$11:AK$50)>=SUMIF($A$11:$A$50,F19,$E$11:$E$50)),OR(G19="",SUMIF($A$11:$A$50,G19,AK$11:AK$50)>=SUMIF($A$11:$A$50,G19,$E$11:$E$50)),OR(H19="",SUMIF($A$11:$A$50,H19,AK$11:AK$50)>=SUMIF($A$11:$A$50,H19,$E$11:$E$50))),"ОТКРЫТО","ЗАКРЫТО")) -> ЗАКРЫТО | BA19: =IF(AL19>=E19,"ИЗУЧЕНО",IF(AND(OR(F19="",SUMIF($A$11:$A$50,F19,AL$11:AL$50)>=SUMIF($A$11:$A$50,F19,$E$11:$E$50)),OR(G19="",SUMIF($A$11:$A$50,G19,AL$11:AL$50)>=SUMIF($A$11:$A$50,G19,$E$11:$E$50)),OR(H19="",SUMIF($A$11:$A$50,H19,AL$11:AL$50)>=SUMIF($A$11:$A$50,H19,$E$11:$E$50))),"ОТКРЫТО","ЗАКРЫТО")) -> ЗАКРЫТО | BB19: =IF(AM19>=E19,"ИЗУЧЕНО",IF(AND(OR(F19="",SUMIF($A$11:$A$50,F19,AM$11:AM$50)>=SUMIF($A$11:$A$50,F19,$E$11:$E$50)),OR(G19="",SUMIF($A$11:$A$50,G19,AM$11:AM$50)>=SUMIF($A$11:$A$50,G19,$E$11:$E$50)),OR(H19="",SUMIF($A$11:$A$50,H19,AM$11:AM$50)>=SUMIF($A$11:$A$50,H19,$E$11:$E$50))),"ОТКРЫТО","ЗАКРЫТО")) -> ЗАКРЫТО | BC19: =IF(AN19>=E19,"ИЗУЧЕНО",IF(AND(OR(F19="",SUMIF($A$11:$A$50,F19,AN$11:AN$50)>=SUMIF($A$11:$A$50,F19,$E$11:$E$50)),OR(G19="",SUMIF($A$11:$A$50,G19,AN$11:AN$50)>=SUMIF($A$11:$A$50,G19,$E$11:$E$50)),OR(H19="",SUMIF($A$11:$A$50,H19,AN$11:AN$50)>=SUMIF($A$11:$A$50,H19,$E$11:$E$50))),"ОТКРЫТО","ЗАКРЫТО")) -> ЗАКРЫТО | BD19: =IF(AO19>=E19,"ИЗУЧЕНО",IF(AND(OR(F19="",SUMIF($A$11:$A$50,F19,AO$11:AO$50)>=SUMIF($A$11:$A$50,F19,$E$11:$E$50)),OR(G19="",SUMIF($A$11:$A$50,G19,AO$11:AO$50)>=SUMIF($A$11:$A$50,G19,$E$11:$E$50)),OR(H19="",SUMIF($A$11:$A$50,H19,AO$11:AO$50)>=SUMIF($A$11:$A$50,H19,$E$11:$E$50))),"ОТКРЫТО","ЗАКРЫТО")) -> ЗАКРЫТО | BE19: =IF(AP19>=E19,"ИЗУЧЕНО",IF(AND(OR(F19="",SUMIF($A$11:$A$50,F19,AP$11:AP$50)>=SUMIF($A$11:$A$50,F19,$E$11:$E$50)),OR(G19="",SUMIF($A$11:$A$50,G19,AP$11:AP$50)>=SUMIF($A$11:$A$50,G19,$E$11:$E$50)),OR(H19="",SUMIF($A$11:$A$50,H19,AP$11:AP$50)>=SUMIF($A$11:$A$50,H19,$E$11:$E$50))),"ОТКРЫТО","ЗАКРЫТО")) -> ЗАКРЫТО | BF19: =IF(AQ19>=E19,"ИЗУЧЕНО",IF(AND(OR(F19="",SUMIF($A$11:$A$50,F19,AQ$11:AQ$50)>=SUMIF($A$11:$A$50,F19,$E$11:$E$50)),OR(G19="",SUMIF($A$11:$A$50,G19,AQ$11:AQ$50)>=SUMIF($A$11:$A$50,G19,$E$11:$E$50)),OR(H19="",SUMIF($A$11:$A$50,H19,AQ$11:AQ$50)>=SUMIF($A$11:$A$50,H19,$E$11:$E$50))),"ОТКРЫТО","ЗАКРЫТО")) -> ЗАКРЫТО
